<?xml version="1.0"?>
<!-- ALLEX Model v0.2.0 -->
<robot name="ALLEX" xmlns:xacro="http://www.ros.org/wiki/xacro">
    <!-- Global Material Definitions -->
    <material name="white">
        <color rgba="0.98 0.98 0.98 1" />
    </material>
    <material name="black">
        <color rgba="0.03 0.03 0.03 1" />
    </material>
    <material name="gray">
        <color rgba="0.15 0.15 0.15 1" />
    </material>
    <material name="led">
        <color rgba="0.53 0.81 0.92 1" />
    </material>
    <material name="pad">
        <color rgba="0.075 0.075 0.070 1" />
    </material>

    <!-- Joint Definitions -->
    <joint type="revolute" name="Waist_Yaw_Joint">
        <parent link="Base_Link" />
        <child link="Waist_Yaw_Link" />
        <origin xyz="0 0 0.064" rpy="0 0 0" />
        <axis xyz="0 0 1" />
        <dynamics damping="0" />
        <limit lower="-2.792526" upper="2.792526" effort="126" velocity="8" />
    </joint>
    <joint type="revolute" name="Waist_Pitch_Dummy_Joint">
        <parent link="Waist_Yaw_Link" />
        <child link="Waist_Pitch_Back_Link" />
        <origin xyz="-0.04 0 0.15" rpy="0 0 0" />
        <axis xyz="0 1 0" />
        <dynamics damping="0" />
        <mimic joint="Waist_Lower_Pitch_Joint" multiplier="1" offset="0" />
        <limit lower="-0.523598" upper="0.785398" effort="126" velocity="8" />
    </joint>
    <joint type="revolute" name="Waist_Lower_Pitch_Joint">
        <parent link="Waist_Yaw_Link" />
        <child link="Waist_Lower_Pitch_Link" />
        <origin xyz="0.06 0 0.12" rpy="0 0 0" />
        <axis xyz="0 1 0" />
        <dynamics damping="0" />
        <limit lower="-0.523598" upper="0.785398" effort="126" velocity="8" />
    </joint>
    <joint type="revolute" name="Waist_Upper_Pitch_Joint">
        <parent link="Waist_Lower_Pitch_Link" />
        <child link="Waist_Upper_Pitch_Link" />
        <origin xyz="0 0 0.32" rpy="0 0 0" />
        <axis xyz="0 1 0" />
        <dynamics damping="0" />
        <mimic joint="Waist_Lower_Pitch_Joint" multiplier="-1" offset="0" />
        <limit lower="-0.785398" upper="0.523598" effort="126" velocity="8" />
    </joint>
    <joint type="fixed" name="Chest_Origin_fixed_Joint">
        <parent link="Waist_Upper_Pitch_Link" />
        <child link="Chest_Origin_Link" />
        <origin xyz="0.0415 0 0.149" rpy="0 0 0" />
    </joint>
    <joint type="revolute" name="Neck_Pitch_Joint">
        <parent link="Chest_Origin_Link" />
        <child link="Neck_Pitch_Link" />
        <origin xyz="-0.0335 0 0.1380804" rpy="0 0 0" />
        <axis xyz="0 1 0" />
        <dynamics damping="0" />
        <limit lower="-0.523599" upper="0.785398" effort="12" velocity="20" />
    </joint>
    <joint type="revolute" name="Neck_Yaw_Joint">
        <parent link="Neck_Pitch_Link" />
        <child link="Neck_Yaw_Link" />
        <origin xyz="-5e-07 0 0.093" rpy="0 0 0" />
        <axis xyz="0 0 1" />
        <dynamics damping="0" />
        <limit lower="-1.570796" upper="1.570796" effort="6" velocity="20" />
    </joint>
    <joint type="fixed" name="realsense_link_fixed_Joint">
        <parent link="Neck_Yaw_Link" />
        <child link="realsense_link" />
        <origin xyz="0.0753 0 0.1029" rpy="0 0 0" />
    </joint>
    <joint type="fixed" name="orbbec_link_fixed_Joint">
        <parent link="Neck_Yaw_Link" />
        <child link="orbbec_link" />
        <origin xyz="0.0893 0.002 0.0733" rpy="0 0 0" />
    </joint>
    <joint type="fixed" name="zed_camera_link_fixed_Joint">
        <parent link="Neck_Yaw_Link" />
        <child link="zed_camera_link" />
        <origin xyz="0.067225 0 0.0145" rpy="0 0 0" />
    </joint>
    <joint type="fixed" name="realsense_color_optical_frame_joint">
        <parent link="realsense_link" />
        <child link="realsense_color_optical_frame" />
        <origin xyz="0.011 0.033 0.013" rpy="0 1.5708 0" />
    </joint>
    <joint type="fixed" name="realsense_depth_optical_frame_joint">
        <parent link="realsense_link" />
        <child link="realsense_depth_optical_frame" />
        <origin xyz="0.011 0.018 0.013" rpy="0 1.5708 0" />
    </joint>
    <joint type="fixed" name="orbbec_color_optical_frame_joint">
        <parent link="orbbec_link" />
        <child link="orbbec_color_optical_frame" />
        <origin xyz="-0.002 -0.033 -0.001" rpy="0 1.5708 0" />
    </joint>
    <joint type="fixed" name="orbbec_depth_optical_frame_joint">
        <parent link="orbbec_link" />
        <child link="orbbec_depth_optical_frame" />
        <origin xyz="0 0 0" rpy="0 1.5708 0" />
    </joint>
    <joint type="fixed" name="zed_left_camera_optical_frame_joint">
        <parent link="zed_camera_link" />
        <child link="zed_left_camera_optical_frame" />
        <origin xyz="0 0.032 0.013" rpy="0 1.5708 0" />
    </joint>
    <joint type="revolute" name="L_Shoulder_Pitch_Joint">
        <parent link="Chest_Origin_Link" />
        <child link="L_Shoulder_Pitch_Link" />
        <origin xyz="0 0.0710988 0.0190509" rpy="0.2617993931425453 5.720983553558767e-08 2.6299670132234887e-06" />
        <axis xyz="0 1 0" />
        <dynamics damping="0" friction="1" />
        <limit lower="-3.316126" upper="1.745329" effort="120" velocity="10" />
    </joint>
    <joint type="revolute" name="L_Shoulder_Roll_Joint">
        <parent link="L_Shoulder_Pitch_Link" />
        <child link="L_Shoulder_RollYaw_Link" />
        <origin xyz="-0.1365 0.1195 0" rpy="-0.2617993931425453 -5.720983531354307e-08 2.6299670132234887e-06" />
        <axis xyz="1 0 0" />
        <dynamics damping="0" friction="1" />
        <limit lower="-0.087266" upper="3.752458" effort="120" velocity="10" />
    </joint>
    <joint type="revolute" name="L_Shoulder_Yaw_Joint">
        <parent link="L_Shoulder_RollYaw_Link" />
        <child link="L_Upper_Arm_Link" />
        <origin xyz="0.1365 0 0.0315" rpy="0 0 0" />
        <axis xyz="0 0 1" />
        <dynamics damping="0" friction="1" />
        <limit lower="-3.316126" upper="1.745329" effort="120" velocity="10" />
    </joint>
    <joint type="revolute" name="L_Elbow_Joint">
        <parent link="L_Upper_Arm_Link" />
        <child link="L_Elbow_Link" />
        <origin xyz="0.03 0 -0.3255" rpy="0 0 0" />
        <axis xyz="0 1 0" />
        <dynamics damping="0" friction="1" />
        <limit lower="-2.792527" upper="0.087266" effort="100" velocity="20" />
    </joint>
    <joint type="revolute" name="L_Wrist_Yaw_Joint">
        <parent link="L_Elbow_Link" />
        <child link="L_Forearm_Link" />
        <origin xyz="-0.045 0 -0.045" rpy="0 0 0" />
        <axis xyz="0 0 1" />
        <dynamics damping="0" friction="1" />
        <limit lower="-4.799655" upper="0.610865" effort="60" velocity="30" />
    </joint>
    <joint type="revolute" name="L_Wrist_Roll_Joint">
        <parent link="L_Forearm_Link" />
        <child link="L_Wrist_Roll_Link" />
        <origin xyz="-0.0085 0 -0.2725" rpy="0 0 0" />
        <axis xyz="1 0 0" />
        <dynamics damping="0" friction="0.3" />
        <limit lower="-0.872665" upper="0.872665" effort="45" velocity="30" />
    </joint>
    <joint type="revolute" name="L_Wrist_Pitch_Joint">
        <parent link="L_Wrist_Roll_Link" />
        <child link="L_Wrist_Pitch_Link" />
        <origin xyz="0.0135 0 -0.025" rpy="0 0 0" />
        <axis xyz="0 1 0" />
        <dynamics damping="0" friction="0.3" />
        <limit lower="-1.396263" upper="1.396263" effort="45" velocity="30" />
    </joint>
    <joint type="fixed" name="L_Palm_fixed_Joint">
        <parent link="L_Wrist_Pitch_Link" />
        <child link="L_Palm_Link" />
        <origin xyz="0.0045 0 -0.095" rpy="0 0 0" />
    </joint>
    <joint type="revolute" name="L_Thumb_Yaw_Joint">
        <parent link="L_Palm_Link" />
        <child link="L_Thumb_Yaw_Link" />
        <origin xyz="0.0098274 0.0210533 0.0360908" rpy="0.08570131975411865 0.12731092045638293 -0.1266080083114749" />
        <axis xyz="0 0 -1" />
        <dynamics damping="0" friction="0" />
        <limit lower="0" upper="2.617994" effort="2.9" velocity="5" />
    </joint>
    <joint type="revolute" name="L_Thumb_CMC_Joint">
        <parent link="L_Thumb_Yaw_Link" />
        <child link="L_Thumb_Proximal_Link" />
        <origin xyz="0 0.0139985 -0.0323434" rpy="-0.268480430783685 0 0" />
        <axis xyz="-1 0 0" />
        <dynamics damping="0" friction="0" />
        <limit lower="0" upper="1.570796" effort="4.8" velocity="8" />
    </joint>
    <joint type="revolute" name="L_Thumb_MCP_Joint">
        <parent link="L_Thumb_Proximal_Link" />
        <child link="L_Thumb_Middle_Link" />
        <origin xyz="0 0.0501371 0.0137939" rpy="0 0 0" />
        <axis xyz="-1 0 0" />
        <dynamics damping="0" friction="0" />
        <limit lower="0" upper="1.570796" effort="4.8" velocity="8" />
    </joint>
        <joint type="revolute" name="L_Thumb_IP_Joint">
        <parent link="L_Thumb_Middle_Link" />
        <child link="L_Thumb_Distal_Link" />
        <origin xyz="0 0.022 0" rpy="0 0 0" />
        <axis xyz="-1 0 0" />
        <dynamics damping="0" friction="0" />
        <mimic joint="L_Thumb_MCP_Joint" multiplier="0.7319" offset="0" />
        <limit lower="0" upper="1.1397" effort="4.8" velocity="8" />
    </joint>
    <joint type="fixed" name="L_Thumb_Fingertip_Joint">
        <parent link="L_Thumb_Distal_Link" />
        <child link="L_Thumb_Fingertip" />
        <origin xyz="0 0.011 -0.006" rpy="0 0 0" />
    </joint>
    <joint type="revolute" name="L_Index_ABAD_Joint">
        <parent link="L_Palm_Link" />
        <child link="L_Index_Roll_Link" />
        <origin xyz="-0.0186259 0.0330567 -0.0383928" rpy="0.11155943312272709 -0.34233803538908836 -0.0870605140350752" />
        <axis xyz="1 0 0" />
        <dynamics damping="0" friction="0" />
        <limit lower="-0.523599" upper="0.523599" effort="2.1" velocity="8" />
    </joint>
    <joint type="revolute" name="L_Index_MCP_Joint">
        <parent link="L_Index_Roll_Link" />
        <child link="L_Index_Proximal_Link" />
        <origin xyz="-0.003817 0 -0.0061246" rpy="0 0.3490658780677358 0" />
        <axis xyz="0 -1 0" />
        <dynamics damping="0" friction="0" />
        <limit lower="-0.174532" upper="1.570796" effort="4.8" velocity="8" />
    </joint>
    <joint type="revolute" name="L_Index_PIP_Joint">
        <parent link="L_Index_Proximal_Link" />
        <child link="L_Index_Middle_Link" />
        <origin xyz="0 0 -0.052" rpy="0 0 0" />
        <axis xyz="0 -1 0" />
        <dynamics damping="0" friction="0" />
        <limit lower="0" upper="1.7453293" effort="3" velocity="10" />
    </joint>
    <joint type="revolute" name="L_Index_DIP_Joint">
        <parent link="L_Index_Middle_Link" />
        <child link="L_Index_Distal_Link" />
        <origin xyz="0.0019932 0 -0.0188952" rpy="0 0 0" />
        <axis xyz="0 -1 0" />
        <dynamics damping="0" friction="0" />
        <mimic joint="L_Index_PIP_Joint" multiplier="0.6361" offset="0" />
        <limit lower="0" upper="1.235693" effort="3" velocity="10" />
    </joint>
    <joint type="fixed" name="L_Index_Fingertip_Joint">
        <parent link="L_Index_Distal_Link" />
        <child link="L_Index_Fingertip" />
        <origin xyz="0.0075 0 -0.011" rpy="0 0 0" />
    </joint>
    <joint type="revolute" name="L_Middle_ABAD_Joint">
        <parent link="L_Palm_Link" />
        <child link="L_Middle_Roll_Link" />
        <origin xyz="-0.0197378 0.0111686 -0.0403088" rpy="0 -0.3490658780677358 0" />
        <axis xyz="1 0 0" />
        <dynamics damping="0" friction="0" />
        <limit lower="-0.523599" upper="0.523599" effort="2.1" velocity="8" />
    </joint>
    <joint type="revolute" name="L_Middle_MCP_Joint">
        <parent link="L_Middle_Roll_Link" />
        <child link="L_Middle_Proximal_Link" />
        <origin xyz="-0.003817 0 -0.0061246" rpy="0 0.3490658780677358 0" />
        <axis xyz="0 -1 0" />
        <dynamics damping="0" friction="0" />
        <limit lower="-0.174532" upper="1.570796" effort="4.8" velocity="8" />
    </joint>
    <joint type="revolute" name="L_Middle_PIP_Joint">
        <parent link="L_Middle_Proximal_Link" />
        <child link="L_Middle_Middle_Link" />
        <origin xyz="0 0 -0.052" rpy="0 0 0" />
        <axis xyz="0 -1 0" />
        <dynamics damping="0" friction="0" />
        <limit lower="0" upper="1.7453293" effort="3" velocity="10" />
    </joint>
    <joint type="revolute" name="L_Middle_DIP_Joint">
        <parent link="L_Middle_Middle_Link" />
        <child link="L_Middle_Distal_Link" />
        <origin xyz="0.0019932 0 -0.0188952" rpy="0 0 0" />
        <axis xyz="0 -1 0" />
        <dynamics damping="0" friction="0" />
        <mimic joint="L_Middle_PIP_Joint" multiplier="0.6361" offset="0" />
        <limit lower="0" upper="1.235693" effort="3" velocity="10" />
    </joint>
    <joint type="fixed" name="L_Middle_Fingertip_Joint">
        <parent link="L_Middle_Distal_Link" />
        <child link="L_Middle_Fingertip" />
        <origin xyz="0.0075 0 -0.011" rpy="0 0 0" />
    </joint>
    <joint type="revolute" name="L_Ring_ABAD_Joint">
        <parent link="L_Palm_Link" />
        <child link="L_Ring_Roll_Link" />
        <origin xyz="-0.0197763 -0.0108314 -0.0403090" rpy="-0.11155943312272709 -0.34233803538908836 0.0870605140350752" />
        <axis xyz="1 0 0" />
        <dynamics damping="0" friction="0" />
        <limit lower="-0.523599" upper="0.523599" effort="2.1" velocity="8" />
    </joint>
    <joint type="revolute" name="L_Ring_MCP_Joint">
        <parent link="L_Ring_Roll_Link" />
        <child link="L_Ring_Proximal_Link" />
        <origin xyz="-0.003817 0 -0.0061246" rpy="0 0.3490658780677358 0" />
        <axis xyz="0 -1 0" />
        <dynamics damping="0" friction="0" />
        <limit lower="-0.174532" upper="1.570796" effort="4.8" velocity="8" />
    </joint>
    <joint type="revolute" name="L_Ring_PIP_Joint">
        <parent link="L_Ring_Proximal_Link" />
        <child link="L_Ring_Middle_Link" />
        <origin xyz="0 0 -0.052" rpy="0 0 0" />
        <axis xyz="0 -1 0" />
        <dynamics damping="0" friction="0" />
        <limit lower="0" upper="1.7453293" effort="3" velocity="10" />
    </joint>
    <joint type="revolute" name="L_Ring_DIP_Joint">
        <parent link="L_Ring_Middle_Link" />
        <child link="L_Ring_Distal_Link" />
        <origin xyz="0.0019932 0 -0.0188952" rpy="0 0 0" />
        <axis xyz="0 -1 0" />
        <dynamics damping="0" friction="0" />
        <mimic joint="L_Ring_PIP_Joint" multiplier="0.6361" offset="0" />
        <limit lower="0" upper="1.235693" effort="3" velocity="10" />
    </joint>
    <joint type="fixed" name="L_Ring_Fingertip_Joint">
        <parent link="L_Ring_Distal_Link" />
        <child link="L_Ring_Fingertip" />
        <origin xyz="0.0075 0 -0.011" rpy="0 0 0" />
    </joint>
    <joint type="revolute" name="L_Little_ABAD_Joint">
        <parent link="L_Palm_Link" />
        <child link="L_Little_Roll_Link" />
        <origin xyz="-0.0185852 -0.0327196 -0.0383938" rpy="-0.22099136278843234 -0.3223829827602436 0.1716472165028659" />
        <axis xyz="1 0 0" />
        <dynamics damping="0" friction="0" />
        <limit lower="-0.523599" upper="0.523599" effort="2.1" velocity="8" />
    </joint>  
    <joint type="revolute" name="L_Little_MCP_Joint">
        <parent link="L_Little_Roll_Link" />
        <child link="L_Little_Proximal_Link" />
        <origin xyz="-0.003817 0 -0.0061246" rpy="0 0.3490658780677358 0" />
        <axis xyz="0 -1 0" />
        <dynamics damping="0" friction="0" />
        <limit lower="-0.174532" upper="1.570796" effort="4.8" velocity="8" />
    </joint> 
    <joint type="revolute" name="L_Little_PIP_Joint">
        <parent link="L_Little_Proximal_Link" />
        <child link="L_Little_Middle_Link" />
        <origin xyz="0 0 -0.052" rpy="0 0 0" />
        <axis xyz="0 -1 0" />
        <dynamics damping="0" friction="0" />
        <limit lower="0" upper="1.7453293" effort="3" velocity="10" />
    </joint>
    <joint type="revolute" name="L_Little_DIP_Joint">
        <parent link="L_Little_Middle_Link" />
        <child link="L_Little_Distal_Link" />
        <origin xyz="0.0019932 0 -0.0188952" rpy="0 0 0" />
        <axis xyz="0 -1 0" />
        <dynamics damping="0" friction="0" />
        <mimic joint="L_Little_PIP_Joint" multiplier="0.6361" offset="0" />
        <limit lower="0" upper="1.235693" effort="3" velocity="10" />
    </joint>
    <joint type="fixed" name="L_Little_Fingertip_Joint">
        <parent link="L_Little_Distal_Link" />
        <child link="L_Little_Fingertip" />
        <origin xyz="0.0075 0 -0.011" rpy="0 0 0" />
    </joint>
    <joint type="revolute" name="R_Shoulder_Pitch_Joint">
        <parent link="Chest_Origin_Link" />
        <child link="R_Shoulder_Pitch_Link" />
        <origin xyz="0 -0.0710988 0.0190509" rpy="-0.2617993931425453 -5.720983531354307e-08 2.6299670132234887e-06" />
        <axis xyz="0 1 0" />
        <dynamics damping="0" friction="1" />
        <limit lower="-3.316126" upper="1.745329" effort="120" velocity="10" />
    </joint>
    <joint type="revolute" name="R_Shoulder_Roll_Joint">
        <parent link="R_Shoulder_Pitch_Link" />
        <child link="R_Shoulder_RollYaw_Link" />
        <origin xyz="-0.1365 -0.1195 0" rpy="0.2617993931425453 5.720983553558767e-08 2.6299670132234887e-06" />
        <axis xyz="1 0 0" />
        <dynamics damping="0" friction="1" />
        <limit lower="-3.752458" upper="0.087266" effort="120" velocity="10" />
    </joint>
    <joint type="revolute" name="R_Shoulder_Yaw_Joint">
        <parent link="R_Shoulder_RollYaw_Link" />
        <child link="R_Upper_Arm_Link" />
        <origin xyz="0.1365 0 0.0315" rpy="0 0 0" />
        <axis xyz="0 0 1" />
        <dynamics damping="0" friction="1" />
        <limit lower="-1.745329" upper="3.316126" effort="120" velocity="10" />
    </joint>
    <joint type="revolute" name="R_Elbow_Joint">
        <parent link="R_Upper_Arm_Link" />
        <child link="R_Elbow_Link" />
        <origin xyz="0.03 0 -0.3255" rpy="0 0 0" />
        <axis xyz="0 1 0" />
        <dynamics damping="0" friction="1" />
        <limit lower="-2.879793" upper="0.087266" effort="100" velocity="20" />
    </joint>
    <joint type="revolute" name="R_Wrist_Yaw_Joint">
        <parent link="R_Elbow_Link" />
        <child link="R_Forearm_Link" />
        <origin xyz="-0.045 0 -0.045" rpy="0 0 0" />
        <axis xyz="0 0 1" />
        <dynamics damping="0" friction="1" />
        <limit lower="-0.610865" upper="4.799655" effort="60" velocity="30" />
    </joint>
    <joint type="revolute" name="R_Wrist_Roll_Joint">
        <parent link="R_Forearm_Link" />
        <child link="R_Wrist_Roll_Link" />
        <origin xyz="-0.0085 0 -0.2725" rpy="0 0 0" />
        <axis xyz="1 0 0" />
        <dynamics damping="0" friction="0.3" />
        <limit lower="-0.872665" upper="0.872665" effort="45" velocity="30" />
    </joint>
    <joint type="revolute" name="R_Wrist_Pitch_Joint">
        <parent link="R_Wrist_Roll_Link" />
        <child link="R_Wrist_Pitch_Link" />
        <origin xyz="0.0135 0 -0.025" rpy="0 0 0" />
        <axis xyz="0 1 0" />
        <dynamics damping="0" friction="0.3" />
        <limit lower="-1.396263" upper="1.396263" effort="45" velocity="30" />
    </joint>
    <joint type="fixed" name="R_Palm_fixed_Joint">
        <parent link="R_Wrist_Pitch_Link" />
        <child link="R_Palm_Link" />
        <origin xyz="0.0045 0 -0.095" rpy="0 0 0" />
    </joint>
    <joint type="revolute" name="R_Thumb_Yaw_Joint">
        <parent link="R_Palm_Link" />
        <child link="R_Thumb_Yaw_Link" />
        <origin xyz="0.0098263 -0.0210097 0.0360889" rpy="-0.08570131975411865 0.12731092045638293 0.1266080083114749" />
        <axis xyz="0 0 -1" />
        <dynamics damping="0" friction="0" />
        <limit lower="-2.617994" upper="0" effort="2.9" velocity="5" />
    </joint>
    <joint type="revolute" name="R_Thumb_CMC_Joint">
        <parent link="R_Thumb_Yaw_Link" />
        <child link="R_Thumb_Proximal_Link" />
        <origin xyz="0 -0.0139985 -0.0323434" rpy="0.268480430783685 0 0" />
        <axis xyz="1 0 0" />
        <dynamics damping="0" friction="0" />
        <limit lower="0" upper="1.570796" effort="4.8" velocity="8" />
    </joint>
    <joint type="revolute" name="R_Thumb_MCP_Joint">
        <parent link="R_Thumb_Proximal_Link" />
        <child link="R_Thumb_Middle_Link" />
        <origin xyz="0 -0.0501371 0.0137939" rpy="0 0 0" />
        <axis xyz="1 0 0" />
        <dynamics damping="0" friction="0" />
        <limit lower="0" upper="1.570796" effort="4.8" velocity="8" />
    </joint>
    <joint type="revolute" name="R_Thumb_IP_Joint">
        <parent link="R_Thumb_Middle_Link" />
        <child link="R_Thumb_Distal_Link" />
        <origin xyz="0 -0.022 0" rpy="0 0 0" />
        <axis xyz="1 0 0" />
        <dynamics damping="0" friction="0" />
        <mimic joint="R_Thumb_MCP_Joint" multiplier="0.7319" offset="0" />
        <limit lower="0" upper="1.1397" effort="4.8" velocity="8" />
    </joint>
    <joint type="fixed" name="R_Thumb_Fingertip_Joint">
        <parent link="R_Thumb_Distal_Link" />
        <child link="R_Thumb_Fingertip" />
        <origin xyz="0 -0.011 -0.006" rpy="0 0 0" />
    </joint>
    <joint type="revolute" name="R_Index_ABAD_Joint">
        <parent link="R_Palm_Link" />
        <child link="R_Index_Roll_Link" />
        <origin xyz="-0.0186259 -0.0330567 -0.0383928" rpy="-0.11155943312272709 -0.34233803538908836 0.0870605140350752" />
        <axis xyz="1 0 0" />
        <dynamics damping="0" friction="0" />
        <limit lower="-0.523599" upper="0.523599" effort="2.1" velocity="8" />
    </joint>
    <joint type="revolute" name="R_Index_MCP_Joint">
        <parent link="R_Index_Roll_Link" />
        <child link="R_Index_Proximal_Link" />
        <origin xyz="-0.003817 0 -0.0061246" rpy="0 0.3490658780677358 0" />
        <axis xyz="0 -1 0" />
        <dynamics damping="0" friction="0" />
        <limit lower="-0.174532" upper="1.570796" effort="4.8" velocity="8" />
    </joint>
    <joint type="revolute" name="R_Index_PIP_Joint">
        <parent link="R_Index_Proximal_Link" />
        <child link="R_Index_Middle_Link" />
        <origin xyz="0 0 -0.052" rpy="0 0 0" />
        <axis xyz="0 -1 0" />
        <dynamics damping="0" friction="0" />
        <limit lower="0" upper="1.7453293" effort="3" velocity="10" />
    </joint>
    <joint type="revolute" name="R_Index_DIP_Joint">
        <parent link="R_Index_Middle_Link" />
        <child link="R_Index_Distal_Link" />
        <origin xyz="0.0019932 0 -0.0188952" rpy="0 0 0" />
        <axis xyz="0 -1 0" />
        <dynamics damping="0" friction="0" />
        <mimic joint="R_Index_PIP_Joint" multiplier="0.6361" offset="0" />
        <limit lower="0" upper="1.235693" effort="3" velocity="10" />
    </joint>
    <joint type="fixed" name="R_Index_Fingertip_Joint">
        <parent link="R_Index_Distal_Link" />
        <child link="R_Index_Fingertip" />
        <origin xyz="0.0075 0 -0.011" rpy="0 0 0" />
    </joint>
    <joint type="revolute" name="R_Middle_ABAD_Joint">
        <parent link="R_Palm_Link" />
        <child link="R_Middle_Roll_Link" />
        <origin xyz="-0.0197378 -0.0111686 -0.0403088" rpy="0 -0.3490658780677358 0" />
        <axis xyz="1 0 0" />
        <dynamics damping="0" friction="0" />
        <limit lower="-0.523599" upper="0.523599" effort="2.1" velocity="8" />
    </joint>
    <joint type="revolute" name="R_Middle_MCP_Joint">
        <parent link="R_Middle_Roll_Link" />
        <child link="R_Middle_Proximal_Link" />
        <origin xyz="-0.003817 0 -0.0061246" rpy="0 0.3490658780677358 0" />
        <axis xyz="0 -1 0" />
        <dynamics damping="0" friction="0" />
        <limit lower="-0.174532" upper="1.570796" effort="4.8" velocity="8" />
    </joint>
    <joint type="revolute" name="R_Middle_PIP_Joint">
        <parent link="R_Middle_Proximal_Link" />
        <child link="R_Middle_Middle_Link" />
        <origin xyz="0 0 -0.052" rpy="0 0 0" />
        <axis xyz="0 -1 0" />
        <dynamics damping="0" friction="0" />
        <limit lower="0" upper="1.7453293" effort="3" velocity="10" />
    </joint>
    <joint type="revolute" name="R_Middle_DIP_Joint">
        <parent link="R_Middle_Middle_Link" />
        <child link="R_Middle_Distal_Link" />
        <origin xyz="0.0019932 0 -0.0188952" rpy="0 0 0" />
        <axis xyz="0 -1 0" />
        <dynamics damping="0" friction="0" />
        <mimic joint="R_Middle_PIP_Joint" multiplier="0.6361" offset="0" />
        <limit lower="0" upper="1.235693" effort="3" velocity="10" />
    </joint>
    <joint type="fixed" name="R_Middle_Fingertip_Joint">
        <parent link="R_Middle_Distal_Link" />
        <child link="R_Middle_Fingertip" />
        <origin xyz="0.0075 0 -0.011" rpy="0 0 0" />
    </joint>
    <joint type="revolute" name="R_Ring_ABAD_Joint">
        <parent link="R_Palm_Link" />
        <child link="R_Ring_Roll_Link" />
        <origin xyz="-0.0197763 0.0108314 -0.0403090" rpy="0.11155943312272709 -0.34233803538908836 -0.0870605140350752" />
        <axis xyz="1 0 0" />
        <dynamics damping="0" friction="0" />
        <limit lower="-0.523599" upper="0.523599" effort="2.1" velocity="8" />
    </joint>
    <joint type="revolute" name="R_Ring_MCP_Joint">
        <parent link="R_Ring_Roll_Link" />
        <child link="R_Ring_Proximal_Link" />
        <origin xyz="-0.003817 0 -0.0061246" rpy="0 0.3490658780677358 0" />
        <axis xyz="0 -1 0" />
        <dynamics damping="0" friction="0" />
        <limit lower="-0.174532" upper="1.570796" effort="4.8" velocity="8" />
    </joint>
    <joint type="revolute" name="R_Ring_PIP_Joint">
        <parent link="R_Ring_Proximal_Link" />
        <child link="R_Ring_Middle_Link" />
        <origin xyz="0 0 -0.052" rpy="0 0 0" />
        <axis xyz="0 -1 0" />
        <dynamics damping="0" friction="0" />
        <limit lower="0" upper="1.7453293" effort="3" velocity="10" />
    </joint>
    <joint type="revolute" name="R_Ring_DIP_Joint">
        <parent link="R_Ring_Middle_Link" />
        <child link="R_Ring_Distal_Link" />
        <origin xyz="0.0019932 0 -0.0188952" rpy="0 0 0" />
        <axis xyz="0 -1 0" />
        <dynamics damping="0" friction="0" />
        <mimic joint="R_Ring_PIP_Joint" multiplier="0.6361" offset="0" />
        <limit lower="0" upper="1.235693" effort="3" velocity="10" />
    </joint>
    <joint type="fixed" name="R_Ring_Fingertip_Joint">
        <parent link="R_Ring_Distal_Link" />
        <child link="R_Ring_Fingertip" />
        <origin xyz="0.0075 0 -0.011" rpy="0 0 0" />
    </joint>
    <joint type="revolute" name="R_Little_ABAD_Joint">
        <parent link="R_Palm_Link" />
        <child link="R_Little_Roll_Link" />
        <origin xyz="-0.0185852 0.0327196 -0.0383938" rpy="0.22099136278843234 -0.3223829827602436 -0.1716472165028659" />
        <axis xyz="1 0 0" />
        <dynamics damping="0" friction="0" />
        <limit lower="-0.523599" upper="0.523599" effort="2.1" velocity="8" />
    </joint>         
    <joint type="revolute" name="R_Little_MCP_Joint">
        <parent link="R_Little_Roll_Link" />
        <child link="R_Little_Proximal_Link" />
        <origin xyz="-0.003817 0 -0.0061246" rpy="0 0.3490658780677358 0" />
        <axis xyz="0 -1 0" />
        <dynamics damping="0" friction="0" />
        <limit lower="-0.174532" upper="1.570796" effort="4.8" velocity="8" />
    </joint> 
    <joint type="revolute" name="R_Little_PIP_Joint">
        <parent link="R_Little_Proximal_Link" />
        <child link="R_Little_Middle_Link" />
        <origin xyz="0 0 -0.052" rpy="0 0 0" />
        <axis xyz="0 -1 0" />
        <dynamics damping="0" friction="0" />
        <limit lower="0" upper="1.7453293" effort="3" velocity="10" />
    </joint>
    <joint type="revolute" name="R_Little_DIP_Joint">
        <parent link="R_Little_Middle_Link" />
        <child link="R_Little_Distal_Link" />
        <origin xyz="0.0019932 0 -0.0188952" rpy="0 0 0" />
        <axis xyz="0 -1 0" />
        <dynamics damping="0" friction="0" />
        <mimic joint="R_Little_PIP_Joint" multiplier="0.6361" offset="0" />
        <limit lower="0" upper="1.235693" effort="3" velocity="10" />
    </joint>
    <joint type="fixed" name="R_Little_Fingertip_Joint">
        <parent link="R_Little_Distal_Link" />
        <child link="R_Little_Fingertip" />
        <origin xyz="0.0075 0 -0.011" rpy="0 0 0" />
    </joint>

    <!-- Link Definitions -->
    <link name="Base_Link">
        <inertial>
            <origin xyz="0.0 0.0 0.0" rpy="0.0 0.0 0.0" />
            <mass value="3.0" />
            <inertia ixx="0.001" iyy="0.001" izz="0.001" ixy="0" ixz="0" iyz="0" />
        </inertial>
        <collision>
            <geometry>
                <mesh filename="package://allex_description/meshes/Base_Collision.stl" scale="0.001 0.001 0.001" />
            </geometry>
        </collision>
        <visual>
            <material name="black"/>
            <geometry>
                <mesh filename="package://allex_description/meshes/Base_Black.stl" scale="0.001 0.001 0.001" />
            </geometry>
        </visual>
    </link>
    <link name="Waist_Yaw_Link">
        <inertial>
            <origin xyz="0.011694814 -0.023786125 0.046361293" rpy="0.2599687021451198 0.4282403455155408 2.3535609333787395" />
            <mass value="3.62644339" />
            <inertia ixx="0.031312224839605406" iyy="0.021963481282834492" izz="0.012671293877560101" ixy="0" ixz="0" iyz="0" />
        </inertial>
        <collision>
            <geometry>
                <mesh filename="package://allex_description/meshes/Waist_Yaw_Collision.stl" scale="0.001 0.001 0.001" />
            </geometry>
        </collision>
        <visual>
            <material name="black"/>
            <geometry>
                <mesh filename="package://allex_description/meshes/Waist_Yaw_Black.stl" scale="0.001 0.001 0.001" />
            </geometry>
        </visual>
    </link>
    <link name="Waist_Pitch_Back_Link">
        <inertial>
            <origin xyz="0.020387801 0.000182755 0.158712024" rpy="-0.0026867251540428597 0.013404662404624679 0.002150684290813142" />
            <mass value="0.9409332" />
            <inertia ixx="0.012184751161500319" iyy="0.010194047669692055" izz="0.002481201168807627" ixy="0" ixz="0" iyz="0" />
        </inertial>
        <visual>
            <material name="gray"/>
            <geometry>
                <mesh filename="package://allex_description/meshes/Waist_Pitch_Back_Gray.stl" scale="0.001 0.001 0.001" />
            </geometry>
        </visual>
    </link>
    <link name="Waist_Lower_Pitch_Link">
        <inertial>
            <origin xyz="-0.029734297 0.002246639 0.109363279" rpy="-0.12503137372414508 -0.010970109708191789 1.5082719644274936" />
            <mass value="5.75979036" />
            <inertia ixx="0.10774375183068814" iyy="0.09954180491925994" izz="0.02037344325005194" ixy="0" ixz="0" iyz="0" />
        </inertial>
        <collision>
            <geometry>
                <mesh filename="package://allex_description/meshes/Waist_Pitch_Front_Collision.stl" scale="0.001 0.001 0.001" />
            </geometry>
        </collision>
        <visual>
            <material name="gray"/>
            <geometry>
                <mesh filename="package://allex_description/meshes/Waist_Pitch_Front_Gray.stl" scale="0.001 0.001 0.001" />
            </geometry>
        </visual>
    </link>
    <link name="Waist_Upper_Pitch_Link">
        <inertial>
            <origin xyz="-0.020961853 -0.005075656 0.111515576" rpy="1.7139995438890618 0.00014479041117065883 1.4949847845606505" />
            <mass value="3.247447863" />
            <inertia ixx="0.037228623253944826" iyy="0.028815272267709743" izz="0.01790210447834539" ixy="0" ixz="0" iyz="0" />
        </inertial>
        <collision>
            <geometry>
                <mesh filename="package://allex_description/meshes/Chest_Collision.stl" scale="0.001 0.001 0.001" />
            </geometry>
        </collision>
        <visual>
            <material name="white"/>
            <geometry>
                <mesh filename="package://allex_description/meshes/Chest_White.stl" scale="0.001 0.001 0.001" />
            </geometry>
        </visual>
        <visual>
            <material name="led"/>
            <geometry>
                <mesh filename="package://allex_description/meshes/Chest_Led.stl" scale="0.001 0.001 0.001" />
            </geometry>
        </visual>
    </link>
    <link name="Chest_Origin_Link">
        <inertial>
            <origin xyz="0.0 0.0 0.0" rpy="0.0 0.0 0.0" />
            <mass value="0.0" />
            <inertia ixx="0.001" iyy="0.001" izz="0.001" ixy="0" ixz="0" iyz="0" />
        </inertial>
    </link>
    <link name="Neck_Pitch_Link">
        <inertial>
            <origin xyz="-0.014276891 -0.005693118 0.046971122" rpy="0.17158581006344864 -0.11549439578026499 1.5607886838348983" />
            <mass value="0.370429008" />
            <inertia ixx="0.0010331793213121552" iyy="0.0009813730878385555" izz="0.00034244759084928986" ixy="0" ixz="0" iyz="0" />
        </inertial>
        <collision>
            <geometry>
                <mesh filename="package://allex_description/meshes/Neck_Pitch_Collision.stl" scale="0.001 0.001 0.001" />
            </geometry>
        </collision>
        <visual>
            <material name="gray"/>
            <geometry>
                <mesh filename="package://allex_description/meshes/Neck_Pitch_Gray.stl" scale="0.001 0.001 0.001" />
            </geometry>
        </visual>
    </link>
    <link name="Neck_Yaw_Link">
        <inertial>
            <origin xyz="0.032970912 0.000181574 0.052561074" rpy="-0.04688719524896884 -0.21558614369077067 0.16418930320095063" />
            <mass value="1.884994309" />
            <inertia ixx="0.007435779579425397" iyy="0.0073038273584568065" izz="0.005808393062117807" ixy="0" ixz="0" iyz="0" />
        </inertial>
        <collision>
            <geometry>
                <mesh filename="package://allex_description/meshes/Neck_Yaw_Collision.stl" scale="0.001 0.001 0.001" />
            </geometry>
        </collision>
        <visual>
            <material name="white"/>
            <geometry>
                <mesh filename="package://allex_description/meshes/Neck_Yaw_Head.stl" scale="0.001 0.001 0.001" />
            </geometry>
        </visual>        
        <visual>
            <material name="black"/>
            <geometry>
                <mesh filename="package://allex_description/meshes/Neck_Yaw_Face.stl" scale="0.001 0.001 0.001" />
            </geometry>
        </visual>
        <visual>
            <material name="black"/>
            <geometry>
                <mesh filename="package://allex_description/meshes/Neck_Yaw_Cam.stl" scale="0.001 0.001 0.001" />
            </geometry>
        </visual>
        <visual>
            <material name="led"/>
            <geometry>
                <mesh filename="package://allex_description/meshes/Neck_Yaw_Led.stl" scale="0.001 0.001 0.001" />
            </geometry>
        </visual>
    </link>
    <link name="realsense_link" />
    <link name="realsense_color_optical_frame" />
    <link name="realsense_depth_optical_frame" />
    <link name="orbbec_link" />
    <link name="orbbec_color_optical_frame" />
    <link name="orbbec_depth_optical_frame" />
    <link name="zed_camera_link" />
    <link name="zed_left_camera_optical_frame" />
    <link name="L_Shoulder_Pitch_Link">
        <inertial>
            <origin xyz="-0.089957538 0.03745113 -0.000688094" rpy="1.5580493982048114 -0.11529303969742988 2.041651888280497" />
            <mass value="1.015421884" />
            <inertia ixx="0.007933697220946258" iyy="0.007335840776207546" izz="0.0026414620028461927" ixy="0" ixz="0" iyz="0" />
        </inertial>
        <collision>
            <geometry>
                <mesh filename="package://allex_description/meshes/L_Shoulder_Pitch_Collision1.stl" scale="0.001 0.001 0.001" />
            </geometry>
        </collision>
        <collision>
            <geometry>
                <mesh filename="package://allex_description/meshes/L_Shoulder_Pitch_Collision2.stl" scale="0.001 0.001 0.001" />
            </geometry>
        </collision>
        <collision>
            <geometry>
                <mesh filename="package://allex_description/meshes/L_Shoulder_Pitch_Collision3.stl" scale="0.001 0.001 0.001" />
            </geometry>
        </collision>        
        <visual>
            <material name="black"/>
            <geometry>
                <mesh filename="package://allex_description/meshes/L_Shoulder_Pitch_Black.stl" scale="0.001 0.001 0.001" />
            </geometry>
        </visual>
        <visual>
            <material name="white"/>
            <geometry>
                <mesh filename="package://allex_description/meshes/L_Shoulder_Pitch_White.stl" scale="0.001 0.001 0.001" />
            </geometry>
        </visual>
    </link>
    <link name="L_Shoulder_RollYaw_Link">
        <inertial>
            <origin xyz="0.067817694 5.5672e-05 0.06" rpy="-0.6693582105744766 0.027853665263424476 1.6086442789458866" />
            <mass value="2.869014517" />
            <inertia ixx="0.01640162022121718" iyy="0.015224239502597828" izz="0.006928140276184996" ixy="0" ixz="0" iyz="0" />
        </inertial>
        <collision>
            <geometry>
                <mesh filename="package://allex_description/meshes/Shoulder_RollYaw_Collision1.stl" scale="0.001 0.001 0.001" />
            </geometry>
        </collision>
        <collision>
            <geometry>
                <mesh filename="package://allex_description/meshes/Shoulder_RollYaw_Collision2.stl" scale="0.001 0.001 0.001" />
            </geometry>
        </collision>
        <visual>
            <material name="white"/>
            <geometry>
                <mesh filename="package://allex_description/meshes/Shoulder_RollYaw_White.stl" scale="0.001 0.001 0.001" />
            </geometry>
        </visual>
    </link>
    <link name="L_Upper_Arm_Link">
        <inertial>
            <origin xyz="0.0013344 0.00030969 -0.174" rpy="-3.0221 1.5308 -2.9956" />
            <mass value="3.5" />
            <inertia ixx="0.006281509788448" iyy="0.02989863619945" izz="0.03060534067031" ixy="0" ixz="0" iyz="0" />
        </inertial>
        <collision>
            <geometry>
                <mesh filename="package://allex_description/meshes/Upper_Arm_Collision1.stl" scale="0.001 0.001 0.001" />
            </geometry>
        </collision>
        <collision>
            <geometry>
                <mesh filename="package://allex_description/meshes/Upper_Arm_Collision2.stl" scale="0.001 0.001 0.001" />
            </geometry>
        </collision>
        <collision>
            <geometry>
                <mesh filename="package://allex_description/meshes/Upper_Arm_Collision3.stl" scale="0.001 0.001 0.001" />
            </geometry>
        </collision>
        <visual>
            <material name="white"/>
            <geometry>
                <mesh filename="package://allex_description/meshes/Upper_Arm_White1.stl" scale="0.001 0.001 0.001" />
            </geometry>
        </visual>
        <visual>
            <material name="white"/>
            <geometry>
                <mesh filename="package://allex_description/meshes/Upper_Arm_White2.stl" scale="0.001 0.001 0.001" />
            </geometry>
        </visual>
        <visual>
            <material name="white"/>
            <geometry>
                <mesh filename="package://allex_description/meshes/Upper_Arm_White3.stl" scale="0.001 0.001 0.001" />
            </geometry>
        </visual>
        <visual>
            <material name="white"/>
            <geometry>
                <mesh filename="package://allex_description/meshes/Upper_Arm_White4.stl" scale="0.001 0.001 0.001" />
            </geometry>
        </visual>
        <visual>
            <material name="white"/>
            <geometry>
                <mesh filename="package://allex_description/meshes/Upper_Arm_White5.stl" scale="0.001 0.001 0.001" />
            </geometry>
        </visual>
        <visual>
            <material name="white"/>
            <geometry>
                <mesh filename="package://allex_description/meshes/Upper_Arm_White6.stl" scale="0.001 0.001 0.001" />
            </geometry>
        </visual>
        <visual>
            <material name="white"/>
            <geometry>
                <mesh filename="package://allex_description/meshes/Upper_Arm_White7.stl" scale="0.001 0.001 0.001" />
            </geometry>
        </visual>
        <visual>
            <material name="white"/>
            <geometry>
                <mesh filename="package://allex_description/meshes/Upper_Arm_White8.stl" scale="0.001 0.001 0.001" />
            </geometry>
        </visual>
        <visual>
            <material name="white"/>
            <geometry>
                <mesh filename="package://allex_description/meshes/Upper_Arm_White9.stl" scale="0.001 0.001 0.001" />
            </geometry>
        </visual>
        <visual>
            <material name="gray"/>
            <geometry>
                <mesh filename="package://allex_description/meshes/Upper_Arm_Gray.stl" scale="0.001 0.001 0.001" />
            </geometry>
        </visual>
    </link>
    <link name="L_Elbow_Link">
        <inertial>
        <origin xyz="-0.0231 5.122e-05 -0.0085872" rpy="-0.065656 0.23878 -0.00036427" />
        <mass value="0.784434687" />
        <inertia ixx="0.0007918289688995" iyy="0.001534644638612" izz="0.001826444338174" ixy="0" ixz="0" iyz="0" />
        </inertial>
        <collision>
            <geometry>
                <mesh filename="package://allex_description/meshes/Elbow_Collision.stl" scale="0.001 0.001 0.001" />
            </geometry>
        </collision>
        <visual>
            <material name="gray"/>
            <geometry>
                <mesh filename="package://allex_description/meshes/Elbow_Gray.stl" scale="0.001 0.001 0.001" />
            </geometry>
        </visual>
    </link>
    <link name="L_Forearm_Link">
        <inertial>
            <origin xyz="-0.0078824 -0.00010307 -0.11643" rpy="-1.5815 -1.4645 0.0078639" />
            <mass value="3.026739291" />
            <inertia ixx="0.003917052543262" iyy="0.01588830836955" izz="0.01689145229235" ixy="0" ixz="0" iyz="0" />
        </inertial>
        <collision>
            <geometry>
                <mesh filename="package://allex_description/meshes/Forearm_Collision1.stl" scale="0.001 0.001 0.001" />
            </geometry>
        </collision>
        <collision>
            <geometry>
                <mesh filename="package://allex_description/meshes/Forearm_Collision2.stl" scale="0.001 0.001 0.001" />
            </geometry>
        </collision>
        <collision>
            <geometry>
                <mesh filename="package://allex_description/meshes/Forearm_Collision3.stl" scale="0.001 0.001 0.001" />
            </geometry>
        </collision>
        <visual>
            <material name="white"/>
            <geometry>
                <mesh filename="package://allex_description/meshes/Forearm_White.stl" scale="0.001 0.001 0.001" />
            </geometry>
        </visual>
        <visual>
            <material name="black"/>
            <geometry>
                <mesh filename="package://allex_description/meshes/Forearm_Black.stl" scale="0.001 0.001 0.001" />
            </geometry>
        </visual>
        <visual>
            <material name="gray"/>
            <geometry>
                <mesh filename="package://allex_description/meshes/Forearm_Gray.stl" scale="0.001 0.001 0.001" />
            </geometry>
        </visual>
    </link>
    <link name="L_Wrist_Roll_Link">
        <inertial>
            <origin xyz="0.004686796 0.002254747 -0.012267969" rpy="1.6691697294740155 0.6245131227140361 0.12012793920363019" />
            <mass value="0.075462826" />
            <inertia ixx="4.659727589212039e-05" iyy="3.368803396964358e-05" izz="1.771469013823594e-05" ixy="0" ixz="0" iyz="0" />
        </inertial>
        <collision>
            <geometry>
                <mesh filename="package://allex_description/meshes/Wrist_Roll_Collision.stl" scale="0.001 0.001 0.001" />
            </geometry>
        </collision>
        <visual>
            <material name="gray"/>
            <geometry>
                <mesh filename="package://allex_description/meshes/Wrist_Roll_Gray.stl" scale="0.001 0.001 0.001" />
            </geometry>
        </visual>
    </link>
    <link name="L_Wrist_Pitch_Link">
        <inertial>
            <origin xyz="-0.013395506 0.001137719 -0.071900813" rpy="0.008323529697197931 0.026136061281717415 0.02382973138718709" />
            <mass value="1.1" />
            <inertia ixx="0.001751025140772635" iyy="0.001379837389829059" izz="0.0005701374693983064" ixy="0" ixz="0" iyz="0" />
        </inertial>
        <collision>
            <geometry>
                <mesh filename="package://allex_description/meshes/Wrist_Pitch_Collision1.stl" scale="0.001 0.001 0.001" />
            </geometry>
        </collision>
        <collision>
            <geometry>
                <mesh filename="package://allex_description/meshes/Wrist_Pitch_Collision2.stl" scale="0.001 0.001 0.001" />
            </geometry>
        </collision>
        <collision>
            <geometry>
                <mesh filename="package://allex_description/meshes/Wrist_Pitch_Collision3.stl" scale="0.001 0.001 0.001" />
            </geometry>
        </collision>
        <visual>
            <material name="gray"/>
            <geometry>
                <mesh filename="package://allex_description/meshes/Wrist_Pitch_Gray.stl" scale="0.001 0.001 0.001" />
            </geometry>
        </visual>
    </link>
    <link name="L_Palm_Link">
        <inertial>
            <origin xyz="0.0 0.0 0.0" rpy="0.0 0.0 0.0" />
            <mass value="0.0" />
            <inertia ixx="0.001" iyy="0.001" izz="0.001" ixy="0" ixz="0" iyz="0" />
        </inertial>
        <collision>
            <geometry>
                <mesh filename="package://allex_description/meshes/L_Palm_Back_Collision1.stl" scale="0.001 0.001 0.001" />
            </geometry>
        </collision>
        <collision>
            <geometry>
                <mesh filename="package://allex_description/meshes/L_Palm_Back_Collision2.stl" scale="0.001 0.001 0.001" />
            </geometry>
        </collision>
        <collision>
            <geometry>
                <mesh filename="package://allex_description/meshes/L_Palm_Back_Collision3.stl" scale="0.001 0.001 0.001" />
            </geometry>
        </collision>
        <collision>
            <geometry>
                <mesh filename="package://allex_description/meshes/L_Palm_Frame_Collision1.stl" scale="0.001 0.001 0.001" />
            </geometry>
        </collision>
        <collision>
            <geometry>
                <mesh filename="package://allex_description/meshes/L_Palm_Frame_Collision2.stl" scale="0.001 0.001 0.001" />
            </geometry>
        </collision>
        <collision>
            <geometry>
                <mesh filename="package://allex_description/meshes/L_Palm_Frame_Collision3.stl" scale="0.001 0.001 0.001" />
            </geometry>
        </collision>
        <collision>
            <geometry>
                <mesh filename="package://allex_description/meshes/L_Palm_Frame_Collision4.stl" scale="0.001 0.001 0.001" />
            </geometry>
        </collision>
        <collision>
            <geometry>
                <mesh filename="package://allex_description/meshes/L_Palm_Frame_Collision5.stl" scale="0.001 0.001 0.001" />
            </geometry>
        </collision>
        <collision>
            <geometry>
                <mesh filename="package://allex_description/meshes/L_Palm_Frame_Collision6.stl" scale="0.001 0.001 0.001" />
            </geometry>
        </collision>
        <collision>
            <geometry>
                <mesh filename="package://allex_description/meshes/L_Palm_Frame_Collision7.stl" scale="0.001 0.001 0.001" />
            </geometry>
        </collision>                        
        <collision>
            <geometry>
                <mesh filename="package://allex_description/meshes/L_Palm_Pad_Collision1.stl" scale="0.001 0.001 0.001" />
            </geometry>
        </collision>
        <collision>
            <geometry>
                <mesh filename="package://allex_description/meshes/L_Palm_Pad_Collision2.stl" scale="0.001 0.001 0.001" />
            </geometry>
        </collision>
        <collision>
            <geometry>
                <mesh filename="package://allex_description/meshes/L_Palm_Pad_Collision3.stl" scale="0.001 0.001 0.001" />
            </geometry>
        </collision>
        <visual>
            <material name="white"/>
            <geometry>
                <mesh filename="package://allex_description/meshes/L_Palm_White.stl" scale="0.001 0.001 0.001" />
            </geometry>
        </visual>
        <visual>
            <material name="gray"/>
            <geometry>
                <mesh filename="package://allex_description/meshes/L_Palm_Gray.stl" scale="0.001 0.001 0.001" />
            </geometry>
        </visual>
        <visual>
            <material name="pad"/>
            <geometry>
                <mesh filename="package://allex_description/meshes/L_Palm_Pad.stl" scale="0.001 0.001 0.001" />
            </geometry>
        </visual>
    </link>
    <link name="L_Thumb_Yaw_Link">
        <inertial>
            <origin xyz="-7.001e-06 0.002747764 -0.019328997" rpy="-0.013383237448801322 -0.3022643290730289 1.601435969993528" />
            <mass value="0.032789432" />
            <inertia ixx="1.0478629355197585e-05" iyy="1.0440618262932475e-05" izz="1.5009756518699486e-06" ixy="0" ixz="0" iyz="0" />
        </inertial>
        <collision>
            <geometry>
                <mesh filename="package://allex_description/meshes/L_Thumb_Yaw_Collision.stl" scale="0.001 0.001 0.001" />
            </geometry>
        </collision>
        <visual>
            <material name="gray"/>
            <geometry>
                <mesh filename="package://allex_description/meshes/L_Thumb_Yaw_Gray.stl" scale="0.001 0.001 0.001" />
            </geometry>
        </visual>
    </link>
    <link name="L_Thumb_Proximal_Link">
        <inertial>
            <origin xyz="-5.9101e-05 0.015021659 0.007733297" rpy="1.843668607756165 -0.00399944438171107 -0.0025940719583285032" />
            <mass value="0.027231496" />
            <inertia ixx="8.186475059539012e-06" iyy="7.0267390150404346e-06" izz="1.9516013574205644e-06" ixy="0" ixz="0" iyz="0" />
        </inertial>
            <collision>
                <geometry>
                    <mesh filename="package://allex_description/meshes/L_Thumb_Proximal_Collision1.stl" scale="0.001 0.001 0.001" />
                </geometry>
            </collision>
            <collision>
                <geometry>
                    <mesh filename="package://allex_description/meshes/L_Thumb_Proximal_Collision2.stl" scale="0.001 0.001 0.001" />
                </geometry>
            </collision>
            <collision>
                <geometry>
                    <mesh filename="package://allex_description/meshes/L_Thumb_Proximal_Collision3.stl" scale="0.001 0.001 0.001" />
                </geometry>
            </collision>
            <collision>
                <geometry>
                    <mesh filename="package://allex_description/meshes/L_Thumb_Proximal_Collision4.stl" scale="0.001 0.001 0.001" />
                </geometry>
            </collision>
        <visual>
            <material name="white"/>
            <geometry>
                <mesh filename="package://allex_description/meshes/L_Thumb_Proximal_White.stl" scale="0.001 0.001 0.001" />
            </geometry>
        </visual>
        <visual>
            <material name="gray"/>
            <geometry>
                <mesh filename="package://allex_description/meshes/L_Thumb_Proximal_Gray.stl" scale="0.001 0.001 0.001" />
            </geometry>
        </visual>
        <visual>
            <material name="pad"/>
            <geometry>
                <mesh filename="package://allex_description/meshes/L_Thumb_Proximal_Pad.stl" scale="0.001 0.001 0.001" />
            </geometry>
        </visual>
    </link>    
    <link name="L_Thumb_Middle_Link">
        <inertial>
            <origin xyz="4.85e-07 0.006779487 -0.00176946" rpy="-3.137487300779882 -1.5055457421150489 -1.574901714216094" />
            <mass value="0.009930981" />
            <inertia ixx="8.84655879483303e-07" iyy="8.109636547560819e-07" izz="3.270751667606149e-07" ixy="0" ixz="0" iyz="0" />
        </inertial>
        <collision>
            <geometry>
                <mesh filename="package://allex_description/meshes/L_Thumb_Middle_Collision.stl" scale="0.001 0.001 0.001" />
            </geometry>
        </collision>
        <visual>
            <material name="gray"/>
            <geometry>
                <mesh filename="package://allex_description/meshes/L_Thumb_Middle_Gray.stl" scale="0.001 0.001 0.001" />
            </geometry>
        </visual>
        <visual>
            <material name="pad"/>
            <geometry>
                <mesh filename="package://allex_description/meshes/L_Thumb_Middle_Pad.stl" scale="0.001 0.001 0.001" />
            </geometry>
        </visual>
    </link>    
    <link name="L_Thumb_Distal_Link">
        <inertial>
            <origin xyz="3.439e-06 0.005724653 0.00265343" rpy="2.666444586983354 -1.5629018400246042 -1.0965087296196256" />
            <mass value="0.00504" />
            <inertia ixx="3.6536667662865367e-07" iyy="3.4402416843769275e-07" izz="1.0507241568847662e-07" ixy="0" ixz="0" iyz="0" />
        </inertial>
        <collision>
            <geometry>
                <mesh filename="package://allex_description/meshes/L_Thumb_Distal_Collision.stl" scale="0.001 0.001 0.001" />
            </geometry>
        </collision>
        <visual>
            <material name="gray"/>
            <geometry>
                <mesh filename="package://allex_description/meshes/L_Thumb_Distal_Gray.stl" scale="0.001 0.001 0.001" />
            </geometry>
        </visual>
    </link>
    <link name="L_Thumb_Fingertip">
        <visual>
            <material name="pad"/>
            <geometry>
                <mesh filename="package://allex_description/meshes/L_Thumb_Distal_Pad.stl" scale="0.001 0.001 0.001" />
            </geometry>
        </visual>
    </link>    
    <link name="L_Index_Roll_Link">
        <inertial>
            <origin xyz="-0.001315071 0.000324987 -0.001749841" rpy="-1.8382067637602202 -1.151471444372825 -3.0482554781624334" />
            <mass value="0.00611" />
            <inertia ixx="1.9798008349877536e-07" iyy="1.3571776663494185e-07" izz="1.0244531559103244e-07" ixy="0" ixz="0" iyz="0" />
        </inertial>
        <collision>
            <geometry>
                <mesh filename="package://allex_description/meshes/Finger_Roll_Collision.stl" scale="0.001 0.001 0.001" />
            </geometry>
        </collision>
        <visual>
            <material name="gray"/>
            <geometry>
                <mesh filename="package://allex_description/meshes/Finger_Roll_Gray.stl" scale="0.001 0.001 0.001" />
            </geometry>
        </visual>
    </link>
    <link name="L_Index_Proximal_Link">
        <inertial>
            <origin xyz="-0.005831596 4.2198e-05 -0.01921192" rpy="-0.17901800682656976 0.005048498440341387 1.5916388848469718" />
            <mass value="0.02387" />
            <inertia ixx="6.642950653324405e-06" iyy="6.5170055602217035e-06" izz="8.852664619138414e-07" ixy="0" ixz="0" iyz="0" />
        </inertial>
        <collision>
            <geometry>
                <mesh filename="package://allex_description/meshes/Finger_Proximal_Collision.stl" scale="0.001 0.001 0.001" />
            </geometry>
        </collision>
        <visual>
            <material name="white"/>
            <geometry>
                <mesh filename="package://allex_description/meshes/Finger_Proximal_White.stl" scale="0.001 0.001 0.001" />
            </geometry>
        </visual>
        <visual>
            <material name="gray"/>
            <geometry>
                <mesh filename="package://allex_description/meshes/Finger_Proximal_Gray.stl" scale="0.001 0.001 0.001" />
            </geometry>
        </visual>
        <visual>
            <material name="pad"/>
            <geometry>
                <mesh filename="package://allex_description/meshes/Finger_Proximal_Pad.stl" scale="0.001 0.001 0.001" />
            </geometry>
        </visual>
    </link>    
    <link name="L_Index_Middle_Link">
        <inertial>
            <origin xyz="-0.00171781 1.917e-06 -0.00601352" rpy="0.000304271917222844 0.12327199275049261 -0.0012306969719562465" />
            <mass value="0.00977" />
            <inertia ixx="7.395801063650778e-07" iyy="6.707525648021429e-07" izz="3.192749712872233e-07" ixy="0" ixz="0" iyz="0" />
        </inertial>
        <collision>
            <geometry>
                <mesh filename="package://allex_description/meshes/Finger_Middle_Collision.stl" scale="0.001 0.001 0.001" />
            </geometry>
        </collision>
        <visual>
            <material name="gray"/>
            <geometry>
                <mesh filename="package://allex_description/meshes/Finger_Middle_Gray.stl" scale="0.001 0.001 0.001" />
            </geometry>
        </visual>
        <visual>
            <material name="pad"/>
            <geometry>
                <mesh filename="package://allex_description/meshes/Finger_Middle_Pad.stl" scale="0.001 0.001 0.001" />
            </geometry>
        </visual>
    </link>    
    <link name="L_Index_Distal_Link">
        <inertial>
            <origin xyz="-0.002635323 -3.528e-06 -0.00600072" rpy="-0.0008628048573492433 0.011544206563548265 0.0037502395629081865" />
            <mass value="0.00504" />
            <inertia ixx="3.4883691525890126e-07" iyy="3.281665762380144e-07" izz="1.0370759062476941e-07" ixy="0" ixz="0" iyz="0" />
        </inertial>
        <collision>
            <geometry>
                <mesh filename="package://allex_description/meshes/Finger_Distal_Collision.stl" scale="0.001 0.001 0.001" />
            </geometry>
        </collision>
        <visual>
            <material name="gray"/>
            <geometry>
                <mesh filename="package://allex_description/meshes/Finger_Distal_Gray.stl" scale="0.001 0.001 0.001" />
            </geometry>
        </visual>
    </link>
    <link name="L_Index_Fingertip">
        <visual>
            <material name="pad"/>
            <geometry>
                <mesh filename="package://allex_description/meshes/Finger_Distal_Pad.stl" scale="0.001 0.001 0.001" />
            </geometry>
        </visual>
    </link>
    <link name="L_Middle_Roll_Link">
        <inertial>
            <origin xyz="-0.001315071 0.000324987 -0.001749841" rpy="-1.8382067637602202 -1.151471444372825 -3.0482554781624334" />
            <mass value="0.00611" />
            <inertia ixx="1.9798008349877536e-07" iyy="1.3571776663494185e-07" izz="1.0244531559103244e-07" ixy="0" ixz="0" iyz="0" />
        </inertial>
        <collision>
            <geometry>
                <mesh filename="package://allex_description/meshes/Finger_Roll_Collision.stl" scale="0.001 0.001 0.001" />
            </geometry>
        </collision>
        <visual>
            <material name="gray"/>
            <geometry>
                <mesh filename="package://allex_description/meshes/Finger_Roll_Gray.stl" scale="0.001 0.001 0.001" />
            </geometry>
        </visual>
    </link>
    <link name="L_Middle_Proximal_Link">
        <inertial>
            <origin xyz="-0.005831596 4.2198e-05 -0.01921192" rpy="-0.17901800682656976 0.005048498440341387 1.5916388848469718" />
            <mass value="0.02387" />
            <inertia ixx="6.642950653324405e-06" iyy="6.5170055602217035e-06" izz="8.852664619138414e-07" ixy="0" ixz="0" iyz="0" />
        </inertial>
        <collision>
            <geometry>
                <mesh filename="package://allex_description/meshes/Finger_Proximal_Collision.stl" scale="0.001 0.001 0.001" />
            </geometry>
        </collision>
        <visual>
            <material name="white"/>
            <geometry>
                <mesh filename="package://allex_description/meshes/Finger_Proximal_White.stl" scale="0.001 0.001 0.001" />
            </geometry>
        </visual>
        <visual>
            <material name="gray"/>
            <geometry>
                <mesh filename="package://allex_description/meshes/Finger_Proximal_Gray.stl" scale="0.001 0.001 0.001" />
            </geometry>
        </visual>
        <visual>
            <material name="pad"/>
            <geometry>
                <mesh filename="package://allex_description/meshes/Finger_Proximal_Pad.stl" scale="0.001 0.001 0.001" />
            </geometry>
        </visual>
    </link>    
    <link name="L_Middle_Middle_Link">
        <inertial>
            <origin xyz="-0.00171781 1.917e-06 -0.00601352" rpy="0.000304271917222844 0.12327199275049261 -0.0012306969719562465" />
            <mass value="0.00977" />
            <inertia ixx="7.395801063650778e-07" iyy="6.707525648021429e-07" izz="3.192749712872233e-07" ixy="0" ixz="0" iyz="0" />
        </inertial>
        <collision>
            <geometry>
                <mesh filename="package://allex_description/meshes/Finger_Middle_Collision.stl" scale="0.001 0.001 0.001" />
            </geometry>
        </collision>
        <visual>
            <material name="gray"/>
            <geometry>
                <mesh filename="package://allex_description/meshes/Finger_Middle_Gray.stl" scale="0.001 0.001 0.001" />
            </geometry>
        </visual>
        <visual>
            <material name="pad"/>
            <geometry>
                <mesh filename="package://allex_description/meshes/Finger_Middle_Pad.stl" scale="0.001 0.001 0.001" />
            </geometry>
        </visual>
    </link>    
    <link name="L_Middle_Distal_Link">
        <inertial>
            <origin xyz="-0.002635323 -3.528e-06 -0.00600072" rpy="-0.0008628048573492433 0.011544206563548265 0.0037502395629081865" />
            <mass value="0.00504" />
            <inertia ixx="3.4883691525890126e-07" iyy="3.281665762380144e-07" izz="1.0370759062476941e-07" ixy="0" ixz="0" iyz="0" />
        </inertial>
        <collision>
            <geometry>
                <mesh filename="package://allex_description/meshes/Finger_Distal_Collision.stl" scale="0.001 0.001 0.001" />
            </geometry>
        </collision>
        <visual>
            <material name="gray"/>
            <geometry>
                <mesh filename="package://allex_description/meshes/Finger_Distal_Gray.stl" scale="0.001 0.001 0.001" />
            </geometry>
        </visual>
    </link>
    <link name="L_Middle_Fingertip">
        <visual>
            <material name="pad"/>
            <geometry>
                <mesh filename="package://allex_description/meshes/Finger_Distal_Pad.stl" scale="0.001 0.001 0.001" />
            </geometry>
        </visual>
    </link>
    <link name="L_Ring_Roll_Link">
        <inertial>
            <origin xyz="-0.001315071 0.000324987 -0.001749841" rpy="-1.8382067637602202 -1.151471444372825 -3.0482554781624334" />
            <mass value="0.00611" />
            <inertia ixx="1.9798008349877536e-07" iyy="1.3571776663494185e-07" izz="1.0244531559103244e-07" ixy="0" ixz="0" iyz="0" />
        </inertial>
        <collision>
            <geometry>
                <mesh filename="package://allex_description/meshes/Finger_Roll_Collision.stl" scale="0.001 0.001 0.001" />
            </geometry>
        </collision>
        <visual>
            <material name="gray"/>
            <geometry>
                <mesh filename="package://allex_description/meshes/Finger_Roll_Gray.stl" scale="0.001 0.001 0.001" />
            </geometry>
        </visual>
    </link>
    <link name="L_Ring_Proximal_Link">
        <inertial>
            <origin xyz="-0.005831596 4.2198e-05 -0.01921192" rpy="-0.17901800682656976 0.005048498440341387 1.5916388848469718" />
            <mass value="0.02387" />
            <inertia ixx="6.642950653324405e-06" iyy="6.5170055602217035e-06" izz="8.852664619138414e-07" ixy="0" ixz="0" iyz="0" />
        </inertial>
        <collision>
            <geometry>
                <mesh filename="package://allex_description/meshes/Finger_Proximal_Collision.stl" scale="0.001 0.001 0.001" />
            </geometry>
        </collision>
        <visual>
            <material name="white"/>
            <geometry>
                <mesh filename="package://allex_description/meshes/Finger_Proximal_White.stl" scale="0.001 0.001 0.001" />
            </geometry>
        </visual>
        <visual>
            <material name="gray"/>
            <geometry>
                <mesh filename="package://allex_description/meshes/Finger_Proximal_Gray.stl" scale="0.001 0.001 0.001" />
            </geometry>
        </visual>
        <visual>
            <material name="pad"/>
            <geometry>
                <mesh filename="package://allex_description/meshes/Finger_Proximal_Pad.stl" scale="0.001 0.001 0.001" />
            </geometry>
        </visual>
    </link>    
    <link name="L_Ring_Middle_Link">
        <inertial>
            <origin xyz="-0.00171781 1.917e-06 -0.00601352" rpy="0.000304271917222844 0.12327199275049261 -0.0012306969719562465" />
            <mass value="0.00977" />
            <inertia ixx="7.395801063650778e-07" iyy="6.707525648021429e-07" izz="3.192749712872233e-07" ixy="0" ixz="0" iyz="0" />
        </inertial>
        <collision>
            <geometry>
                <mesh filename="package://allex_description/meshes/Finger_Middle_Collision.stl" scale="0.001 0.001 0.001" />
            </geometry>
        </collision>
        <visual>
            <material name="gray"/>
            <geometry>
                <mesh filename="package://allex_description/meshes/Finger_Middle_Gray.stl" scale="0.001 0.001 0.001" />
            </geometry>
        </visual>
        <visual>
            <material name="pad"/>
            <geometry>
                <mesh filename="package://allex_description/meshes/Finger_Middle_Pad.stl" scale="0.001 0.001 0.001" />
            </geometry>
        </visual>
    </link>    
    <link name="L_Ring_Distal_Link">
        <inertial>
            <origin xyz="-0.002635323 -3.528e-06 -0.00600072" rpy="-0.0008628048573492433 0.011544206563548265 0.0037502395629081865" />
            <mass value="0.00504" />
            <inertia ixx="3.4883691525890126e-07" iyy="3.281665762380144e-07" izz="1.0370759062476941e-07" ixy="0" ixz="0" iyz="0" />
        </inertial>
        <collision>
            <geometry>
                <mesh filename="package://allex_description/meshes/Finger_Distal_Collision.stl" scale="0.001 0.001 0.001" />
            </geometry>
        </collision>
        <visual>
            <material name="gray"/>
            <geometry>
                <mesh filename="package://allex_description/meshes/Finger_Distal_Gray.stl" scale="0.001 0.001 0.001" />
            </geometry>
        </visual>
    </link>
    <link name="L_Ring_Fingertip">
        <visual>
            <material name="pad"/>
            <geometry>
                <mesh filename="package://allex_description/meshes/Finger_Distal_Pad.stl" scale="0.001 0.001 0.001" />
            </geometry>
        </visual>
    </link>
    <link name="L_Little_Roll_Link">
        <inertial>
            <origin xyz="-0.001315071 0.000324987 -0.001749841" rpy="-1.8382067637602202 -1.151471444372825 -3.0482554781624334" />
            <mass value="0.00611" />
            <inertia ixx="1.9798008349877536e-07" iyy="1.3571776663494185e-07" izz="1.0244531559103244e-07" ixy="0" ixz="0" iyz="0" />
        </inertial>
        <collision>
            <geometry>
                <mesh filename="package://allex_description/meshes/Finger_Roll_Collision.stl" scale="0.001 0.001 0.001" />
            </geometry>
        </collision>
        <visual>
            <material name="gray"/>
            <geometry>
                <mesh filename="package://allex_description/meshes/Finger_Roll_Gray.stl" scale="0.001 0.001 0.001" />
            </geometry>
        </visual>
    </link>
    <link name="L_Little_Proximal_Link">
        <inertial>
            <origin xyz="-0.005831596 4.2198e-05 -0.01921192" rpy="-0.17901800682656976 0.005048498440341387 1.5916388848469718" />
            <mass value="0.02175" />
            <inertia ixx="6.052960901122989e-06" iyy="5.938201547332301e-06" izz="8.066420421711759e-07" ixy="0" ixz="0" iyz="0" />
        </inertial>
        <collision>
            <geometry>
                <mesh filename="package://allex_description/meshes/Finger_Proximal_Collision.stl" scale="0.001 0.001 0.001" />
            </geometry>
        </collision>
        <visual>
            <material name="white"/>
            <geometry>
                <mesh filename="package://allex_description/meshes/Finger_Proximal_White.stl" scale="0.001 0.001 0.001" />
            </geometry>
        </visual>
        <visual>
            <material name="gray"/>
            <geometry>
                <mesh filename="package://allex_description/meshes/Finger_Proximal_Gray.stl" scale="0.001 0.001 0.001" />
            </geometry>
        </visual>
        <visual>
            <material name="pad"/>
            <geometry>
                <mesh filename="package://allex_description/meshes/Finger_Proximal_Pad.stl" scale="0.001 0.001 0.001" />
            </geometry>
        </visual>
    </link>
    <link name="L_Little_Middle_Link">
        <inertial>
            <origin xyz="-0.00171781 1.917e-06 -0.00601352" rpy="0.000304271917222844 0.12327199275049261 -0.0012306969719562465" />
            <mass value="0.00977" />
            <inertia ixx="7.395801063650778e-07" iyy="6.707525648021429e-07" izz="3.192749712872233e-07" ixy="0" ixz="0" iyz="0" />
        </inertial>
        <collision>
            <geometry>
                <mesh filename="package://allex_description/meshes/Finger_Middle_Collision.stl" scale="0.001 0.001 0.001" />
            </geometry>
        </collision>
        <visual>
            <material name="gray"/>
            <geometry>
                <mesh filename="package://allex_description/meshes/Finger_Middle_Gray.stl" scale="0.001 0.001 0.001" />
            </geometry>
        </visual>
        <visual>
            <material name="pad"/>
            <geometry>
                <mesh filename="package://allex_description/meshes/Finger_Middle_Pad.stl" scale="0.001 0.001 0.001" />
            </geometry>
        </visual>
    </link>
    <link name="L_Little_Distal_Link">
        <inertial>
            <origin xyz="-0.002635323 -3.528e-06 -0.00600072" rpy="-0.0008628048573492433 0.011544206563548265 0.0037502395629081865" />
            <mass value="0.00504" />
            <inertia ixx="3.4883691525890126e-07" iyy="3.281665762380144e-07" izz="1.0370759062476941e-07" ixy="0" ixz="0" iyz="0" />
        </inertial>
        <collision>
            <geometry>
                <mesh filename="package://allex_description/meshes/Finger_Distal_Collision.stl" scale="0.001 0.001 0.001" />
            </geometry>
        </collision>
        <visual>
            <material name="gray"/>
            <geometry>
                <mesh filename="package://allex_description/meshes/Finger_Distal_Gray.stl" scale="0.001 0.001 0.001" />
            </geometry>
        </visual>
    </link>
    <link name="L_Little_Fingertip">
        <visual>
            <material name="pad"/>
            <geometry>
                <mesh filename="package://allex_description/meshes/Finger_Distal_Pad.stl" scale="0.001 0.001 0.001" />
            </geometry>
        </visual>
    </link>
    <link name="R_Shoulder_Pitch_Link">
        <inertial>
            <origin xyz="-0.089957538 -0.03745113 -0.000688094" rpy="1.5580493982048116 0.11529303969742988 1.0999407653092963" />
            <mass value="1.015421884" />
            <inertia ixx="0.007933697220946258" iyy="0.007335840776207546" izz="0.0026414620028461927" ixy="0" ixz="0" iyz="0" />
        </inertial>
        <collision>
            <geometry>
                <mesh filename="package://allex_description/meshes/R_Shoulder_Pitch_Collision1.stl" scale="0.001 0.001 0.001" />
            </geometry>
        </collision>
        <collision>
            <geometry>
                <mesh filename="package://allex_description/meshes/R_Shoulder_Pitch_Collision2.stl" scale="0.001 0.001 0.001" />
            </geometry>
        </collision>
        <collision>
            <geometry>
                <mesh filename="package://allex_description/meshes/R_Shoulder_Pitch_Collision3.stl" scale="0.001 0.001 0.001" />
            </geometry>
        </collision>        
        <visual>
            <material name="black"/>
            <geometry>
                <mesh filename="package://allex_description/meshes/R_Shoulder_Pitch_Black.stl" scale="0.001 0.001 0.001" />
            </geometry>
        </visual>
        <visual>
            <material name="white"/>
            <geometry>
                <mesh filename="package://allex_description/meshes/R_Shoulder_Pitch_White.stl" scale="0.001 0.001 0.001" />
            </geometry>
        </visual>
    </link>
    <link name="R_Shoulder_RollYaw_Link">
        <inertial>
            <origin xyz="0.067817694 5.5672e-05 0.06" rpy="-0.6693582105744766 0.027853665263424476 1.6086442789458866" />
            <mass value="2.869014517" />
            <inertia ixx="0.01640162022121718" iyy="0.015224239502597828" izz="0.006928140276184996" ixy="0" ixz="0" iyz="0" />
        </inertial>
        <collision>
            <geometry>
                <mesh filename="package://allex_description/meshes/Shoulder_RollYaw_Collision1.stl" scale="0.001 0.001 0.001" />
            </geometry>
        </collision>
        <collision>
            <geometry>
                <mesh filename="package://allex_description/meshes/Shoulder_RollYaw_Collision2.stl" scale="0.001 0.001 0.001" />
            </geometry>
        </collision>
        <visual>
            <material name="white"/>
            <geometry>
                <mesh filename="package://allex_description/meshes/Shoulder_RollYaw_White.stl" scale="0.001 0.001 0.001" />
            </geometry>
        </visual>
    </link>
    <link name="R_Upper_Arm_Link">
        <inertial>
            <origin xyz="0.0013344 0.00030969 -0.174" rpy="-3.0221 1.5308 -2.9956" />
            <mass value="3.5" />
            <inertia ixx="0.006281509788448" iyy="0.02989863619945" izz="0.03060534067031" ixy="0" ixz="0" iyz="0" />
        </inertial>
        <collision>
            <geometry>
                <mesh filename="package://allex_description/meshes/Upper_Arm_Collision1.stl" scale="0.001 0.001 0.001" />
            </geometry>
        </collision>
        <collision>
            <geometry>
                <mesh filename="package://allex_description/meshes/Upper_Arm_Collision2.stl" scale="0.001 0.001 0.001" />
            </geometry>
        </collision>
        <collision>
            <geometry>
                <mesh filename="package://allex_description/meshes/Upper_Arm_Collision3.stl" scale="0.001 0.001 0.001" />
            </geometry>
        </collision>
        <visual>
            <material name="white"/>
            <geometry>
                <mesh filename="package://allex_description/meshes/Upper_Arm_White1.stl" scale="0.001 0.001 0.001" />
            </geometry>
        </visual>
        <visual>
            <material name="white"/>
            <geometry>
                <mesh filename="package://allex_description/meshes/Upper_Arm_White2.stl" scale="0.001 0.001 0.001" />
            </geometry>
        </visual>
        <visual>
            <material name="white"/>
            <geometry>
                <mesh filename="package://allex_description/meshes/Upper_Arm_White3.stl" scale="0.001 0.001 0.001" />
            </geometry>
        </visual>
        <visual>
            <material name="white"/>
            <geometry>
                <mesh filename="package://allex_description/meshes/Upper_Arm_White4.stl" scale="0.001 0.001 0.001" />
            </geometry>
        </visual>
        <visual>
            <material name="white"/>
            <geometry>
                <mesh filename="package://allex_description/meshes/Upper_Arm_White5.stl" scale="0.001 0.001 0.001" />
            </geometry>
        </visual>
        <visual>
            <material name="white"/>
            <geometry>
                <mesh filename="package://allex_description/meshes/Upper_Arm_White6.stl" scale="0.001 0.001 0.001" />
            </geometry>
        </visual>
        <visual>
            <material name="white"/>
            <geometry>
                <mesh filename="package://allex_description/meshes/Upper_Arm_White7.stl" scale="0.001 0.001 0.001" />
            </geometry>
        </visual>
        <visual>
            <material name="white"/>
            <geometry>
                <mesh filename="package://allex_description/meshes/Upper_Arm_White8.stl" scale="0.001 0.001 0.001" />
            </geometry>
        </visual>
        <visual>
            <material name="white"/>
            <geometry>
                <mesh filename="package://allex_description/meshes/Upper_Arm_White9.stl" scale="0.001 0.001 0.001" />
            </geometry>
        </visual>
        <visual>
            <material name="gray"/>
            <geometry>
                <mesh filename="package://allex_description/meshes/Upper_Arm_Gray.stl" scale="0.001 0.001 0.001" />
            </geometry>
        </visual>
    </link>
    <link name="R_Elbow_Link">
        <inertial>
        <origin xyz="-0.0231 5.122e-05 -0.0085872" rpy="-0.065656 0.23878 -0.00036427" />
        <mass value="0.784434687" />
        <inertia ixx="0.0007918289688995" iyy="0.001534644638612" izz="0.001826444338174" ixy="0" ixz="0" iyz="0" />
        </inertial>
        <collision>
            <geometry>
                <mesh filename="package://allex_description/meshes/Elbow_Collision.stl" scale="0.001 0.001 0.001" />
            </geometry>
        </collision>
        <visual>
            <material name="gray"/>
            <geometry>
                <mesh filename="package://allex_description/meshes/Elbow_Gray.stl" scale="0.001 0.001 0.001" />
            </geometry>
        </visual>
    </link>
    <link name="R_Forearm_Link">
        <inertial>
            <origin xyz="-0.0078824 -0.00010307 -0.11643" rpy="-1.5815 -1.4645 0.0078639" />
            <mass value="3.026739291" />
            <inertia ixx="0.003917052543262" iyy="0.01588830836955" izz="0.01689145229235" ixy="0" ixz="0" iyz="0" />
        </inertial>
        <collision>
            <geometry>
                <mesh filename="package://allex_description/meshes/Forearm_Collision1.stl" scale="0.001 0.001 0.001" />
            </geometry>
        </collision>
        <collision>
            <geometry>
                <mesh filename="package://allex_description/meshes/Forearm_Collision2.stl" scale="0.001 0.001 0.001" />
            </geometry>
        </collision>
        <collision>
            <geometry>
                <mesh filename="package://allex_description/meshes/Forearm_Collision3.stl" scale="0.001 0.001 0.001" />
            </geometry>
        </collision>
        <visual>
            <material name="white"/>
            <geometry>
                <mesh filename="package://allex_description/meshes/Forearm_White.stl" scale="0.001 0.001 0.001" />
            </geometry>
        </visual>
        <visual>
            <material name="black"/>
            <geometry>
                <mesh filename="package://allex_description/meshes/Forearm_Black.stl" scale="0.001 0.001 0.001" />
            </geometry>
        </visual>
        <visual>
            <material name="gray"/>
            <geometry>
                <mesh filename="package://allex_description/meshes/Forearm_Gray.stl" scale="0.001 0.001 0.001" />
            </geometry>
        </visual>
    </link>
    <link name="R_Wrist_Roll_Link">
        <inertial>
            <origin xyz="0.004686796 0.002254747 -0.012267969" rpy="1.6691697294740155 0.6245131227140361 0.12012793920363019" />
            <mass value="0.075462826" />
            <inertia ixx="4.659727589212039e-05" iyy="3.368803396964358e-05" izz="1.771469013823594e-05" ixy="0" ixz="0" iyz="0" />
        </inertial>
        <collision>
            <geometry>
                <mesh filename="package://allex_description/meshes/Wrist_Roll_Collision.stl" scale="0.001 0.001 0.001" />
            </geometry>
        </collision>
        <visual>
            <material name="gray"/>
            <geometry>
                <mesh filename="package://allex_description/meshes/Wrist_Roll_Gray.stl" scale="0.001 0.001 0.001" />
            </geometry>
        </visual>
    </link>
    <link name="R_Wrist_Pitch_Link">
        <inertial>
            <origin xyz="-0.013395506 -0.001137719 -0.071900813" rpy="-0.008323529697197931 0.026136061281717415 -0.02382973138718709" />
            <mass value="1.1" />
            <inertia ixx="0.001751025140772635" iyy="0.001379837389829059" izz="0.0005701374693983064" ixy="0" ixz="0" iyz="0" />
        </inertial>
        <collision>
            <geometry>
                <mesh filename="package://allex_description/meshes/Wrist_Pitch_Collision1.stl" scale="0.001 0.001 0.001" />
            </geometry>
        </collision>
        <collision>
            <geometry>
                <mesh filename="package://allex_description/meshes/Wrist_Pitch_Collision2.stl" scale="0.001 0.001 0.001" />
            </geometry>
        </collision>
        <collision>
            <geometry>
                <mesh filename="package://allex_description/meshes/Wrist_Pitch_Collision3.stl" scale="0.001 0.001 0.001" />
            </geometry>
        </collision>
        <visual>
            <material name="gray"/>
            <geometry>
                <mesh filename="package://allex_description/meshes/Wrist_Pitch_Gray.stl" scale="0.001 0.001 0.001" />
            </geometry>
        </visual>
    </link>
    <link name="R_Palm_Link">
        <inertial>
            <origin xyz="0.0 0.0 0.0" rpy="0.0 0.0 0.0" />
            <mass value="0.0" />
            <inertia ixx="0.001" iyy="0.001" izz="0.001" ixy="0" ixz="0" iyz="0" />
        </inertial>
        <collision>
            <geometry>
                <mesh filename="package://allex_description/meshes/R_Palm_Back_Collision1.stl" scale="0.001 0.001 0.001" />
            </geometry>
        </collision>
        <collision>
            <geometry>
                <mesh filename="package://allex_description/meshes/R_Palm_Back_Collision2.stl" scale="0.001 0.001 0.001" />
            </geometry>
        </collision>
        <collision>
            <geometry>
                <mesh filename="package://allex_description/meshes/R_Palm_Back_Collision3.stl" scale="0.001 0.001 0.001" />
            </geometry>
        </collision>
        <collision>
            <geometry>
                <mesh filename="package://allex_description/meshes/R_Palm_Frame_Collision1.stl" scale="0.001 0.001 0.001" />
            </geometry>
        </collision>
        <collision>
            <geometry>
                <mesh filename="package://allex_description/meshes/R_Palm_Frame_Collision2.stl" scale="0.001 0.001 0.001" />
            </geometry>
        </collision>
        <collision>
            <geometry>
                <mesh filename="package://allex_description/meshes/R_Palm_Frame_Collision3.stl" scale="0.001 0.001 0.001" />
            </geometry>
        </collision>
        <collision>
            <geometry>
                <mesh filename="package://allex_description/meshes/R_Palm_Frame_Collision4.stl" scale="0.001 0.001 0.001" />
            </geometry>
        </collision>
        <collision>
            <geometry>
                <mesh filename="package://allex_description/meshes/R_Palm_Frame_Collision5.stl" scale="0.001 0.001 0.001" />
            </geometry>
        </collision>
        <collision>
            <geometry>
                <mesh filename="package://allex_description/meshes/R_Palm_Frame_Collision6.stl" scale="0.001 0.001 0.001" />
            </geometry>
        </collision>
        <collision>
            <geometry>
                <mesh filename="package://allex_description/meshes/R_Palm_Frame_Collision7.stl" scale="0.001 0.001 0.001" />
            </geometry>
        </collision>                        
        <collision>
            <geometry>
                <mesh filename="package://allex_description/meshes/R_Palm_Pad_Collision1.stl" scale="0.001 0.001 0.001" />
            </geometry>
        </collision>
        <collision>
            <geometry>
                <mesh filename="package://allex_description/meshes/R_Palm_Pad_Collision2.stl" scale="0.001 0.001 0.001" />
            </geometry>
        </collision>
        <collision>
            <geometry>
                <mesh filename="package://allex_description/meshes/R_Palm_Pad_Collision3.stl" scale="0.001 0.001 0.001" />
            </geometry>
        </collision>
        <visual>
            <material name="white"/>
            <geometry>
                <mesh filename="package://allex_description/meshes/R_Palm_White.stl" scale="0.001 0.001 0.001" />
            </geometry>
        </visual>
        <visual>
            <material name="gray"/>
            <geometry>
                <mesh filename="package://allex_description/meshes/R_Palm_Gray.stl" scale="0.001 0.001 0.001" />
            </geometry>
        </visual>
        <visual>
            <material name="pad"/>
            <geometry>
                <mesh filename="package://allex_description/meshes/R_Palm_Pad.stl" scale="0.001 0.001 0.001" />
            </geometry>
        </visual>
    </link>
    <link name="R_Thumb_Yaw_Link">
        <inertial>
            <origin xyz="-7.001e-06 -0.002747764 -0.019328997" rpy="-0.01338323744880121 0.3022643290730289 1.540156683596265" />
            <mass value="0.032789432" />
            <inertia ixx="1.0478629355197585e-05" iyy="1.0440618262932475e-05" izz="1.5009756518699486e-06" ixy="0" ixz="0" iyz="0" />
        </inertial>
        <collision>
            <geometry>
                <mesh filename="package://allex_description/meshes/R_Thumb_Yaw_Collision.stl" scale="0.001 0.001 0.001" />
            </geometry>
        </collision>
        <visual>
            <material name="gray"/>
            <geometry>
                <mesh filename="package://allex_description/meshes/R_Thumb_Yaw_Gray.stl" scale="0.001 0.001 0.001" />
            </geometry>
        </visual>
    </link>
<link name="R_Thumb_Proximal_Link">
        <inertial>
            <origin xyz="-5.9101e-05 -0.015021659 0.007733297" rpy="1.297924045833628 -0.00399944438171107 0.0025940719583285032" />
            <mass value="0.027231496" />
            <inertia ixx="8.186475059539012e-06" iyy="7.0267390150404346e-06" izz="1.9516013574205644e-06" ixy="0" ixz="0" iyz="0" />
        </inertial>
        <collision>
            <geometry>
                <mesh filename="package://allex_description/meshes/R_Thumb_Proximal_Collision1.stl" scale="0.001 0.001 0.001" />
            </geometry>
        </collision>
        <collision>
            <geometry>
                <mesh filename="package://allex_description/meshes/R_Thumb_Proximal_Collision2.stl" scale="0.001 0.001 0.001" />
            </geometry>
        </collision>
        <collision>
            <geometry>
                <mesh filename="package://allex_description/meshes/R_Thumb_Proximal_Collision3.stl" scale="0.001 0.001 0.001" />
            </geometry>
        </collision>
        <collision>
            <geometry>
                <mesh filename="package://allex_description/meshes/R_Thumb_Proximal_Collision4.stl" scale="0.001 0.001 0.001" />
            </geometry>
        </collision>
        <visual>
            <material name="white"/>
            <geometry>
                <mesh filename="package://allex_description/meshes/R_Thumb_Proximal_White.stl" scale="0.001 0.001 0.001" />
            </geometry>
        </visual>
        <visual>
            <material name="gray"/>
            <geometry>
                <mesh filename="package://allex_description/meshes/R_Thumb_Proximal_Gray.stl" scale="0.001 0.001 0.001" />
            </geometry>
        </visual>
        <visual>
            <material name="pad"/>
            <geometry>
                <mesh filename="package://allex_description/meshes/R_Thumb_Proximal_Pad.stl" scale="0.001 0.001 0.001" />
            </geometry>
        </visual>
    </link>    
    <link name="R_Thumb_Middle_Link">
        <inertial>
            <origin xyz="4.85e-07 -0.006779487 -0.00176946" rpy="-0.004105352809910978 -1.5055457421150489 1.574901714216094" />
            <mass value="0.009930981" />
            <inertia ixx="8.84655879483303e-07" iyy="8.109636547560819e-07" izz="3.270751667606149e-07" ixy="0" ixz="0" iyz="0" />
        </inertial>
        <collision>
            <geometry>
                <mesh filename="package://allex_description/meshes/R_Thumb_Middle_Collision.stl" scale="0.001 0.001 0.001" />
            </geometry>
        </collision>
        <visual>
            <material name="gray"/>
            <geometry>
                <mesh filename="package://allex_description/meshes/R_Thumb_Middle_Gray.stl" scale="0.001 0.001 0.001" />
            </geometry>
        </visual>
        <visual>
            <material name="pad"/>
            <geometry>
                <mesh filename="package://allex_description/meshes/R_Thumb_Middle_Pad.stl" scale="0.001 0.001 0.001" />
            </geometry>
        </visual>
    </link>    
    <link name="R_Thumb_Distal_Link">
        <inertial>
            <origin xyz="3.439e-06 -0.005724653 0.00265343" rpy="0.4751480666064391 -1.5629018400246042 1.0965087296196254" />
            <mass value="0.00504" />
            <inertia ixx="3.6536667662865367e-07" iyy="3.4402416843769275e-07" izz="1.0507241568847662e-07" ixy="0" ixz="0" iyz="0" />
        </inertial>
        <collision>
            <geometry>
                <mesh filename="package://allex_description/meshes/R_Thumb_Distal_Collision.stl" scale="0.001 0.001 0.001" />
            </geometry>
        </collision>
        <visual>
            <material name="gray"/>
            <geometry>
                <mesh filename="package://allex_description/meshes/R_Thumb_Distal_Gray.stl" scale="0.001 0.001 0.001" />
            </geometry>
        </visual>
    </link>
    <link name="R_Thumb_Fingertip">
        <visual>
            <material name="pad"/>
            <geometry>
                <mesh filename="package://allex_description/meshes/R_Thumb_Distal_Pad.stl" scale="0.001 0.001 0.001" />
            </geometry>
        </visual>
    </link>
    <link name="R_Index_Roll_Link">
        <inertial>
            <origin xyz="-0.001315071 0.000324987 -0.001749841" rpy="-1.8382067637602202 -1.151471444372825 -3.0482554781624334" />
            <mass value="0.00611" />
            <inertia ixx="1.9798008349877536e-07" iyy="1.3571776663494185e-07" izz="1.0244531559103244e-07" ixy="0" ixz="0" iyz="0" />
        </inertial>
        <collision>
            <geometry>
                <mesh filename="package://allex_description/meshes/Finger_Roll_Collision.stl" scale="0.001 0.001 0.001" />
            </geometry>
        </collision>
        <visual>
            <material name="gray"/>
            <geometry>
                <mesh filename="package://allex_description/meshes/Finger_Roll_Gray.stl" scale="0.001 0.001 0.001" />
            </geometry>
        </visual>
    </link>
    <link name="R_Index_Proximal_Link">
        <inertial>
            <origin xyz="-0.005831596 4.2198e-05 -0.01921192" rpy="-0.17901800682656976 0.005048498440341387 1.5916388848469718" />
            <mass value="0.02387" />
            <inertia ixx="6.642950653324405e-06" iyy="6.5170055602217035e-06" izz="8.852664619138414e-07" ixy="0" ixz="0" iyz="0" />
        </inertial>
        <collision>
            <geometry>
                <mesh filename="package://allex_description/meshes/Finger_Proximal_Collision.stl" scale="0.001 0.001 0.001" />
            </geometry>
        </collision>
        <visual>
            <material name="white"/>
            <geometry>
                <mesh filename="package://allex_description/meshes/Finger_Proximal_White.stl" scale="0.001 0.001 0.001" />
            </geometry>
        </visual>
        <visual>
            <material name="gray"/>
            <geometry>
                <mesh filename="package://allex_description/meshes/Finger_Proximal_Gray.stl" scale="0.001 0.001 0.001" />
            </geometry>
        </visual>
        <visual>
            <material name="pad"/>
            <geometry>
                <mesh filename="package://allex_description/meshes/Finger_Proximal_Pad.stl" scale="0.001 0.001 0.001" />
            </geometry>
        </visual>
    </link>    
    <link name="R_Index_Middle_Link">
        <inertial>
            <origin xyz="-0.00171781 1.917e-06 -0.00601352" rpy="0.000304271917222844 0.12327199275049261 -0.0012306969719562465" />
            <mass value="0.00977" />
            <inertia ixx="7.395801063650778e-07" iyy="6.707525648021429e-07" izz="3.192749712872233e-07" ixy="0" ixz="0" iyz="0" />
        </inertial>
        <collision>
            <geometry>
                <mesh filename="package://allex_description/meshes/Finger_Middle_Collision.stl" scale="0.001 0.001 0.001" />
            </geometry>
        </collision>
        <visual>
            <material name="gray"/>
            <geometry>
                <mesh filename="package://allex_description/meshes/Finger_Middle_Gray.stl" scale="0.001 0.001 0.001" />
            </geometry>
        </visual>
        <visual>
            <material name="pad"/>
            <geometry>
                <mesh filename="package://allex_description/meshes/Finger_Middle_Pad.stl" scale="0.001 0.001 0.001" />
            </geometry>
        </visual>
    </link>
        <link name="R_Index_Distal_Link">
        <inertial>
            <origin xyz="-0.002635323 -3.528e-06 -0.00600072" rpy="-0.0008628048573492433 0.011544206563548265 0.0037502395629081865" />
            <mass value="0.00504" />
            <inertia ixx="3.4883691525890126e-07" iyy="3.281665762380144e-07" izz="1.0370759062476941e-07" ixy="0" ixz="0" iyz="0" />
        </inertial>
        <collision>
            <geometry>
                <mesh filename="package://allex_description/meshes/Finger_Distal_Collision.stl" scale="0.001 0.001 0.001" />
            </geometry>
        </collision>
        <visual>
            <material name="gray"/>
            <geometry>
                <mesh filename="package://allex_description/meshes/Finger_Distal_Gray.stl" scale="0.001 0.001 0.001" />
            </geometry>
        </visual>
    </link>
    <link name="R_Index_Fingertip">
        <visual>
            <material name="pad"/>
            <geometry>
                <mesh filename="package://allex_description/meshes/Finger_Distal_Pad.stl" scale="0.001 0.001 0.001" />
            </geometry>
        </visual>
    </link>
    <link name="R_Middle_Roll_Link">
        <inertial>
            <origin xyz="-0.001315071 0.000324987 -0.001749841" rpy="-1.8382067637602202 -1.151471444372825 -3.0482554781624334" />
            <mass value="0.00611" />
            <inertia ixx="1.9798008349877536e-07" iyy="1.3571776663494185e-07" izz="1.0244531559103244e-07" ixy="0" ixz="0" iyz="0" />
        </inertial>
        <collision>
            <geometry>
                <mesh filename="package://allex_description/meshes/Finger_Roll_Collision.stl" scale="0.001 0.001 0.001" />
            </geometry>
        </collision>
        <visual>
            <material name="gray"/>
            <geometry>
                <mesh filename="package://allex_description/meshes/Finger_Roll_Gray.stl" scale="0.001 0.001 0.001" />
            </geometry>
        </visual>
    </link>
    <link name="R_Middle_Proximal_Link">
        <inertial>
            <origin xyz="-0.005831596 4.2198e-05 -0.01921192" rpy="-0.17901800682656976 0.005048498440341387 1.5916388848469718" />
            <mass value="0.02387" />
            <inertia ixx="6.642950653324405e-06" iyy="6.5170055602217035e-06" izz="8.852664619138414e-07" ixy="0" ixz="0" iyz="0" />
        </inertial>
        <collision>
            <geometry>
                <mesh filename="package://allex_description/meshes/Finger_Proximal_Collision.stl" scale="0.001 0.001 0.001" />
            </geometry>
        </collision>
        <visual>
            <material name="white"/>
            <geometry>
                <mesh filename="package://allex_description/meshes/Finger_Proximal_White.stl" scale="0.001 0.001 0.001" />
            </geometry>
        </visual>
        <visual>
            <material name="gray"/>
            <geometry>
                <mesh filename="package://allex_description/meshes/Finger_Proximal_Gray.stl" scale="0.001 0.001 0.001" />
            </geometry>
        </visual>
        <visual>
            <material name="pad"/>
            <geometry>
                <mesh filename="package://allex_description/meshes/Finger_Proximal_Pad.stl" scale="0.001 0.001 0.001" />
            </geometry>
        </visual>
    </link>    
    <link name="R_Middle_Middle_Link">
        <inertial>
            <origin xyz="-0.00171781 1.917e-06 -0.00601352" rpy="0.000304271917222844 0.12327199275049261 -0.0012306969719562465" />
            <mass value="0.00977" />
            <inertia ixx="7.395801063650778e-07" iyy="6.707525648021429e-07" izz="3.192749712872233e-07" ixy="0" ixz="0" iyz="0" />
        </inertial>
        <collision>
            <geometry>
                <mesh filename="package://allex_description/meshes/Finger_Middle_Collision.stl" scale="0.001 0.001 0.001" />
            </geometry>
        </collision>
        <visual>
            <material name="gray"/>
            <geometry>
                <mesh filename="package://allex_description/meshes/Finger_Middle_Gray.stl" scale="0.001 0.001 0.001" />
            </geometry>
        </visual>
        <visual>
            <material name="pad"/>
            <geometry>
                <mesh filename="package://allex_description/meshes/Finger_Middle_Pad.stl" scale="0.001 0.001 0.001" />
            </geometry>
        </visual>
    </link>    
    <link name="R_Middle_Distal_Link">
        <inertial>
            <origin xyz="-0.002635323 -3.528e-06 -0.00600072" rpy="-0.0008628048573492433 0.011544206563548265 0.0037502395629081865" />
            <mass value="0.00504" />
            <inertia ixx="3.4883691525890126e-07" iyy="3.281665762380144e-07" izz="1.0370759062476941e-07" ixy="0" ixz="0" iyz="0" />
        </inertial>
        <collision>
            <geometry>
                <mesh filename="package://allex_description/meshes/Finger_Distal_Collision.stl" scale="0.001 0.001 0.001" />
            </geometry>
        </collision>
        <visual>
            <material name="gray"/>
            <geometry>
                <mesh filename="package://allex_description/meshes/Finger_Distal_Gray.stl" scale="0.001 0.001 0.001" />
            </geometry>
        </visual>
    </link>
    <link name="R_Middle_Fingertip">
        <visual>
            <material name="pad"/>
            <geometry>
                <mesh filename="package://allex_description/meshes/Finger_Distal_Pad.stl" scale="0.001 0.001 0.001" />
            </geometry>
        </visual>
    </link>
    <link name="R_Ring_Roll_Link">
        <inertial>
            <origin xyz="-0.001315071 0.000324987 -0.001749841" rpy="-1.8382067637602202 -1.151471444372825 -3.0482554781624334" />
            <mass value="0.00611" />
            <inertia ixx="1.9798008349877536e-07" iyy="1.3571776663494185e-07" izz="1.0244531559103244e-07" ixy="0" ixz="0" iyz="0" />
        </inertial>
        <collision>
            <geometry>
                <mesh filename="package://allex_description/meshes/Finger_Roll_Collision.stl" scale="0.001 0.001 0.001" />
            </geometry>
        </collision>
        <visual>
            <material name="gray"/>
            <geometry>
                <mesh filename="package://allex_description/meshes/Finger_Roll_Gray.stl" scale="0.001 0.001 0.001" />
            </geometry>
        </visual>
    </link>
    <link name="R_Ring_Proximal_Link">
        <inertial>
            <origin xyz="-0.005831596 4.2198e-05 -0.01921192" rpy="-0.17901800682656976 0.005048498440341387 1.5916388848469718" />
            <mass value="0.02387" />
            <inertia ixx="6.642950653324405e-06" iyy="6.5170055602217035e-06" izz="8.852664619138414e-07" ixy="0" ixz="0" iyz="0" />
        </inertial>
        <collision>
            <geometry>
                <mesh filename="package://allex_description/meshes/Finger_Proximal_Collision.stl" scale="0.001 0.001 0.001" />
            </geometry>
        </collision>
        <visual>
            <material name="white"/>
            <geometry>
                <mesh filename="package://allex_description/meshes/Finger_Proximal_White.stl" scale="0.001 0.001 0.001" />
            </geometry>
        </visual>
        <visual>
            <material name="gray"/>
            <geometry>
                <mesh filename="package://allex_description/meshes/Finger_Proximal_Gray.stl" scale="0.001 0.001 0.001" />
            </geometry>
        </visual>
        <visual>
            <material name="pad"/>
            <geometry>
                <mesh filename="package://allex_description/meshes/Finger_Proximal_Pad.stl" scale="0.001 0.001 0.001" />
            </geometry>
        </visual>
    </link>    
    <link name="R_Ring_Middle_Link">
        <inertial>
            <origin xyz="-0.00171781 1.917e-06 -0.00601352" rpy="0.000304271917222844 0.12327199275049261 -0.0012306969719562465" />
            <mass value="0.00977" />
            <inertia ixx="7.395801063650778e-07" iyy="6.707525648021429e-07" izz="3.192749712872233e-07" ixy="0" ixz="0" iyz="0" />
        </inertial>
        <collision>
            <geometry>
                <mesh filename="package://allex_description/meshes/Finger_Middle_Collision.stl" scale="0.001 0.001 0.001" />
            </geometry>
        </collision>
        <visual>
            <material name="gray"/>
            <geometry>
                <mesh filename="package://allex_description/meshes/Finger_Middle_Gray.stl" scale="0.001 0.001 0.001" />
            </geometry>
        </visual>
        <visual>
            <material name="pad"/>
            <geometry>
                <mesh filename="package://allex_description/meshes/Finger_Middle_Pad.stl" scale="0.001 0.001 0.001" />
            </geometry>
        </visual>
    </link>    
    <link name="R_Ring_Distal_Link">
        <inertial>
            <origin xyz="-0.002635323 -3.528e-06 -0.00600072" rpy="-0.0008628048573492433 0.011544206563548265 0.0037502395629081865" />
            <mass value="0.00504" />
            <inertia ixx="3.4883691525890126e-07" iyy="3.281665762380144e-07" izz="1.0370759062476941e-07" ixy="0" ixz="0" iyz="0" />
        </inertial>
        <collision>
            <geometry>
                <mesh filename="package://allex_description/meshes/Finger_Distal_Collision.stl" scale="0.001 0.001 0.001" />
            </geometry>
        </collision>
        <visual>
            <material name="gray"/>
            <geometry>
                <mesh filename="package://allex_description/meshes/Finger_Distal_Gray.stl" scale="0.001 0.001 0.001" />
            </geometry>
        </visual>
    </link>
    <link name="R_Ring_Fingertip">
        <visual>
            <material name="pad"/>
            <geometry>
                <mesh filename="package://allex_description/meshes/Finger_Distal_Pad.stl" scale="0.001 0.001 0.001" />
            </geometry>
        </visual>
    </link>
    <link name="R_Little_Roll_Link">
        <inertial>
            <origin xyz="-0.001315071 0.000324987 -0.001749841" rpy="-1.8382067637602202 -1.151471444372825 -3.0482554781624334" />
            <mass value="0.00611" />
            <inertia ixx="1.9798008349877536e-07" iyy="1.3571776663494185e-07" izz="1.0244531559103244e-07" ixy="0" ixz="0" iyz="0" />
        </inertial>
        <collision>
            <geometry>
                <mesh filename="package://allex_description/meshes/Finger_Roll_Collision.stl" scale="0.001 0.001 0.001" />
            </geometry>
        </collision>
        <visual>
            <material name="gray"/>
            <geometry>
                <mesh filename="package://allex_description/meshes/Finger_Roll_Gray.stl" scale="0.001 0.001 0.001" />
            </geometry>
        </visual>
    </link>
    <link name="R_Little_Proximal_Link">
        <inertial>
            <origin xyz="-0.005831596 4.2198e-05 -0.01921192" rpy="-0.17901800682656976 0.005048498440341387 1.5916388848469718" />
            <mass value="0.02175" />
            <inertia ixx="6.052960901122989e-06" iyy="5.938201547332301e-06" izz="8.066420421711759e-07" ixy="0" ixz="0" iyz="0" />
        </inertial>
        <collision>
            <geometry>
                <mesh filename="package://allex_description/meshes/Finger_Proximal_Collision.stl" scale="0.001 0.001 0.001" />
            </geometry>
        </collision>
        <visual>
            <material name="white"/>
            <geometry>
                <mesh filename="package://allex_description/meshes/Finger_Proximal_White.stl" scale="0.001 0.001 0.001" />
            </geometry>
        </visual>
        <visual>
            <material name="gray"/>
            <geometry>
                <mesh filename="package://allex_description/meshes/Finger_Proximal_Gray.stl" scale="0.001 0.001 0.001" />
            </geometry>
        </visual>
        <visual>
            <material name="pad"/>
            <geometry>
                <mesh filename="package://allex_description/meshes/Finger_Proximal_Pad.stl" scale="0.001 0.001 0.001" />
            </geometry>
        </visual>
    </link>
    <link name="R_Little_Middle_Link">
        <inertial>
            <origin xyz="-0.00171781 1.917e-06 -0.00601352" rpy="0.000304271917222844 0.12327199275049261 -0.0012306969719562465" />
            <mass value="0.00977" />
            <inertia ixx="7.395801063650778e-07" iyy="6.707525648021429e-07" izz="3.192749712872233e-07" ixy="0" ixz="0" iyz="0" />
        </inertial>
        <collision>
            <geometry>
                <mesh filename="package://allex_description/meshes/Finger_Middle_Collision.stl" scale="0.001 0.001 0.001" />
            </geometry>
        </collision>
        <visual>
            <material name="gray"/>
            <geometry>
                <mesh filename="package://allex_description/meshes/Finger_Middle_Gray.stl" scale="0.001 0.001 0.001" />
            </geometry>
        </visual>
        <visual>
            <material name="pad"/>
            <geometry>
                <mesh filename="package://allex_description/meshes/Finger_Middle_Pad.stl" scale="0.001 0.001 0.001" />
            </geometry>
        </visual>
    </link>
    <link name="R_Little_Distal_Link">
        <inertial>
            <origin xyz="-0.002635323 -3.528e-06 -0.00600072" rpy="-0.0008628048573492433 0.011544206563548265 0.0037502395629081865" />
            <mass value="0.00504" />
            <inertia ixx="3.4883691525890126e-07" iyy="3.281665762380144e-07" izz="1.0370759062476941e-07" ixy="0" ixz="0" iyz="0" />
        </inertial>
        <collision>
            <geometry>
                <mesh filename="package://allex_description/meshes/Finger_Distal_Collision.stl" scale="0.001 0.001 0.001" />
            </geometry>
        </collision>
        <visual>
            <material name="gray"/>
            <geometry>
                <mesh filename="package://allex_description/meshes/Finger_Distal_Gray.stl" scale="0.001 0.001 0.001" />
            </geometry>
        </visual>
    </link>
    <link name="R_Little_Fingertip">
        <visual>
            <material name="pad"/>
            <geometry>
                <mesh filename="package://allex_description/meshes/Finger_Distal_Pad.stl" scale="0.001 0.001 0.001" />
            </geometry>
        </visual>
    </link>
</robot>