<?xml version="1.0"?>
<robot name="ALLEX">
  <material name="black">
    <color rgba="0.12 0.12 0.12 1" />
  </material>
  <material name="gray">
    <color rgba="0.4 0.4 0.4 1" />
  </material>
  <material name="led">
    <color rgba="0.5 0.5 0.5 1" />
  </material>
  <material name="pad">
    <color rgba="0.7 0.7 0.7 1" />
  </material>
  <material name="white">
    <color rgba="0.98 0.98 0.98 1" />
  </material>
  <link name="Base_Link">
    <inertial>
      <origin xyz="0 0 0" rpy="0 0 0" />
      <mass value="3" />
      <inertia ixx="0.001" iyy="0.001" izz="0.001" ixy="0" ixz="0" iyz="0" />
    </inertial>
    <visual>
      <material name="black" />
      <geometry>
        <mesh filename="package://allex_description/meshes/Base_Black.stl" scale="0.001 0.001 0.001" />
      </geometry>
    </visual>
    <collision>
      <geometry>
        <mesh filename="package://allex_description/meshes/Base_Collision.stl" scale="0.001 0.001 0.001" />
      </geometry>
    </collision>
  </link>
  <link name="Waist_Yaw_Link">
    <inertial>
      <origin xyz="0.011694814 -0.023786125 0.046361293" rpy="0.259968702 0.428240346 2.35356093" />
      <mass value="3.62644339" />
      <inertia ixx="0.0313122248" iyy="0.0219634813" izz="0.0126712939" ixy="0" ixz="0" iyz="0" />
    </inertial>
    <visual>
      <material name="black" />
      <geometry>
        <mesh filename="package://allex_description/meshes/Waist_Yaw_Black.stl" scale="0.001 0.001 0.001" />
      </geometry>
    </visual>
    <collision>
      <geometry>
        <mesh filename="package://allex_description/meshes/Waist_Yaw_Collision.stl" scale="0.001 0.001 0.001" />
      </geometry>
    </collision>
  </link>
  <link name="Waist_Pitch_Back_Link">
    <inertial>
      <origin xyz="0.020387801 0.000182755 0.158712024" rpy="-0.00268672515 0.0134046624 0.00215068429" />
      <mass value="0.9409332" />
      <inertia ixx="0.0121847512" iyy="0.0101940477" izz="0.00248120117" ixy="0" ixz="0" iyz="0" />
    </inertial>
    <visual>
      <material name="gray" />
      <geometry>
        <mesh filename="package://allex_description/meshes/Waist_Pitch_Back_Gray.stl" scale="0.001 0.001 0.001" />
      </geometry>
    </visual>
  </link>
  <link name="Waist_Lower_Pitch_Link">
    <inertial>
      <origin xyz="-0.029734297 0.002246639 0.109363279" rpy="-0.125031374 -0.0109701097 1.50827196" />
      <mass value="5.75979036" />
      <inertia ixx="0.107743752" iyy="0.0995418049" izz="0.0203734433" ixy="0" ixz="0" iyz="0" />
    </inertial>
    <visual>
      <material name="gray" />
      <geometry>
        <mesh filename="package://allex_description/meshes/Waist_Pitch_Front_Gray.stl" scale="0.001 0.001 0.001" />
      </geometry>
    </visual>
    <collision>
      <geometry>
        <mesh filename="package://allex_description/meshes/Waist_Pitch_Front_Collision.stl" scale="0.001 0.001 0.001" />
      </geometry>
    </collision>
  </link>
  <link name="Waist_Upper_Pitch_Link">
    <inertial>
      <origin xyz="-0.0397 -0.0003 0.1189" rpy="1.58104391 1.2364387 0.00723096239" />
      <mass value="2.780295" />
      <inertia ixx="0.0185193677" iyy="0.0207840048" izz="0.0275323814" ixy="0" ixz="0" iyz="0" />
    </inertial>
    <visual>
      <material name="led" />
      <geometry>
        <mesh filename="package://allex_description/meshes/Chest_Led.stl" scale="0.001 0.001 0.001" />
      </geometry>
    </visual>
    <visual>
      <material name="white" />
      <geometry>
        <mesh filename="package://allex_description/meshes/Chest_White.stl" scale="0.001 0.001 0.001" />
      </geometry>
    </visual>
    <collision>
      <geometry>
        <mesh filename="package://allex_description/meshes/Chest_Collision.stl" scale="0.001 0.001 0.001" />
      </geometry>
    </collision>
  </link>
  <link name="Chest_Origin_Link">
    <inertial>
      <origin xyz="0 0 0" rpy="0 0 0" />
      <mass value="0" />
      <inertia ixx="0.001" iyy="0.001" izz="0.001" ixy="0" ixz="0" iyz="0" />
    </inertial>
  </link>
  <link name="Neck_Pitch_Link">
    <inertial>
      <origin xyz="-0.014276891 -0.005693118 0.046971122" rpy="0.17158581 -0.115494396 1.56078868" />
      <mass value="0.370429008" />
      <inertia ixx="0.00103317932" iyy="0.000981373088" izz="0.000342447591" ixy="0" ixz="0" iyz="0" />
    </inertial>
    <visual>
      <material name="gray" />
      <geometry>
        <mesh filename="package://allex_description/meshes/Neck_Pitch_Gray.stl" scale="0.001 0.001 0.001" />
      </geometry>
    </visual>
    <collision>
      <geometry>
        <mesh filename="package://allex_description/meshes/Neck_Pitch_Collision.stl" scale="0.001 0.001 0.001" />
      </geometry>
    </collision>
  </link>
  <link name="Neck_Yaw_Link">
    <inertial>
      <origin xyz="0.032970912 0.000181574 0.052561074" rpy="-0.0468871952 -0.215586144 0.164189303" />
      <mass value="1.88499431" />
      <inertia ixx="0.00743577958" iyy="0.00730382736" izz="0.00580839306" ixy="0" ixz="0" iyz="0" />
    </inertial>
    <visual>
      <material name="black" />
      <geometry>
        <mesh filename="package://allex_description/meshes/Neck_Yaw_Face.stl" scale="0.001 0.001 0.001" />
      </geometry>
    </visual>
    <visual>
      <material name="white" />
      <geometry>
        <mesh filename="package://allex_description/meshes/Neck_Yaw_Head.stl" scale="0.001 0.001 0.001" />
      </geometry>
    </visual>
    <visual>
      <material name="black" />
      <geometry>
        <mesh filename="package://allex_description/meshes/Neck_Yaw_Cam.stl" scale="0.001 0.001 0.001" />
      </geometry>
    </visual>
    <visual>
      <material name="led" />
      <geometry>
        <mesh filename="package://allex_description/meshes/Neck_Yaw_Led.stl" scale="0.001 0.001 0.001" />
      </geometry>
    </visual>
    <collision>
      <geometry>
        <mesh filename="package://allex_description/meshes/Neck_Yaw_Collision.stl" scale="0.001 0.001 0.001" />
      </geometry>
    </collision>
  </link>
  <link name="realsense_link" />
  <link name="orbbec_link" />
  <link name="zed_camera_link" />
  <link name="L_Shoulder_Pitch_Link">
    <inertial>
      <origin xyz="-0.09 0.0375 -0.0007" rpy="1.5580494 -0.11529304 2.04165189" />
      <mass value="1.01542188" />
      <inertia ixx="0.00793369722" iyy="0.00733584078" izz="0.002641462" ixy="0" ixz="0" iyz="0" />
    </inertial>
    <visual>
      <material name="black" />
      <geometry>
        <mesh filename="package://allex_description/meshes/L_Shoulder_Pitch_Black.stl" scale="0.001 0.001 0.001" />
      </geometry>
    </visual>
    <visual>
      <material name="white" />
      <geometry>
        <mesh filename="package://allex_description/meshes/L_Shoulder_Pitch_White.stl" scale="0.001 0.001 0.001" />
      </geometry>
    </visual>
    <collision>
      <geometry>
        <mesh filename="package://allex_description/meshes/L_Shoulder_Pitch_Collision1.stl" scale="0.001 0.001 0.001" />
      </geometry>
    </collision>
    <collision>
      <geometry>
        <mesh filename="package://allex_description/meshes/L_Shoulder_Pitch_Collision2.stl" scale="0.001 0.001 0.001" />
      </geometry>
    </collision>
    <collision>
      <geometry>
        <mesh filename="package://allex_description/meshes/L_Shoulder_Pitch_Collision3.stl" scale="0.001 0.001 0.001" />
      </geometry>
    </collision>
  </link>
  <link name="L_Shoulder_RollYaw_Link">
    <inertial>
      <origin xyz="0.0678 0.0001 0.04" rpy="-0.669358211 0.0278536652 1.60864428" />
      <mass value="2.86901452" />
      <inertia ixx="0.0164016202" iyy="0.0152242395" izz="0.00692814028" ixy="0" ixz="0" iyz="0" />
    </inertial>
    <visual>
      <material name="white" />
      <geometry>
        <mesh filename="package://allex_description/meshes/Shoulder_RollYaw_White.stl" scale="0.001 0.001 0.001" />
      </geometry>
    </visual>
    <collision>
      <geometry>
        <mesh filename="package://allex_description/meshes/Shoulder_RollYaw_Collision1.stl" scale="0.001 0.001 0.001" />
      </geometry>
    </collision>
    <collision>
      <geometry>
        <mesh filename="package://allex_description/meshes/Shoulder_RollYaw_Collision2.stl" scale="0.001 0.001 0.001" />
      </geometry>
    </collision>
  </link>
  <link name="L_Upper_Arm_Link">
    <inertial>
      <origin xyz="0.0013 0.0003 -0.1955" rpy="-3.02206816 1.53080048 -2.99558927" />
      <mass value="3.51" />
      <inertia ixx="0.00628165" iyy="0.029898693" izz="0.030695144" ixy="0" ixz="0" iyz="0" />
    </inertial>
    <visual>
      <material name="gray" />
      <geometry>
        <mesh filename="package://allex_description/meshes/Upper_Arm_Gray.stl" scale="0.001 0.001 0.001" />
      </geometry>
    </visual>
    <visual>
      <material name="white" />
      <geometry>
        <mesh filename="package://allex_description/meshes/Upper_Arm_White1.stl" scale="0.001 0.001 0.001" />
      </geometry>
    </visual>
    <visual>
      <material name="white" />
      <geometry>
        <mesh filename="package://allex_description/meshes/Upper_Arm_White2.stl" scale="0.001 0.001 0.001" />
      </geometry>
    </visual>
    <visual>
      <material name="white" />
      <geometry>
        <mesh filename="package://allex_description/meshes/Upper_Arm_White3.stl" scale="0.001 0.001 0.001" />
      </geometry>
    </visual>
    <visual>
      <material name="white" />
      <geometry>
        <mesh filename="package://allex_description/meshes/Upper_Arm_White4.stl" scale="0.001 0.001 0.001" />
      </geometry>
    </visual>
    <visual>
      <material name="white" />
      <geometry>
        <mesh filename="package://allex_description/meshes/Upper_Arm_White5.stl" scale="0.001 0.001 0.001" />
      </geometry>
    </visual>
    <visual>
      <material name="white" />
      <geometry>
        <mesh filename="package://allex_description/meshes/Upper_Arm_White6.stl" scale="0.001 0.001 0.001" />
      </geometry>
    </visual>
    <visual>
      <material name="white" />
      <geometry>
        <mesh filename="package://allex_description/meshes/Upper_Arm_White7.stl" scale="0.001 0.001 0.001" />
      </geometry>
    </visual>
    <visual>
      <material name="white" />
      <geometry>
        <mesh filename="package://allex_description/meshes/Upper_Arm_White8.stl" scale="0.001 0.001 0.001" />
      </geometry>
    </visual>
    <visual>
      <material name="white" />
      <geometry>
        <mesh filename="package://allex_description/meshes/Upper_Arm_White9.stl" scale="0.001 0.001 0.001" />
      </geometry>
    </visual>
    <collision>
      <geometry>
        <mesh filename="package://allex_description/meshes/Upper_Arm_Collision1.stl" scale="0.001 0.001 0.001" />
      </geometry>
    </collision>
    <collision>
      <geometry>
        <mesh filename="package://allex_description/meshes/Upper_Arm_Collision2.stl" scale="0.001 0.001 0.001" />
      </geometry>
    </collision>
    <collision>
      <geometry>
        <mesh filename="package://allex_description/meshes/Upper_Arm_Collision3.stl" scale="0.001 0.001 0.001" />
      </geometry>
    </collision>
  </link>
  <link name="L_Elbow_Link">
    <inertial>
      <origin xyz="-0.0231 5e-05 -0.0086" rpy="-0.0656563862 0.238783548 -0.000364268369" />
      <mass value="0.784434687" />
      <inertia ixx="0.000791828969" iyy="0.00153464464" izz="0.00182644434" ixy="0" ixz="0" iyz="0" />
    </inertial>
    <visual>
      <material name="gray" />
      <geometry>
        <mesh filename="package://allex_description/meshes/Elbow_Gray.stl" scale="0.001 0.001 0.001" />
      </geometry>
    </visual>
    <collision>
      <geometry>
        <mesh filename="package://allex_description/meshes/Elbow_Collision.stl" scale="0.001 0.001 0.001" />
      </geometry>
    </collision>
  </link>
  <link name="L_Forearm_Link">
    <inertial>
      <origin xyz="-0.0079 -0.0001 -0.1425" rpy="-1.58149419 -1.46449268 0.00786387073" />
      <mass value="3.1" />
      <inertia ixx="0.00391705254" iyy="0.0158883084" izz="0.0168914523" ixy="0" ixz="0" iyz="0" />
    </inertial>
    <visual>
      <material name="black" />
      <geometry>
        <mesh filename="package://allex_description/meshes/Forearm_Black.stl" scale="0.001 0.001 0.001" />
      </geometry>
    </visual>
    <visual>
      <material name="gray" />
      <geometry>
        <mesh filename="package://allex_description/meshes/Forearm_Gray.stl" scale="0.001 0.001 0.001" />
      </geometry>
    </visual>
    <visual>
      <material name="white" />
      <geometry>
        <mesh filename="package://allex_description/meshes/Forearm_White.stl" scale="0.001 0.001 0.001" />
      </geometry>
    </visual>
    <collision>
      <geometry>
        <mesh filename="package://allex_description/meshes/Forearm_Collision1.stl" scale="0.001 0.001 0.001" />
      </geometry>
    </collision>
    <collision>
      <geometry>
        <mesh filename="package://allex_description/meshes/Forearm_Collision2.stl" scale="0.001 0.001 0.001" />
      </geometry>
    </collision>
    <collision>
      <geometry>
        <mesh filename="package://allex_description/meshes/Forearm_Collision3.stl" scale="0.001 0.001 0.001" />
      </geometry>
    </collision>
  </link>
  <link name="L_Wrist_Roll_Link">
    <inertial>
      <origin xyz="-0.0004 0.0003 -0.023" rpy="1.66916973 0.624513123 0.120127939" />
      <mass value="0.172" />
      <inertia ixx="4.65972759e-05" iyy="3.3688034e-05" izz="1.77146901e-05" ixy="0" ixz="0" iyz="0" />
    </inertial>
    <visual>
      <material name="gray" />
      <geometry>
        <mesh filename="package://allex_description/meshes/Wrist_Roll_Gray.stl" scale="0.001 0.001 0.001" />
      </geometry>
    </visual>
    <collision>
      <geometry>
        <mesh filename="package://allex_description/meshes/Wrist_Roll_Collision.stl" scale="0.001 0.001 0.001" />
      </geometry>
    </collision>
  </link>
  <link name="L_Wrist_Pitch_Link">
    <inertial>
      <origin xyz="-0.0115 -0.0061 -0.1013" rpy="0.0083235297 0.0261360613 0.0238297314" />
      <mass value="0.97383" />
      <inertia ixx="0.00175102514" iyy="0.00137983739" izz="0.000570137469" ixy="0" ixz="0" iyz="0" />
    </inertial>
    <visual>
      <material name="gray" />
      <geometry>
        <mesh filename="package://allex_description/meshes/Wrist_Pitch_Gray.stl" scale="0.001 0.001 0.001" />
      </geometry>
    </visual>
    <collision>
      <geometry>
        <mesh filename="package://allex_description/meshes/Wrist_Pitch_Collision1.stl" scale="0.001 0.001 0.001" />
      </geometry>
    </collision>
    <collision>
      <geometry>
        <mesh filename="package://allex_description/meshes/Wrist_Pitch_Collision2.stl" scale="0.001 0.001 0.001" />
      </geometry>
    </collision>
    <collision>
      <geometry>
        <mesh filename="package://allex_description/meshes/Wrist_Pitch_Collision3.stl" scale="0.001 0.001 0.001" />
      </geometry>
    </collision>
  </link>
  <link name="L_Palm_Link">
    <inertial>
      <origin xyz="0 0 0" rpy="0 0 0" />
      <mass value="0" />
      <inertia ixx="0.001" iyy="0.001" izz="0.001" ixy="0" ixz="0" iyz="0" />
    </inertial>
    <visual>
      <material name="gray" />
      <geometry>
        <mesh filename="package://allex_description/meshes/L_Palm_Gray.stl" scale="0.001 0.001 0.001" />
      </geometry>
    </visual>
    <visual>
      <material name="pad" />
      <geometry>
        <mesh filename="package://allex_description/meshes/L_Palm_Pad.stl" scale="0.001 0.001 0.001" />
      </geometry>
    </visual>
    <visual>
      <material name="white" />
      <geometry>
        <mesh filename="package://allex_description/meshes/L_Palm_White.stl" scale="0.001 0.001 0.001" />
      </geometry>
    </visual>
    <collision>
      <geometry>
        <mesh filename="package://allex_description/meshes/L_Palm_Back_Collision1.stl" scale="0.001 0.001 0.001" />
      </geometry>
    </collision>
    <collision>
      <geometry>
        <mesh filename="package://allex_description/meshes/L_Palm_Back_Collision2.stl" scale="0.001 0.001 0.001" />
      </geometry>
    </collision>
    <collision>
      <geometry>
        <mesh filename="package://allex_description/meshes/L_Palm_Back_Collision3.stl" scale="0.001 0.001 0.001" />
      </geometry>
    </collision>
    <collision>
      <geometry>
        <mesh filename="package://allex_description/meshes/L_Palm_Frame_Collision1.stl" scale="0.001 0.001 0.001" />
      </geometry>
    </collision>
    <collision>
      <geometry>
        <mesh filename="package://allex_description/meshes/L_Palm_Frame_Collision2.stl" scale="0.001 0.001 0.001" />
      </geometry>
    </collision>
    <collision>
      <geometry>
        <mesh filename="package://allex_description/meshes/L_Palm_Frame_Collision3.stl" scale="0.001 0.001 0.001" />
      </geometry>
    </collision>
    <collision>
      <geometry>
        <mesh filename="package://allex_description/meshes/L_Palm_Frame_Collision4.stl" scale="0.001 0.001 0.001" />
      </geometry>
    </collision>
    <collision>
      <geometry>
        <mesh filename="package://allex_description/meshes/L_Palm_Frame_Collision5.stl" scale="0.001 0.001 0.001" />
      </geometry>
    </collision>
    <collision>
      <geometry>
        <mesh filename="package://allex_description/meshes/L_Palm_Frame_Collision6.stl" scale="0.001 0.001 0.001" />
      </geometry>
    </collision>
    <collision>
      <geometry>
        <mesh filename="package://allex_description/meshes/L_Palm_Frame_Collision7.stl" scale="0.001 0.001 0.001" />
      </geometry>
    </collision>
    <collision>
      <geometry>
        <mesh filename="package://allex_description/meshes/L_Palm_Pad_Collision1.stl" scale="0.001 0.001 0.001" />
      </geometry>
    </collision>
    <collision>
      <geometry>
        <mesh filename="package://allex_description/meshes/L_Palm_Pad_Collision2.stl" scale="0.001 0.001 0.001" />
      </geometry>
    </collision>
    <collision>
      <geometry>
        <mesh filename="package://allex_description/meshes/L_Palm_Pad_Collision3.stl" scale="0.001 0.001 0.001" />
      </geometry>
    </collision>
  </link>
  <link name="L_Thumb_Yaw_Link">
    <inertial>
      <origin xyz="-7.001e-06 0.002747764 -0.019328997" rpy="-0.0133832376 -0.302264329 1.60143597" />
      <mass value="0.032789432" />
      <inertia ixx="1.04786294e-05" iyy="1.04406183e-05" izz="1.50097565e-06" ixy="0" ixz="0" iyz="0" />
    </inertial>
    <visual>
      <material name="gray" />
      <geometry>
        <mesh filename="package://allex_description/meshes/L_Thumb_Yaw_Gray.stl" scale="0.001 0.001 0.001" />
      </geometry>
    </visual>
    <collision>
      <geometry>
        <mesh filename="package://allex_description/meshes/L_Thumb_Yaw_Collision.stl" scale="0.001 0.001 0.001" />
      </geometry>
    </collision>
  </link>
  <link name="L_Thumb_Proximal_Link">
    <inertial>
      <origin xyz="-5.9101e-05 0.015021659 0.007733297" rpy="1.84366861 -0.00399944438 -0.00259407196" />
      <mass value="0.027231496" />
      <inertia ixx="8.18647506e-06" iyy="7.02673901e-06" izz="1.95160136e-06" ixy="0" ixz="0" iyz="0" />
    </inertial>
    <visual>
      <material name="gray" />
      <geometry>
        <mesh filename="package://allex_description/meshes/L_Thumb_Proximal_Gray.stl" scale="0.001 0.001 0.001" />
      </geometry>
    </visual>
    <visual>
      <material name="pad" />
      <geometry>
        <mesh filename="package://allex_description/meshes/L_Thumb_Proximal_Pad.stl" scale="0.001 0.001 0.001" />
      </geometry>
    </visual>
    <visual>
      <material name="white" />
      <geometry>
        <mesh filename="package://allex_description/meshes/L_Thumb_Proximal_White.stl" scale="0.001 0.001 0.001" />
      </geometry>
    </visual>
    <collision>
      <geometry>
        <mesh filename="package://allex_description/meshes/L_Thumb_Proximal_Collision1.stl" scale="0.001 0.001 0.001" />
      </geometry>
    </collision>
    <collision>
      <geometry>
        <mesh filename="package://allex_description/meshes/L_Thumb_Proximal_Collision2.stl" scale="0.001 0.001 0.001" />
      </geometry>
    </collision>
    <collision>
      <geometry>
        <mesh filename="package://allex_description/meshes/L_Thumb_Proximal_Collision3.stl" scale="0.001 0.001 0.001" />
      </geometry>
    </collision>
    <collision>
      <geometry>
        <mesh filename="package://allex_description/meshes/L_Thumb_Proximal_Collision4.stl" scale="0.001 0.001 0.001" />
      </geometry>
    </collision>
  </link>
  <link name="L_Thumb_Middle_Link">
    <inertial>
      <origin xyz="4.85e-07 0.006779487 -0.00176946" rpy="-3.1374873 -1.50554574 -1.57490171" />
      <mass value="0.009930981" />
      <inertia ixx="8.84655879e-07" iyy="8.10963655e-07" izz="3.27075167e-07" ixy="0" ixz="0" iyz="0" />
    </inertial>
    <visual>
      <material name="gray" />
      <geometry>
        <mesh filename="package://allex_description/meshes/L_Thumb_Middle_Gray.stl" scale="0.001 0.001 0.001" />
      </geometry>
    </visual>
    <visual>
      <material name="pad" />
      <geometry>
        <mesh filename="package://allex_description/meshes/L_Thumb_Middle_Pad.stl" scale="0.001 0.001 0.001" />
      </geometry>
    </visual>
    <collision>
      <geometry>
        <mesh filename="package://allex_description/meshes/L_Thumb_Middle_Collision.stl" scale="0.001 0.001 0.001" />
      </geometry>
    </collision>
  </link>
  <link name="L_Thumb_Distal_Link">
    <inertial>
      <origin xyz="3.439e-06 0.005724653 0.00265343" rpy="2.66644458 -1.56290184 -1.09650873" />
      <mass value="0.00504" />
      <inertia ixx="3.65366677e-07" iyy="3.44024168e-07" izz="1.05072416e-07" ixy="0" ixz="0" iyz="0" />
    </inertial>
    <visual>
      <material name="gray" />
      <geometry>
        <mesh filename="package://allex_description/meshes/L_Thumb_Distal_Gray.stl" scale="0.001 0.001 0.001" />
      </geometry>
    </visual>
    <collision>
      <geometry>
        <mesh filename="package://allex_description/meshes/L_Thumb_Distal_Collision.stl" scale="0.001 0.001 0.001" />
      </geometry>
    </collision>
  </link>
  <link name="L_Thumb_Fingertip">
    <visual>
      <material name="pad" />
      <geometry>
        <mesh filename="package://allex_description/meshes/L_Thumb_Distal_Pad.stl" scale="0.001 0.001 0.001" />
      </geometry>
    </visual>
  </link>
  <link name="L_Index_Roll_Link">
    <inertial>
      <origin xyz="-0.001315071 0.000324987 -0.001749841" rpy="-1.83820676 -1.15147144 -3.04825548" />
      <mass value="0.00611" />
      <inertia ixx="1.97980083e-07" iyy="1.35717767e-07" izz="1.02445316e-07" ixy="0" ixz="0" iyz="0" />
    </inertial>
    <visual>
      <material name="gray" />
      <geometry>
        <mesh filename="package://allex_description/meshes/Finger_Roll_Gray.stl" scale="0.001 0.001 0.001" />
      </geometry>
    </visual>
    <collision>
      <geometry>
        <mesh filename="package://allex_description/meshes/Finger_Roll_Collision.stl" scale="0.001 0.001 0.001" />
      </geometry>
    </collision>
  </link>
  <link name="L_Index_Proximal_Link">
    <inertial>
      <origin xyz="-0.005831596 4.2198e-05 -0.01921192" rpy="-0.179018007 0.00504849843 1.59163888" />
      <mass value="0.02387" />
      <inertia ixx="6.64295065e-06" iyy="6.51700556e-06" izz="8.85266462e-07" ixy="0" ixz="0" iyz="0" />
    </inertial>
    <visual>
      <material name="gray" />
      <geometry>
        <mesh filename="package://allex_description/meshes/Finger_Proximal_Gray.stl" scale="0.001 0.001 0.001" />
      </geometry>
    </visual>
    <visual>
      <material name="pad" />
      <geometry>
        <mesh filename="package://allex_description/meshes/Finger_Proximal_Pad.stl" scale="0.001 0.001 0.001" />
      </geometry>
    </visual>
    <visual>
      <material name="white" />
      <geometry>
        <mesh filename="package://allex_description/meshes/Finger_Proximal_White.stl" scale="0.001 0.001 0.001" />
      </geometry>
    </visual>
    <collision>
      <geometry>
        <mesh filename="package://allex_description/meshes/Finger_Proximal_Collision.stl" scale="0.001 0.001 0.001" />
      </geometry>
    </collision>
  </link>
  <link name="L_Index_Middle_Link">
    <inertial>
      <origin xyz="-0.00171781 1.917e-06 -0.00601352" rpy="0.000304271917 0.123271993 -0.00123069697" />
      <mass value="0.00977" />
      <inertia ixx="7.39580106e-07" iyy="6.70752565e-07" izz="3.19274971e-07" ixy="0" ixz="0" iyz="0" />
    </inertial>
    <visual>
      <material name="gray" />
      <geometry>
        <mesh filename="package://allex_description/meshes/Finger_Middle_Gray.stl" scale="0.001 0.001 0.001" />
      </geometry>
    </visual>
    <visual>
      <material name="pad" />
      <geometry>
        <mesh filename="package://allex_description/meshes/Finger_Middle_Pad.stl" scale="0.001 0.001 0.001" />
      </geometry>
    </visual>
    <collision>
      <geometry>
        <mesh filename="package://allex_description/meshes/Finger_Middle_Collision.stl" scale="0.001 0.001 0.001" />
      </geometry>
    </collision>
  </link>
  <link name="L_Index_Distal_Link">
    <inertial>
      <origin xyz="-0.002635323 -3.528e-06 -0.00600072" rpy="-0.000862804857 0.0115442066 0.00375023956" />
      <mass value="0.00504" />
      <inertia ixx="3.48836915e-07" iyy="3.28166576e-07" izz="1.03707591e-07" ixy="0" ixz="0" iyz="0" />
    </inertial>
    <visual>
      <material name="gray" />
      <geometry>
        <mesh filename="package://allex_description/meshes/Finger_Distal_Gray.stl" scale="0.001 0.001 0.001" />
      </geometry>
    </visual>
    <collision>
      <geometry>
        <mesh filename="package://allex_description/meshes/Finger_Distal_Collision.stl" scale="0.001 0.001 0.001" />
      </geometry>
    </collision>
  </link>
  <link name="L_Index_Fingertip">
    <visual>
      <material name="pad" />
      <geometry>
        <mesh filename="package://allex_description/meshes/Finger_Distal_Pad.stl" scale="0.001 0.001 0.001" />
      </geometry>
    </visual>
  </link>
  <link name="L_Middle_Roll_Link">
    <inertial>
      <origin xyz="-0.001315071 0.000324987 -0.001749841" rpy="-1.83820676 -1.15147144 -3.04825548" />
      <mass value="0.00611" />
      <inertia ixx="1.97980083e-07" iyy="1.35717767e-07" izz="1.02445316e-07" ixy="0" ixz="0" iyz="0" />
    </inertial>
    <visual>
      <material name="gray" />
      <geometry>
        <mesh filename="package://allex_description/meshes/Finger_Roll_Gray.stl" scale="0.001 0.001 0.001" />
      </geometry>
    </visual>
    <collision>
      <geometry>
        <mesh filename="package://allex_description/meshes/Finger_Roll_Collision.stl" scale="0.001 0.001 0.001" />
      </geometry>
    </collision>
  </link>
  <link name="L_Middle_Proximal_Link">
    <inertial>
      <origin xyz="-0.005831596 4.2198e-05 -0.01921192" rpy="-0.179018007 0.00504849843 1.59163888" />
      <mass value="0.02387" />
      <inertia ixx="6.64295065e-06" iyy="6.51700556e-06" izz="8.85266462e-07" ixy="0" ixz="0" iyz="0" />
    </inertial>
    <visual>
      <material name="gray" />
      <geometry>
        <mesh filename="package://allex_description/meshes/Finger_Proximal_Gray.stl" scale="0.001 0.001 0.001" />
      </geometry>
    </visual>
    <visual>
      <material name="pad" />
      <geometry>
        <mesh filename="package://allex_description/meshes/Finger_Proximal_Pad.stl" scale="0.001 0.001 0.001" />
      </geometry>
    </visual>
    <visual>
      <material name="white" />
      <geometry>
        <mesh filename="package://allex_description/meshes/Finger_Proximal_White.stl" scale="0.001 0.001 0.001" />
      </geometry>
    </visual>
    <collision>
      <geometry>
        <mesh filename="package://allex_description/meshes/Finger_Proximal_Collision.stl" scale="0.001 0.001 0.001" />
      </geometry>
    </collision>
  </link>
  <link name="L_Middle_Middle_Link">
    <inertial>
      <origin xyz="-0.00171781 1.917e-06 -0.00601352" rpy="0.000304271917 0.123271993 -0.00123069697" />
      <mass value="0.00977" />
      <inertia ixx="7.39580106e-07" iyy="6.70752565e-07" izz="3.19274971e-07" ixy="0" ixz="0" iyz="0" />
    </inertial>
    <visual>
      <material name="gray" />
      <geometry>
        <mesh filename="package://allex_description/meshes/Finger_Middle_Gray.stl" scale="0.001 0.001 0.001" />
      </geometry>
    </visual>
    <visual>
      <material name="pad" />
      <geometry>
        <mesh filename="package://allex_description/meshes/Finger_Middle_Pad.stl" scale="0.001 0.001 0.001" />
      </geometry>
    </visual>
    <collision>
      <geometry>
        <mesh filename="package://allex_description/meshes/Finger_Middle_Collision.stl" scale="0.001 0.001 0.001" />
      </geometry>
    </collision>
  </link>
  <link name="L_Middle_Distal_Link">
    <inertial>
      <origin xyz="-0.002635323 -3.528e-06 -0.00600072" rpy="-0.000862804857 0.0115442066 0.00375023956" />
      <mass value="0.00504" />
      <inertia ixx="3.48836915e-07" iyy="3.28166576e-07" izz="1.03707591e-07" ixy="0" ixz="0" iyz="0" />
    </inertial>
    <visual>
      <material name="gray" />
      <geometry>
        <mesh filename="package://allex_description/meshes/Finger_Distal_Gray.stl" scale="0.001 0.001 0.001" />
      </geometry>
    </visual>
    <collision>
      <geometry>
        <mesh filename="package://allex_description/meshes/Finger_Distal_Collision.stl" scale="0.001 0.001 0.001" />
      </geometry>
    </collision>
  </link>
  <link name="L_Middle_Fingertip">
    <visual>
      <material name="pad" />
      <geometry>
        <mesh filename="package://allex_description/meshes/Finger_Distal_Pad.stl" scale="0.001 0.001 0.001" />
      </geometry>
    </visual>
  </link>
  <link name="L_Ring_Roll_Link">
    <inertial>
      <origin xyz="-0.001315071 0.000324987 -0.001749841" rpy="-1.83820676 -1.15147144 -3.04825548" />
      <mass value="0.00611" />
      <inertia ixx="1.97980083e-07" iyy="1.35717767e-07" izz="1.02445316e-07" ixy="0" ixz="0" iyz="0" />
    </inertial>
    <visual>
      <material name="gray" />
      <geometry>
        <mesh filename="package://allex_description/meshes/Finger_Roll_Gray.stl" scale="0.001 0.001 0.001" />
      </geometry>
    </visual>
    <collision>
      <geometry>
        <mesh filename="package://allex_description/meshes/Finger_Roll_Collision.stl" scale="0.001 0.001 0.001" />
      </geometry>
    </collision>
  </link>
  <link name="L_Ring_Proximal_Link">
    <inertial>
      <origin xyz="-0.005831596 4.2198e-05 -0.01921192" rpy="-0.179018007 0.00504849843 1.59163888" />
      <mass value="0.02387" />
      <inertia ixx="6.64295065e-06" iyy="6.51700556e-06" izz="8.85266462e-07" ixy="0" ixz="0" iyz="0" />
    </inertial>
    <visual>
      <material name="gray" />
      <geometry>
        <mesh filename="package://allex_description/meshes/Finger_Proximal_Gray.stl" scale="0.001 0.001 0.001" />
      </geometry>
    </visual>
    <visual>
      <material name="pad" />
      <geometry>
        <mesh filename="package://allex_description/meshes/Finger_Proximal_Pad.stl" scale="0.001 0.001 0.001" />
      </geometry>
    </visual>
    <visual>
      <material name="white" />
      <geometry>
        <mesh filename="package://allex_description/meshes/Finger_Proximal_White.stl" scale="0.001 0.001 0.001" />
      </geometry>
    </visual>
    <collision>
      <geometry>
        <mesh filename="package://allex_description/meshes/Finger_Proximal_Collision.stl" scale="0.001 0.001 0.001" />
      </geometry>
    </collision>
  </link>
  <link name="L_Ring_Middle_Link">
    <inertial>
      <origin xyz="-0.00171781 1.917e-06 -0.00601352" rpy="0.000304271917 0.123271993 -0.00123069697" />
      <mass value="0.00977" />
      <inertia ixx="7.39580106e-07" iyy="6.70752565e-07" izz="3.19274971e-07" ixy="0" ixz="0" iyz="0" />
    </inertial>
    <visual>
      <material name="gray" />
      <geometry>
        <mesh filename="package://allex_description/meshes/Finger_Middle_Gray.stl" scale="0.001 0.001 0.001" />
      </geometry>
    </visual>
    <visual>
      <material name="pad" />
      <geometry>
        <mesh filename="package://allex_description/meshes/Finger_Middle_Pad.stl" scale="0.001 0.001 0.001" />
      </geometry>
    </visual>
    <collision>
      <geometry>
        <mesh filename="package://allex_description/meshes/Finger_Middle_Collision.stl" scale="0.001 0.001 0.001" />
      </geometry>
    </collision>
  </link>
  <link name="L_Ring_Distal_Link">
    <inertial>
      <origin xyz="-0.002635323 -3.528e-06 -0.00600072" rpy="-0.000862804857 0.0115442066 0.00375023956" />
      <mass value="0.00504" />
      <inertia ixx="3.48836915e-07" iyy="3.28166576e-07" izz="1.03707591e-07" ixy="0" ixz="0" iyz="0" />
    </inertial>
    <visual>
      <material name="gray" />
      <geometry>
        <mesh filename="package://allex_description/meshes/Finger_Distal_Gray.stl" scale="0.001 0.001 0.001" />
      </geometry>
    </visual>
    <collision>
      <geometry>
        <mesh filename="package://allex_description/meshes/Finger_Distal_Collision.stl" scale="0.001 0.001 0.001" />
      </geometry>
    </collision>
  </link>
  <link name="L_Ring_Fingertip">
    <visual>
      <material name="pad" />
      <geometry>
        <mesh filename="package://allex_description/meshes/Finger_Distal_Pad.stl" scale="0.001 0.001 0.001" />
      </geometry>
    </visual>
  </link>
  <link name="L_Little_Roll_Link">
    <inertial>
      <origin xyz="-0.001315071 0.000324987 -0.001749841" rpy="-1.83820676 -1.15147144 -3.04825548" />
      <mass value="0.00611" />
      <inertia ixx="1.97980083e-07" iyy="1.35717767e-07" izz="1.02445316e-07" ixy="0" ixz="0" iyz="0" />
    </inertial>
    <visual>
      <material name="gray" />
      <geometry>
        <mesh filename="package://allex_description/meshes/Finger_Roll_Gray.stl" scale="0.001 0.001 0.001" />
      </geometry>
    </visual>
    <collision>
      <geometry>
        <mesh filename="package://allex_description/meshes/Finger_Roll_Collision.stl" scale="0.001 0.001 0.001" />
      </geometry>
    </collision>
  </link>
  <link name="L_Little_Proximal_Link">
    <inertial>
      <origin xyz="-0.005831596 4.2198e-05 -0.01921192" rpy="-0.179018007 0.00504849843 1.59163888" />
      <mass value="0.02175" />
      <inertia ixx="6.0529609e-06" iyy="5.93820155e-06" izz="8.06642042e-07" ixy="0" ixz="0" iyz="0" />
    </inertial>
    <visual>
      <material name="gray" />
      <geometry>
        <mesh filename="package://allex_description/meshes/Finger_Proximal_Gray.stl" scale="0.001 0.001 0.001" />
      </geometry>
    </visual>
    <visual>
      <material name="pad" />
      <geometry>
        <mesh filename="package://allex_description/meshes/Finger_Proximal_Pad.stl" scale="0.001 0.001 0.001" />
      </geometry>
    </visual>
    <visual>
      <material name="white" />
      <geometry>
        <mesh filename="package://allex_description/meshes/Finger_Proximal_White.stl" scale="0.001 0.001 0.001" />
      </geometry>
    </visual>
    <collision>
      <geometry>
        <mesh filename="package://allex_description/meshes/Finger_Proximal_Collision.stl" scale="0.001 0.001 0.001" />
      </geometry>
    </collision>
  </link>
  <link name="L_Little_Middle_Link">
    <inertial>
      <origin xyz="-0.00171781 1.917e-06 -0.00601352" rpy="0.000304271917 0.123271993 -0.00123069697" />
      <mass value="0.00977" />
      <inertia ixx="7.39580106e-07" iyy="6.70752565e-07" izz="3.19274971e-07" ixy="0" ixz="0" iyz="0" />
    </inertial>
    <visual>
      <material name="gray" />
      <geometry>
        <mesh filename="package://allex_description/meshes/Finger_Middle_Gray.stl" scale="0.001 0.001 0.001" />
      </geometry>
    </visual>
    <visual>
      <material name="pad" />
      <geometry>
        <mesh filename="package://allex_description/meshes/Finger_Middle_Pad.stl" scale="0.001 0.001 0.001" />
      </geometry>
    </visual>
    <collision>
      <geometry>
        <mesh filename="package://allex_description/meshes/Finger_Middle_Collision.stl" scale="0.001 0.001 0.001" />
      </geometry>
    </collision>
  </link>
  <link name="L_Little_Distal_Link">
    <inertial>
      <origin xyz="-0.002635323 -3.528e-06 -0.00600072" rpy="-0.000862804857 0.0115442066 0.00375023956" />
      <mass value="0.00504" />
      <inertia ixx="3.48836915e-07" iyy="3.28166576e-07" izz="1.03707591e-07" ixy="0" ixz="0" iyz="0" />
    </inertial>
    <visual>
      <material name="gray" />
      <geometry>
        <mesh filename="package://allex_description/meshes/Finger_Distal_Gray.stl" scale="0.001 0.001 0.001" />
      </geometry>
    </visual>
    <collision>
      <geometry>
        <mesh filename="package://allex_description/meshes/Finger_Distal_Collision.stl" scale="0.001 0.001 0.001" />
      </geometry>
    </collision>
  </link>
  <link name="L_Little_Fingertip">
    <visual>
      <material name="pad" />
      <geometry>
        <mesh filename="package://allex_description/meshes/Finger_Distal_Pad.stl" scale="0.001 0.001 0.001" />
      </geometry>
    </visual>
  </link>
  <link name="R_Shoulder_Pitch_Link">
    <inertial>
      <origin xyz="-0.09 -0.0375 -0.0007" rpy="1.5580494 0.11529304 1.09994077" />
      <mass value="1.01542188" />
      <inertia ixx="0.00793369722" iyy="0.00733584078" izz="0.002641462" ixy="0" ixz="0" iyz="0" />
    </inertial>
    <visual>
      <material name="black" />
      <geometry>
        <mesh filename="package://allex_description/meshes/R_Shoulder_Pitch_Black.stl" scale="0.001 0.001 0.001" />
      </geometry>
    </visual>
    <visual>
      <material name="white" />
      <geometry>
        <mesh filename="package://allex_description/meshes/R_Shoulder_Pitch_White.stl" scale="0.001 0.001 0.001" />
      </geometry>
    </visual>
    <collision>
      <geometry>
        <mesh filename="package://allex_description/meshes/R_Shoulder_Pitch_Collision1.stl" scale="0.001 0.001 0.001" />
      </geometry>
    </collision>
    <collision>
      <geometry>
        <mesh filename="package://allex_description/meshes/R_Shoulder_Pitch_Collision2.stl" scale="0.001 0.001 0.001" />
      </geometry>
    </collision>
    <collision>
      <geometry>
        <mesh filename="package://allex_description/meshes/R_Shoulder_Pitch_Collision3.stl" scale="0.001 0.001 0.001" />
      </geometry>
    </collision>
  </link>
  <link name="R_Shoulder_RollYaw_Link">
    <inertial>
      <origin xyz="0.0678 0.0001 0.04" rpy="-0.669358211 0.0278536652 1.60864428" />
      <mass value="2.86901452" />
      <inertia ixx="0.0164016202" iyy="0.0152242395" izz="0.00692814028" ixy="0" ixz="0" iyz="0" />
    </inertial>
    <visual>
      <material name="white" />
      <geometry>
        <mesh filename="package://allex_description/meshes/Shoulder_RollYaw_White.stl" scale="0.001 0.001 0.001" />
      </geometry>
    </visual>
    <collision>
      <geometry>
        <mesh filename="package://allex_description/meshes/Shoulder_RollYaw_Collision1.stl" scale="0.001 0.001 0.001" />
      </geometry>
    </collision>
    <collision>
      <geometry>
        <mesh filename="package://allex_description/meshes/Shoulder_RollYaw_Collision2.stl" scale="0.001 0.001 0.001" />
      </geometry>
    </collision>
  </link>
  <link name="R_Upper_Arm_Link">
    <inertial>
      <origin xyz="0.0013 0.0003 -0.1955" rpy="-3.02206816 1.53080048 -2.99558927" />
      <mass value="3.51" />
      <inertia ixx="0.0062815" iyy="0.029898693" izz="0.030695144" ixy="0" ixz="0" iyz="0" />
    </inertial>
    <visual>
      <material name="gray" />
      <geometry>
        <mesh filename="package://allex_description/meshes/Upper_Arm_Gray.stl" scale="0.001 0.001 0.001" />
      </geometry>
    </visual>
    <visual>
      <material name="white" />
      <geometry>
        <mesh filename="package://allex_description/meshes/Upper_Arm_White1.stl" scale="0.001 0.001 0.001" />
      </geometry>
    </visual>
    <visual>
      <material name="white" />
      <geometry>
        <mesh filename="package://allex_description/meshes/Upper_Arm_White2.stl" scale="0.001 0.001 0.001" />
      </geometry>
    </visual>
    <visual>
      <material name="white" />
      <geometry>
        <mesh filename="package://allex_description/meshes/Upper_Arm_White3.stl" scale="0.001 0.001 0.001" />
      </geometry>
    </visual>
    <visual>
      <material name="white" />
      <geometry>
        <mesh filename="package://allex_description/meshes/Upper_Arm_White4.stl" scale="0.001 0.001 0.001" />
      </geometry>
    </visual>
    <visual>
      <material name="white" />
      <geometry>
        <mesh filename="package://allex_description/meshes/Upper_Arm_White5.stl" scale="0.001 0.001 0.001" />
      </geometry>
    </visual>
    <visual>
      <material name="white" />
      <geometry>
        <mesh filename="package://allex_description/meshes/Upper_Arm_White6.stl" scale="0.001 0.001 0.001" />
      </geometry>
    </visual>
    <visual>
      <material name="white" />
      <geometry>
        <mesh filename="package://allex_description/meshes/Upper_Arm_White7.stl" scale="0.001 0.001 0.001" />
      </geometry>
    </visual>
    <visual>
      <material name="white" />
      <geometry>
        <mesh filename="package://allex_description/meshes/Upper_Arm_White8.stl" scale="0.001 0.001 0.001" />
      </geometry>
    </visual>
    <visual>
      <material name="white" />
      <geometry>
        <mesh filename="package://allex_description/meshes/Upper_Arm_White9.stl" scale="0.001 0.001 0.001" />
      </geometry>
    </visual>
    <collision>
      <geometry>
        <mesh filename="package://allex_description/meshes/Upper_Arm_Collision1.stl" scale="0.001 0.001 0.001" />
      </geometry>
    </collision>
    <collision>
      <geometry>
        <mesh filename="package://allex_description/meshes/Upper_Arm_Collision2.stl" scale="0.001 0.001 0.001" />
      </geometry>
    </collision>
    <collision>
      <geometry>
        <mesh filename="package://allex_description/meshes/Upper_Arm_Collision3.stl" scale="0.001 0.001 0.001" />
      </geometry>
    </collision>
  </link>
  <link name="R_Elbow_Link">
    <inertial>
      <origin xyz="-0.0231 5e-05 -0.0086" rpy="-0.0656563862 0.238783548 -0.000364268369" />
      <mass value="0.784434687" />
      <inertia ixx="0.000791828969" iyy="0.00153464464" izz="0.00182644434" ixy="0" ixz="0" iyz="0" />
    </inertial>
    <visual>
      <material name="gray" />
      <geometry>
        <mesh filename="package://allex_description/meshes/Elbow_Gray.stl" scale="0.001 0.001 0.001" />
      </geometry>
    </visual>
    <collision>
      <geometry>
        <mesh filename="package://allex_description/meshes/Elbow_Collision.stl" scale="0.001 0.001 0.001" />
      </geometry>
    </collision>
  </link>
  <link name="R_Forearm_Link">
    <inertial>
      <origin xyz="-0.0079 -0.0001 -0.1425" rpy="-1.58149419 -1.46449268 0.00786387073" />
      <mass value="3.1" />
      <inertia ixx="0.00391705254" iyy="0.0158883084" izz="0.0168914523" ixy="0" ixz="0" iyz="0" />
    </inertial>
    <visual>
      <material name="black" />
      <geometry>
        <mesh filename="package://allex_description/meshes/Forearm_Black.stl" scale="0.001 0.001 0.001" />
      </geometry>
    </visual>
    <visual>
      <material name="gray" />
      <geometry>
        <mesh filename="package://allex_description/meshes/Forearm_Gray.stl" scale="0.001 0.001 0.001" />
      </geometry>
    </visual>
    <visual>
      <material name="white" />
      <geometry>
        <mesh filename="package://allex_description/meshes/Forearm_White.stl" scale="0.001 0.001 0.001" />
      </geometry>
    </visual>
    <collision>
      <geometry>
        <mesh filename="package://allex_description/meshes/Forearm_Collision1.stl" scale="0.001 0.001 0.001" />
      </geometry>
    </collision>
    <collision>
      <geometry>
        <mesh filename="package://allex_description/meshes/Forearm_Collision2.stl" scale="0.001 0.001 0.001" />
      </geometry>
    </collision>
    <collision>
      <geometry>
        <mesh filename="package://allex_description/meshes/Forearm_Collision3.stl" scale="0.001 0.001 0.001" />
      </geometry>
    </collision>
  </link>
  <link name="R_Wrist_Roll_Link">
    <inertial>
      <origin xyz="-0.0004 0.0003 -0.023" rpy="1.66916973 0.624513123 0.120127939" />
      <mass value="0.172" />
      <inertia ixx="4.65972759e-05" iyy="3.3688034e-05" izz="1.77146901e-05" ixy="0" ixz="0" iyz="0" />
    </inertial>
    <visual>
      <material name="gray" />
      <geometry>
        <mesh filename="package://allex_description/meshes/Wrist_Roll_Gray.stl" scale="0.001 0.001 0.001" />
      </geometry>
    </visual>
    <collision>
      <geometry>
        <mesh filename="package://allex_description/meshes/Wrist_Roll_Collision.stl" scale="0.001 0.001 0.001" />
      </geometry>
    </collision>
  </link>
  <link name="R_Wrist_Pitch_Link">
    <inertial>
      <origin xyz="-0.0115 -0.0061 -0.1013" rpy="-0.0083235297 0.0261360613 -0.0238297314" />
      <mass value="0.97383" />
      <inertia ixx="0.00175102514" iyy="0.00137983739" izz="0.000570137469" ixy="0" ixz="0" iyz="0" />
    </inertial>
    <visual>
      <material name="gray" />
      <geometry>
        <mesh filename="package://allex_description/meshes/Wrist_Pitch_Gray.stl" scale="0.001 0.001 0.001" />
      </geometry>
    </visual>
    <collision>
      <geometry>
        <mesh filename="package://allex_description/meshes/Wrist_Pitch_Collision1.stl" scale="0.001 0.001 0.001" />
      </geometry>
    </collision>
    <collision>
      <geometry>
        <mesh filename="package://allex_description/meshes/Wrist_Pitch_Collision2.stl" scale="0.001 0.001 0.001" />
      </geometry>
    </collision>
    <collision>
      <geometry>
        <mesh filename="package://allex_description/meshes/Wrist_Pitch_Collision3.stl" scale="0.001 0.001 0.001" />
      </geometry>
    </collision>
  </link>
  <link name="R_Palm_Link">
    <inertial>
      <origin xyz="0 0 0" rpy="0 0 0" />
      <mass value="0" />
      <inertia ixx="0.001" iyy="0.001" izz="0.001" ixy="0" ixz="0" iyz="0" />
    </inertial>
    <visual>
      <material name="gray" />
      <geometry>
        <mesh filename="package://allex_description/meshes/R_Palm_Gray.stl" scale="0.001 0.001 0.001" />
      </geometry>
    </visual>
    <visual>
      <material name="pad" />
      <geometry>
        <mesh filename="package://allex_description/meshes/R_Palm_Pad.stl" scale="0.001 0.001 0.001" />
      </geometry>
    </visual>
    <visual>
      <material name="white" />
      <geometry>
        <mesh filename="package://allex_description/meshes/R_Palm_White.stl" scale="0.001 0.001 0.001" />
      </geometry>
    </visual>
    <collision>
      <geometry>
        <mesh filename="package://allex_description/meshes/R_Palm_Back_Collision1.stl" scale="0.001 0.001 0.001" />
      </geometry>
    </collision>
    <collision>
      <geometry>
        <mesh filename="package://allex_description/meshes/R_Palm_Back_Collision2.stl" scale="0.001 0.001 0.001" />
      </geometry>
    </collision>
    <collision>
      <geometry>
        <mesh filename="package://allex_description/meshes/R_Palm_Back_Collision3.stl" scale="0.001 0.001 0.001" />
      </geometry>
    </collision>
    <collision>
      <geometry>
        <mesh filename="package://allex_description/meshes/R_Palm_Frame_Collision1.stl" scale="0.001 0.001 0.001" />
      </geometry>
    </collision>
    <collision>
      <geometry>
        <mesh filename="package://allex_description/meshes/R_Palm_Frame_Collision2.stl" scale="0.001 0.001 0.001" />
      </geometry>
    </collision>
    <collision>
      <geometry>
        <mesh filename="package://allex_description/meshes/R_Palm_Frame_Collision3.stl" scale="0.001 0.001 0.001" />
      </geometry>
    </collision>
    <collision>
      <geometry>
        <mesh filename="package://allex_description/meshes/R_Palm_Frame_Collision4.stl" scale="0.001 0.001 0.001" />
      </geometry>
    </collision>
    <collision>
      <geometry>
        <mesh filename="package://allex_description/meshes/R_Palm_Frame_Collision5.stl" scale="0.001 0.001 0.001" />
      </geometry>
    </collision>
    <collision>
      <geometry>
        <mesh filename="package://allex_description/meshes/R_Palm_Frame_Collision6.stl" scale="0.001 0.001 0.001" />
      </geometry>
    </collision>
    <collision>
      <geometry>
        <mesh filename="package://allex_description/meshes/R_Palm_Frame_Collision7.stl" scale="0.001 0.001 0.001" />
      </geometry>
    </collision>
    <collision>
      <geometry>
        <mesh filename="package://allex_description/meshes/R_Palm_Pad_Collision1.stl" scale="0.001 0.001 0.001" />
      </geometry>
    </collision>
    <collision>
      <geometry>
        <mesh filename="package://allex_description/meshes/R_Palm_Pad_Collision2.stl" scale="0.001 0.001 0.001" />
      </geometry>
    </collision>
    <collision>
      <geometry>
        <mesh filename="package://allex_description/meshes/R_Palm_Pad_Collision3.stl" scale="0.001 0.001 0.001" />
      </geometry>
    </collision>
  </link>
  <link name="R_Thumb_Yaw_Link">
    <inertial>
      <origin xyz="-7.001e-06 -0.002747764 -0.019328997" rpy="-0.0133832376 0.302264329 1.54015668" />
      <mass value="0.032789432" />
      <inertia ixx="1.04786294e-05" iyy="1.04406183e-05" izz="1.50097565e-06" ixy="0" ixz="0" iyz="0" />
    </inertial>
    <visual>
      <material name="gray" />
      <geometry>
        <mesh filename="package://allex_description/meshes/R_Thumb_Yaw_Gray.stl" scale="0.001 0.001 0.001" />
      </geometry>
    </visual>
    <collision>
      <geometry>
        <mesh filename="package://allex_description/meshes/R_Thumb_Yaw_Collision.stl" scale="0.001 0.001 0.001" />
      </geometry>
    </collision>
  </link>
  <link name="R_Thumb_Proximal_Link">
    <inertial>
      <origin xyz="-5.9101e-05 -0.015021659 0.007733297" rpy="1.29792405 -0.00399944438 0.00259407196" />
      <mass value="0.027231496" />
      <inertia ixx="8.18647506e-06" iyy="7.02673901e-06" izz="1.95160136e-06" ixy="0" ixz="0" iyz="0" />
    </inertial>
    <visual>
      <material name="gray" />
      <geometry>
        <mesh filename="package://allex_description/meshes/R_Thumb_Proximal_Gray.stl" scale="0.001 0.001 0.001" />
      </geometry>
    </visual>
    <visual>
      <material name="pad" />
      <geometry>
        <mesh filename="package://allex_description/meshes/R_Thumb_Proximal_Pad.stl" scale="0.001 0.001 0.001" />
      </geometry>
    </visual>
    <visual>
      <material name="white" />
      <geometry>
        <mesh filename="package://allex_description/meshes/R_Thumb_Proximal_White.stl" scale="0.001 0.001 0.001" />
      </geometry>
    </visual>
    <collision>
      <geometry>
        <mesh filename="package://allex_description/meshes/R_Thumb_Proximal_Collision1.stl" scale="0.001 0.001 0.001" />
      </geometry>
    </collision>
    <collision>
      <geometry>
        <mesh filename="package://allex_description/meshes/R_Thumb_Proximal_Collision2.stl" scale="0.001 0.001 0.001" />
      </geometry>
    </collision>
    <collision>
      <geometry>
        <mesh filename="package://allex_description/meshes/R_Thumb_Proximal_Collision3.stl" scale="0.001 0.001 0.001" />
      </geometry>
    </collision>
    <collision>
      <geometry>
        <mesh filename="package://allex_description/meshes/R_Thumb_Proximal_Collision4.stl" scale="0.001 0.001 0.001" />
      </geometry>
    </collision>
  </link>
  <link name="R_Thumb_Middle_Link">
    <inertial>
      <origin xyz="4.85e-07 -0.006779487 -0.00176946" rpy="-0.00410535232 -1.50554574 1.57490171" />
      <mass value="0.009930981" />
      <inertia ixx="8.84655879e-07" iyy="8.10963655e-07" izz="3.27075167e-07" ixy="0" ixz="0" iyz="0" />
    </inertial>
    <visual>
      <material name="gray" />
      <geometry>
        <mesh filename="package://allex_description/meshes/R_Thumb_Middle_Gray.stl" scale="0.001 0.001 0.001" />
      </geometry>
    </visual>
    <visual>
      <material name="pad" />
      <geometry>
        <mesh filename="package://allex_description/meshes/R_Thumb_Middle_Pad.stl" scale="0.001 0.001 0.001" />
      </geometry>
    </visual>
    <collision>
      <geometry>
        <mesh filename="package://allex_description/meshes/R_Thumb_Middle_Collision.stl" scale="0.001 0.001 0.001" />
      </geometry>
    </collision>
  </link>
  <link name="R_Thumb_Distal_Link">
    <inertial>
      <origin xyz="3.439e-06 -0.005724653 0.00265343" rpy="0.475148071 -1.56290184 1.09650873" />
      <mass value="0.00504" />
      <inertia ixx="3.65366677e-07" iyy="3.44024168e-07" izz="1.05072416e-07" ixy="0" ixz="0" iyz="0" />
    </inertial>
    <visual>
      <material name="gray" />
      <geometry>
        <mesh filename="package://allex_description/meshes/R_Thumb_Distal_Gray.stl" scale="0.001 0.001 0.001" />
      </geometry>
    </visual>
    <collision>
      <geometry>
        <mesh filename="package://allex_description/meshes/R_Thumb_Distal_Collision.stl" scale="0.001 0.001 0.001" />
      </geometry>
    </collision>
  </link>
  <link name="R_Thumb_Fingertip">
    <visual>
      <material name="pad" />
      <geometry>
        <mesh filename="package://allex_description/meshes/R_Thumb_Distal_Pad.stl" scale="0.001 0.001 0.001" />
      </geometry>
    </visual>
  </link>
  <link name="R_Index_Roll_Link">
    <inertial>
      <origin xyz="-0.001315071 0.000324987 -0.001749841" rpy="-1.83820676 -1.15147144 -3.04825548" />
      <mass value="0.00611" />
      <inertia ixx="1.97980083e-07" iyy="1.35717767e-07" izz="1.02445316e-07" ixy="0" ixz="0" iyz="0" />
    </inertial>
    <visual>
      <material name="gray" />
      <geometry>
        <mesh filename="package://allex_description/meshes/Finger_Roll_Gray.stl" scale="0.001 0.001 0.001" />
      </geometry>
    </visual>
    <collision>
      <geometry>
        <mesh filename="package://allex_description/meshes/Finger_Roll_Collision.stl" scale="0.001 0.001 0.001" />
      </geometry>
    </collision>
  </link>
  <link name="R_Index_Proximal_Link">
    <inertial>
      <origin xyz="-0.005831596 4.2198e-05 -0.01921192" rpy="-0.179018007 0.00504849843 1.59163888" />
      <mass value="0.02387" />
      <inertia ixx="6.64295065e-06" iyy="6.51700556e-06" izz="8.85266462e-07" ixy="0" ixz="0" iyz="0" />
    </inertial>
    <visual>
      <material name="gray" />
      <geometry>
        <mesh filename="package://allex_description/meshes/Finger_Proximal_Gray.stl" scale="0.001 0.001 0.001" />
      </geometry>
    </visual>
    <visual>
      <material name="pad" />
      <geometry>
        <mesh filename="package://allex_description/meshes/Finger_Proximal_Pad.stl" scale="0.001 0.001 0.001" />
      </geometry>
    </visual>
    <visual>
      <material name="white" />
      <geometry>
        <mesh filename="package://allex_description/meshes/Finger_Proximal_White.stl" scale="0.001 0.001 0.001" />
      </geometry>
    </visual>
    <collision>
      <geometry>
        <mesh filename="package://allex_description/meshes/Finger_Proximal_Collision.stl" scale="0.001 0.001 0.001" />
      </geometry>
    </collision>
  </link>
  <link name="R_Index_Middle_Link">
    <inertial>
      <origin xyz="-0.00171781 1.917e-06 -0.00601352" rpy="0.000304271917 0.123271993 -0.00123069697" />
      <mass value="0.00977" />
      <inertia ixx="7.39580106e-07" iyy="6.70752565e-07" izz="3.19274971e-07" ixy="0" ixz="0" iyz="0" />
    </inertial>
    <visual>
      <material name="gray" />
      <geometry>
        <mesh filename="package://allex_description/meshes/Finger_Middle_Gray.stl" scale="0.001 0.001 0.001" />
      </geometry>
    </visual>
    <visual>
      <material name="pad" />
      <geometry>
        <mesh filename="package://allex_description/meshes/Finger_Middle_Pad.stl" scale="0.001 0.001 0.001" />
      </geometry>
    </visual>
    <collision>
      <geometry>
        <mesh filename="package://allex_description/meshes/Finger_Middle_Collision.stl" scale="0.001 0.001 0.001" />
      </geometry>
    </collision>
  </link>
  <link name="R_Index_Distal_Link">
    <inertial>
      <origin xyz="-0.002635323 -3.528e-06 -0.00600072" rpy="-0.000862804857 0.0115442066 0.00375023956" />
      <mass value="0.00504" />
      <inertia ixx="3.48836915e-07" iyy="3.28166576e-07" izz="1.03707591e-07" ixy="0" ixz="0" iyz="0" />
    </inertial>
    <visual>
      <material name="gray" />
      <geometry>
        <mesh filename="package://allex_description/meshes/Finger_Distal_Gray.stl" scale="0.001 0.001 0.001" />
      </geometry>
    </visual>
    <collision>
      <geometry>
        <mesh filename="package://allex_description/meshes/Finger_Distal_Collision.stl" scale="0.001 0.001 0.001" />
      </geometry>
    </collision>
  </link>
  <link name="R_Index_Fingertip">
    <visual>
      <material name="pad" />
      <geometry>
        <mesh filename="package://allex_description/meshes/Finger_Distal_Pad.stl" scale="0.001 0.001 0.001" />
      </geometry>
    </visual>
  </link>
  <link name="R_Middle_Roll_Link">
    <inertial>
      <origin xyz="-0.001315071 0.000324987 -0.001749841" rpy="-1.83820676 -1.15147144 -3.04825548" />
      <mass value="0.00611" />
      <inertia ixx="1.97980083e-07" iyy="1.35717767e-07" izz="1.02445316e-07" ixy="0" ixz="0" iyz="0" />
    </inertial>
    <visual>
      <material name="gray" />
      <geometry>
        <mesh filename="package://allex_description/meshes/Finger_Roll_Gray.stl" scale="0.001 0.001 0.001" />
      </geometry>
    </visual>
    <collision>
      <geometry>
        <mesh filename="package://allex_description/meshes/Finger_Roll_Collision.stl" scale="0.001 0.001 0.001" />
      </geometry>
    </collision>
  </link>
  <link name="R_Middle_Proximal_Link">
    <inertial>
      <origin xyz="-0.005831596 4.2198e-05 -0.01921192" rpy="-0.179018007 0.00504849843 1.59163888" />
      <mass value="0.02387" />
      <inertia ixx="6.64295065e-06" iyy="6.51700556e-06" izz="8.85266462e-07" ixy="0" ixz="0" iyz="0" />
    </inertial>
    <visual>
      <material name="gray" />
      <geometry>
        <mesh filename="package://allex_description/meshes/Finger_Proximal_Gray.stl" scale="0.001 0.001 0.001" />
      </geometry>
    </visual>
    <visual>
      <material name="pad" />
      <geometry>
        <mesh filename="package://allex_description/meshes/Finger_Proximal_Pad.stl" scale="0.001 0.001 0.001" />
      </geometry>
    </visual>
    <visual>
      <material name="white" />
      <geometry>
        <mesh filename="package://allex_description/meshes/Finger_Proximal_White.stl" scale="0.001 0.001 0.001" />
      </geometry>
    </visual>
    <collision>
      <geometry>
        <mesh filename="package://allex_description/meshes/Finger_Proximal_Collision.stl" scale="0.001 0.001 0.001" />
      </geometry>
    </collision>
  </link>
  <link name="R_Middle_Middle_Link">
    <inertial>
      <origin xyz="-0.00171781 1.917e-06 -0.00601352" rpy="0.000304271917 0.123271993 -0.00123069697" />
      <mass value="0.00977" />
      <inertia ixx="7.39580106e-07" iyy="6.70752565e-07" izz="3.19274971e-07" ixy="0" ixz="0" iyz="0" />
    </inertial>
    <visual>
      <material name="gray" />
      <geometry>
        <mesh filename="package://allex_description/meshes/Finger_Middle_Gray.stl" scale="0.001 0.001 0.001" />
      </geometry>
    </visual>
    <visual>
      <material name="pad" />
      <geometry>
        <mesh filename="package://allex_description/meshes/Finger_Middle_Pad.stl" scale="0.001 0.001 0.001" />
      </geometry>
    </visual>
    <collision>
      <geometry>
        <mesh filename="package://allex_description/meshes/Finger_Middle_Collision.stl" scale="0.001 0.001 0.001" />
      </geometry>
    </collision>
  </link>
  <link name="R_Middle_Distal_Link">
    <inertial>
      <origin xyz="-0.002635323 -3.528e-06 -0.00600072" rpy="-0.000862804857 0.0115442066 0.00375023956" />
      <mass value="0.00504" />
      <inertia ixx="3.48836915e-07" iyy="3.28166576e-07" izz="1.03707591e-07" ixy="0" ixz="0" iyz="0" />
    </inertial>
    <visual>
      <material name="gray" />
      <geometry>
        <mesh filename="package://allex_description/meshes/Finger_Distal_Gray.stl" scale="0.001 0.001 0.001" />
      </geometry>
    </visual>
    <collision>
      <geometry>
        <mesh filename="package://allex_description/meshes/Finger_Distal_Collision.stl" scale="0.001 0.001 0.001" />
      </geometry>
    </collision>
  </link>
  <link name="R_Middle_Fingertip">
    <visual>
      <material name="pad" />
      <geometry>
        <mesh filename="package://allex_description/meshes/Finger_Distal_Pad.stl" scale="0.001 0.001 0.001" />
      </geometry>
    </visual>
  </link>
  <link name="R_Ring_Roll_Link">
    <inertial>
      <origin xyz="-0.001315071 0.000324987 -0.001749841" rpy="-1.83820676 -1.15147144 -3.04825548" />
      <mass value="0.00611" />
      <inertia ixx="1.97980083e-07" iyy="1.35717767e-07" izz="1.02445316e-07" ixy="0" ixz="0" iyz="0" />
    </inertial>
    <visual>
      <material name="gray" />
      <geometry>
        <mesh filename="package://allex_description/meshes/Finger_Roll_Gray.stl" scale="0.001 0.001 0.001" />
      </geometry>
    </visual>
    <collision>
      <geometry>
        <mesh filename="package://allex_description/meshes/Finger_Roll_Collision.stl" scale="0.001 0.001 0.001" />
      </geometry>
    </collision>
  </link>
  <link name="R_Ring_Proximal_Link">
    <inertial>
      <origin xyz="-0.005831596 4.2198e-05 -0.01921192" rpy="-0.179018007 0.00504849843 1.59163888" />
      <mass value="0.02387" />
      <inertia ixx="6.64295065e-06" iyy="6.51700556e-06" izz="8.85266462e-07" ixy="0" ixz="0" iyz="0" />
    </inertial>
    <visual>
      <material name="gray" />
      <geometry>
        <mesh filename="package://allex_description/meshes/Finger_Proximal_Gray.stl" scale="0.001 0.001 0.001" />
      </geometry>
    </visual>
    <visual>
      <material name="pad" />
      <geometry>
        <mesh filename="package://allex_description/meshes/Finger_Proximal_Pad.stl" scale="0.001 0.001 0.001" />
      </geometry>
    </visual>
    <visual>
      <material name="white" />
      <geometry>
        <mesh filename="package://allex_description/meshes/Finger_Proximal_White.stl" scale="0.001 0.001 0.001" />
      </geometry>
    </visual>
    <collision>
      <geometry>
        <mesh filename="package://allex_description/meshes/Finger_Proximal_Collision.stl" scale="0.001 0.001 0.001" />
      </geometry>
    </collision>
  </link>
  <link name="R_Ring_Middle_Link">
    <inertial>
      <origin xyz="-0.00171781 1.917e-06 -0.00601352" rpy="0.000304271917 0.123271993 -0.00123069697" />
      <mass value="0.00977" />
      <inertia ixx="7.39580106e-07" iyy="6.70752565e-07" izz="3.19274971e-07" ixy="0" ixz="0" iyz="0" />
    </inertial>
    <visual>
      <material name="gray" />
      <geometry>
        <mesh filename="package://allex_description/meshes/Finger_Middle_Gray.stl" scale="0.001 0.001 0.001" />
      </geometry>
    </visual>
    <visual>
      <material name="pad" />
      <geometry>
        <mesh filename="package://allex_description/meshes/Finger_Middle_Pad.stl" scale="0.001 0.001 0.001" />
      </geometry>
    </visual>
    <collision>
      <geometry>
        <mesh filename="package://allex_description/meshes/Finger_Middle_Collision.stl" scale="0.001 0.001 0.001" />
      </geometry>
    </collision>
  </link>
  <link name="R_Ring_Distal_Link">
    <inertial>
      <origin xyz="-0.002635323 -3.528e-06 -0.00600072" rpy="-0.000862804857 0.0115442066 0.00375023956" />
      <mass value="0.00504" />
      <inertia ixx="3.48836915e-07" iyy="3.28166576e-07" izz="1.03707591e-07" ixy="0" ixz="0" iyz="0" />
    </inertial>
    <visual>
      <material name="gray" />
      <geometry>
        <mesh filename="package://allex_description/meshes/Finger_Distal_Gray.stl" scale="0.001 0.001 0.001" />
      </geometry>
    </visual>
    <collision>
      <geometry>
        <mesh filename="package://allex_description/meshes/Finger_Distal_Collision.stl" scale="0.001 0.001 0.001" />
      </geometry>
    </collision>
  </link>
  <link name="R_Ring_Fingertip">
    <visual>
      <material name="pad" />
      <geometry>
        <mesh filename="package://allex_description/meshes/Finger_Distal_Pad.stl" scale="0.001 0.001 0.001" />
      </geometry>
    </visual>
  </link>
  <link name="R_Little_Roll_Link">
    <inertial>
      <origin xyz="-0.001315071 0.000324987 -0.001749841" rpy="-1.83820676 -1.15147144 -3.04825548" />
      <mass value="0.00611" />
      <inertia ixx="1.97980083e-07" iyy="1.35717767e-07" izz="1.02445316e-07" ixy="0" ixz="0" iyz="0" />
    </inertial>
    <visual>
      <material name="gray" />
      <geometry>
        <mesh filename="package://allex_description/meshes/Finger_Roll_Gray.stl" scale="0.001 0.001 0.001" />
      </geometry>
    </visual>
    <collision>
      <geometry>
        <mesh filename="package://allex_description/meshes/Finger_Roll_Collision.stl" scale="0.001 0.001 0.001" />
      </geometry>
    </collision>
  </link>
  <link name="R_Little_Proximal_Link">
    <inertial>
      <origin xyz="-0.005831596 4.2198e-05 -0.01921192" rpy="-0.179018007 0.00504849843 1.59163888" />
      <mass value="0.02175" />
      <inertia ixx="6.0529609e-06" iyy="5.93820155e-06" izz="8.06642042e-07" ixy="0" ixz="0" iyz="0" />
    </inertial>
    <visual>
      <material name="gray" />
      <geometry>
        <mesh filename="package://allex_description/meshes/Finger_Proximal_Gray.stl" scale="0.001 0.001 0.001" />
      </geometry>
    </visual>
    <visual>
      <material name="pad" />
      <geometry>
        <mesh filename="package://allex_description/meshes/Finger_Proximal_Pad.stl" scale="0.001 0.001 0.001" />
      </geometry>
    </visual>
    <visual>
      <material name="white" />
      <geometry>
        <mesh filename="package://allex_description/meshes/Finger_Proximal_White.stl" scale="0.001 0.001 0.001" />
      </geometry>
    </visual>
    <collision>
      <geometry>
        <mesh filename="package://allex_description/meshes/Finger_Proximal_Collision.stl" scale="0.001 0.001 0.001" />
      </geometry>
    </collision>
  </link>
  <link name="R_Little_Middle_Link">
    <inertial>
      <origin xyz="-0.00171781 1.917e-06 -0.00601352" rpy="0.000304271917 0.123271993 -0.00123069697" />
      <mass value="0.00977" />
      <inertia ixx="7.39580106e-07" iyy="6.70752565e-07" izz="3.19274971e-07" ixy="0" ixz="0" iyz="0" />
    </inertial>
    <visual>
      <material name="gray" />
      <geometry>
        <mesh filename="package://allex_description/meshes/Finger_Middle_Gray.stl" scale="0.001 0.001 0.001" />
      </geometry>
    </visual>
    <visual>
      <material name="pad" />
      <geometry>
        <mesh filename="package://allex_description/meshes/Finger_Middle_Pad.stl" scale="0.001 0.001 0.001" />
      </geometry>
    </visual>
    <collision>
      <geometry>
        <mesh filename="package://allex_description/meshes/Finger_Middle_Collision.stl" scale="0.001 0.001 0.001" />
      </geometry>
    </collision>
  </link>
  <link name="R_Little_Distal_Link">
    <inertial>
      <origin xyz="-0.002635323 -3.528e-06 -0.00600072" rpy="-0.000862804857 0.0115442066 0.00375023956" />
      <mass value="0.00504" />
      <inertia ixx="3.48836915e-07" iyy="3.28166576e-07" izz="1.03707591e-07" ixy="0" ixz="0" iyz="0" />
    </inertial>
    <visual>
      <material name="gray" />
      <geometry>
        <mesh filename="package://allex_description/meshes/Finger_Distal_Gray.stl" scale="0.001 0.001 0.001" />
      </geometry>
    </visual>
    <collision>
      <geometry>
        <mesh filename="package://allex_description/meshes/Finger_Distal_Collision.stl" scale="0.001 0.001 0.001" />
      </geometry>
    </collision>
  </link>
  <link name="R_Little_Fingertip">
    <visual>
      <material name="pad" />
      <geometry>
        <mesh filename="package://allex_description/meshes/Finger_Distal_Pad.stl" scale="0.001 0.001 0.001" />
      </geometry>
    </visual>
  </link>
  <joint name="Waist_Yaw_Joint" type="revolute">
    <parent link="Base_Link" />
    <child link="Waist_Yaw_Link" />
    <origin xyz="0 0 0.064" rpy="0 0 0" />
    <axis xyz="0 0 1" />
    <dynamics damping="0.95" friction="4.361" />
    <limit lower="-2.8797933" upper="2.8797933" effort="130" velocity="8" />
  </joint>
  <joint name="Waist_Pitch_Dummy_Joint" type="revolute">
    <parent link="Waist_Yaw_Link" />
    <child link="Waist_Pitch_Back_Link" />
    <origin xyz="-0.04 0 0.15" rpy="0 0 0" />
    <axis xyz="0 1 0" />
    <dynamics damping="0" friction="0" />
    <limit lower="-0.5235988" upper="1.0471976" effort="0" velocity="8" />
    <mimic joint="Waist_Lower_Pitch_Joint" multiplier="1" offset="0" />
  </joint>
  <joint name="Waist_Lower_Pitch_Joint" type="revolute">
    <parent link="Waist_Yaw_Link" />
    <child link="Waist_Lower_Pitch_Link" />
    <origin xyz="0.06 0 0.12" rpy="0 0 0" />
    <axis xyz="0 1 0" />
    <dynamics damping="0.01" friction="2.31675" />
    <limit lower="-0.5235988" upper="1.0471976" effort="152" velocity="8" />
  </joint>
  <joint name="Waist_Upper_Pitch_Joint" type="revolute">
    <parent link="Waist_Lower_Pitch_Link" />
    <child link="Waist_Upper_Pitch_Link" />
    <origin xyz="0 0 0.32" rpy="0 0 0" />
    <axis xyz="0 1 0" />
    <dynamics damping="0" friction="0" />
    <limit lower="-1.0471976" upper="0.5235988" effort="0" velocity="8" />
    <mimic joint="Waist_Lower_Pitch_Joint" multiplier="-1" offset="0" />
  </joint>
  <joint name="Neck_Pitch_Joint" type="revolute">
    <parent link="Chest_Origin_Link" />
    <child link="Neck_Pitch_Link" />
    <origin xyz="-0.0335 0 0.1380804" rpy="0 0 0" />
    <axis xyz="0 1 0" />
    <dynamics damping="0" friction="0.33968" />
    <limit lower="-0.6981317" upper="0.8726646" effort="12" velocity="20" />
  </joint>
  <joint name="Neck_Yaw_Joint" type="revolute">
    <parent link="Neck_Pitch_Link" />
    <child link="Neck_Yaw_Link" />
    <origin xyz="-5e-07 0 0.093" rpy="0 0 0" />
    <axis xyz="0 0 1" />
    <dynamics damping="0" friction="0.1501" />
    <limit lower="-1.570796" upper="1.570796" effort="6" velocity="20" />
  </joint>
  <joint name="L_Shoulder_Pitch_Joint" type="revolute">
    <parent link="Chest_Origin_Link" />
    <child link="L_Shoulder_Pitch_Link" />
    <origin xyz="0 0.0710988 0.0190509" rpy="0.261799393 5.72098355e-08 2.62996701e-06" />
    <axis xyz="0 1 0" />
    <dynamics damping="0" friction="1" />
    <limit lower="-3.316126" upper="1.745329" effort="120" velocity="10" />
  </joint>
  <joint name="L_Shoulder_Roll_Joint" type="revolute">
    <parent link="L_Shoulder_Pitch_Link" />
    <child link="L_Shoulder_RollYaw_Link" />
    <origin xyz="-0.1365 0.1195 0" rpy="-0.261799393 -5.72098353e-08 2.62996701e-06" />
    <axis xyz="1 0 0" />
    <dynamics damping="0" friction="1" />
    <limit lower="-0.087266" upper="3.752458" effort="120" velocity="10" />
  </joint>
  <joint name="L_Shoulder_Yaw_Joint" type="revolute">
    <parent link="L_Shoulder_RollYaw_Link" />
    <child link="L_Upper_Arm_Link" />
    <origin xyz="0.1365 0 0.0315" rpy="0 0 0" />
    <axis xyz="0 0 1" />
    <dynamics damping="0" friction="1" />
    <limit lower="-3.316126" upper="1.745329" effort="120" velocity="10" />
  </joint>
  <joint name="L_Elbow_Joint" type="revolute">
    <parent link="L_Upper_Arm_Link" />
    <child link="L_Elbow_Link" />
    <origin xyz="0.03 0 -0.3255" rpy="0 0 0" />
    <axis xyz="0 1 0" />
    <dynamics damping="0" friction="1" />
    <limit lower="-2.792527" upper="0.087266" effort="100" velocity="20" />
  </joint>
  <joint name="L_Wrist_Yaw_Joint" type="revolute">
    <parent link="L_Elbow_Link" />
    <child link="L_Forearm_Link" />
    <origin xyz="-0.045 0 -0.045" rpy="0 0 0" />
    <axis xyz="0 0 1" />
    <dynamics damping="0" friction="1" />
    <limit lower="-4.799655" upper="0.610865" effort="60" velocity="30" />
  </joint>
  <joint name="L_Wrist_Roll_Joint" type="revolute">
    <parent link="L_Forearm_Link" />
    <child link="L_Wrist_Roll_Link" />
    <origin xyz="-0.0085 0 -0.2725" rpy="0 0 0" />
    <axis xyz="1 0 0" />
    <dynamics damping="0" friction="0.3" />
    <limit lower="-0.872665" upper="0.872665" effort="20" velocity="30" />
  </joint>
  <joint name="L_Wrist_Pitch_Joint" type="revolute">
    <parent link="L_Wrist_Roll_Link" />
    <child link="L_Wrist_Pitch_Link" />
    <origin xyz="0.0135 0 -0.025" rpy="0 0 0" />
    <axis xyz="0 1 0" />
    <dynamics damping="0" friction="0.3" />
    <limit lower="-1.396263" upper="1.396263" effort="18" velocity="30" />
  </joint>
  <joint name="L_Thumb_Yaw_Joint" type="revolute">
    <parent link="L_Palm_Link" />
    <child link="L_Thumb_Yaw_Link" />
    <origin xyz="0.0098274 0.0210533 0.0360908" rpy="0.0857013198 0.12731092 -0.126608008" />
    <axis xyz="0 0 -1" />
    <dynamics damping="0" friction="0.03874" />
    <limit lower="0" upper="2.617994" effort="1.5" velocity="5" />
  </joint>
  <joint name="L_Thumb_CMC_Joint" type="revolute">
    <parent link="L_Thumb_Yaw_Link" />
    <child link="L_Thumb_Proximal_Link" />
    <origin xyz="0 0.0139985 -0.0323434" rpy="-0.268480431 0 0" />
    <axis xyz="-1 0 0" />
    <dynamics damping="0" friction="0.05879" />
    <limit lower="0" upper="1.570796" effort="4.5" velocity="8" />
  </joint>
  <joint name="L_Thumb_MCP_Joint" type="revolute">
    <parent link="L_Thumb_Proximal_Link" />
    <child link="L_Thumb_Middle_Link" />
    <origin xyz="0 0.0501371 0.0137939" rpy="0 0 0" />
    <axis xyz="-1 0 0" />
    <dynamics damping="0" friction="0.0185" />
    <limit lower="0" upper="1.570796" effort="3" velocity="8" />
  </joint>
  <joint name="L_Thumb_IP_Joint" type="revolute">
    <parent link="L_Thumb_Middle_Link" />
    <child link="L_Thumb_Distal_Link" />
    <origin xyz="0 0.022 0" rpy="0 0 0" />
    <axis xyz="-1 0 0" />
    <dynamics damping="0" friction="0" />
    <limit lower="0" upper="1.14964202" effort="0" velocity="8" />
    <mimic joint="L_Thumb_MCP_Joint" multiplier="0.731884995" offset="0" />
  </joint>
  <joint name="L_Index_ABAD_Joint" type="revolute">
    <parent link="L_Palm_Link" />
    <child link="L_Index_Roll_Link" />
    <origin xyz="-0.0186259 0.0330567 -0.0383928" rpy="0.111559433 -0.342338035 -0.087060514" />
    <axis xyz="1 0 0" />
    <dynamics damping="0" friction="0.0137996" />
    <limit lower="-0.523599" upper="0.523599" effort="3.5" velocity="8" />
  </joint>
  <joint name="L_Index_MCP_Joint" type="revolute">
    <parent link="L_Index_Roll_Link" />
    <child link="L_Index_Proximal_Link" />
    <origin xyz="-0.003817 0 -0.0061246" rpy="0 0.349065878 0" />
    <axis xyz="0 -1 0" />
    <dynamics damping="0" friction="0.0456392" />
    <limit lower="-0.174532" upper="1.570796" effort="5" velocity="8" />
  </joint>
  <joint name="L_Index_PIP_Joint" type="revolute">
    <parent link="L_Index_Proximal_Link" />
    <child link="L_Index_Middle_Link" />
    <origin xyz="0 0 -0.052" rpy="0 0 0" />
    <axis xyz="0 -1 0" />
    <dynamics damping="0" friction="0.0210383" />
    <limit lower="0" upper="1.9198622" effort="3" velocity="10" />
  </joint>
  <joint name="L_Index_DIP_Joint" type="revolute">
    <parent link="L_Index_Middle_Link" />
    <child link="L_Index_Distal_Link" />
    <origin xyz="0.0019932 0 -0.0188952" rpy="0 0 0" />
    <axis xyz="0 -1 0" />
    <dynamics damping="0" friction="0" />
    <limit lower="0" upper="1.25999882" effort="0" velocity="10" />
    <mimic joint="L_Index_PIP_Joint" multiplier="0.656296489" offset="0" />
  </joint>
  <joint name="L_Middle_ABAD_Joint" type="revolute">
    <parent link="L_Palm_Link" />
    <child link="L_Middle_Roll_Link" />
    <origin xyz="-0.0197378 0.0111686 -0.0403088" rpy="0 -0.349065878 0" />
    <axis xyz="1 0 0" />
    <dynamics damping="0" friction="0.0137996" />
    <limit lower="-0.523599" upper="0.523599" effort="3.5" velocity="8" />
  </joint>
  <joint name="L_Middle_MCP_Joint" type="revolute">
    <parent link="L_Middle_Roll_Link" />
    <child link="L_Middle_Proximal_Link" />
    <origin xyz="-0.003817 0 -0.0061246" rpy="0 0.349065878 0" />
    <axis xyz="0 -1 0" />
    <dynamics damping="0" friction="0.0456392" />
    <limit lower="-0.174532" upper="1.570796" effort="5" velocity="8" />
  </joint>
  <joint name="L_Middle_PIP_Joint" type="revolute">
    <parent link="L_Middle_Proximal_Link" />
    <child link="L_Middle_Middle_Link" />
    <origin xyz="0 0 -0.052" rpy="0 0 0" />
    <axis xyz="0 -1 0" />
    <dynamics damping="0" friction="0.0210383" />
    <limit lower="0" upper="1.9198622" effort="3" velocity="10" />
  </joint>
  <joint name="L_Middle_DIP_Joint" type="revolute">
    <parent link="L_Middle_Middle_Link" />
    <child link="L_Middle_Distal_Link" />
    <origin xyz="0.0019932 0 -0.0188952" rpy="0 0 0" />
    <axis xyz="0 -1 0" />
    <dynamics damping="0" friction="0" />
    <limit lower="0" upper="1.25999882" effort="0" velocity="10" />
    <mimic joint="L_Middle_PIP_Joint" multiplier="0.656296489" offset="0" />
  </joint>
  <joint name="L_Ring_ABAD_Joint" type="revolute">
    <parent link="L_Palm_Link" />
    <child link="L_Ring_Roll_Link" />
    <origin xyz="-0.0197763 -0.0108314 -0.040309" rpy="-0.111559433 -0.342338035 0.087060514" />
    <axis xyz="1 0 0" />
    <dynamics damping="0" friction="0.0137996" />
    <limit lower="-0.523599" upper="0.523599" effort="3.5" velocity="8" />
  </joint>
  <joint name="L_Ring_MCP_Joint" type="revolute">
    <parent link="L_Ring_Roll_Link" />
    <child link="L_Ring_Proximal_Link" />
    <origin xyz="-0.003817 0 -0.0061246" rpy="0 0.349065878 0" />
    <axis xyz="0 -1 0" />
    <dynamics damping="0" friction="0.0456392" />
    <limit lower="-0.174532" upper="1.570796" effort="5" velocity="8" />
  </joint>
  <joint name="L_Ring_PIP_Joint" type="revolute">
    <parent link="L_Ring_Proximal_Link" />
    <child link="L_Ring_Middle_Link" />
    <origin xyz="0 0 -0.052" rpy="0 0 0" />
    <axis xyz="0 -1 0" />
    <dynamics damping="0" friction="0.0210383" />
    <limit lower="0" upper="1.9198622" effort="3" velocity="10" />
  </joint>
  <joint name="L_Ring_DIP_Joint" type="revolute">
    <parent link="L_Ring_Middle_Link" />
    <child link="L_Ring_Distal_Link" />
    <origin xyz="0.0019932 0 -0.0188952" rpy="0 0 0" />
    <axis xyz="0 -1 0" />
    <dynamics damping="0" friction="0" />
    <limit lower="0" upper="1.25999882" effort="0" velocity="10" />
    <mimic joint="L_Ring_PIP_Joint" multiplier="0.656296489" offset="0" />
  </joint>
  <joint name="L_Little_ABAD_Joint" type="revolute">
    <parent link="L_Palm_Link" />
    <child link="L_Little_Roll_Link" />
    <origin xyz="-0.0185852 -0.0327196 -0.0383938" rpy="-0.220991363 -0.322382983 0.171647217" />
    <axis xyz="1 0 0" />
    <dynamics damping="0" friction="0.0137996" />
    <limit lower="-0.523599" upper="0.523599" effort="3.5" velocity="8" />
  </joint>
  <joint name="L_Little_MCP_Joint" type="revolute">
    <parent link="L_Little_Roll_Link" />
    <child link="L_Little_Proximal_Link" />
    <origin xyz="-0.003817 0 -0.0061246" rpy="0 0.349065878 0" />
    <axis xyz="0 -1 0" />
    <dynamics damping="0" friction="0.0456392" />
    <limit lower="-0.174532" upper="1.570796" effort="5" velocity="8" />
  </joint>
  <joint name="L_Little_PIP_Joint" type="revolute">
    <parent link="L_Little_Proximal_Link" />
    <child link="L_Little_Middle_Link" />
    <origin xyz="0 0 -0.052" rpy="0 0 0" />
    <axis xyz="0 -1 0" />
    <dynamics damping="0" friction="0.0210383" />
    <limit lower="0" upper="1.9198622" effort="3" velocity="10" />
  </joint>
  <joint name="L_Little_DIP_Joint" type="revolute">
    <parent link="L_Little_Middle_Link" />
    <child link="L_Little_Distal_Link" />
    <origin xyz="0.0019932 0 -0.0188952" rpy="0 0 0" />
    <axis xyz="0 -1 0" />
    <dynamics damping="0" friction="0" />
    <limit lower="0" upper="1.25999882" effort="0" velocity="10" />
    <mimic joint="L_Little_PIP_Joint" multiplier="0.656296489" offset="0" />
  </joint>
  <joint name="R_Shoulder_Pitch_Joint" type="revolute">
    <parent link="Chest_Origin_Link" />
    <child link="R_Shoulder_Pitch_Link" />
    <origin xyz="0 -0.0710988 0.0190509" rpy="-0.261799393 -5.72098353e-08 2.62996701e-06" />
    <axis xyz="0 1 0" />
    <dynamics damping="0" friction="1" />
    <limit lower="-3.316126" upper="1.745329" effort="120" velocity="10" />
  </joint>
  <joint name="R_Shoulder_Roll_Joint" type="revolute">
    <parent link="R_Shoulder_Pitch_Link" />
    <child link="R_Shoulder_RollYaw_Link" />
    <origin xyz="-0.1365 -0.1195 0" rpy="0.261799393 5.72098355e-08 2.62996701e-06" />
    <axis xyz="1 0 0" />
    <dynamics damping="0" friction="1" />
    <limit lower="-3.752458" upper="0.087266" effort="120" velocity="10" />
  </joint>
  <joint name="R_Shoulder_Yaw_Joint" type="revolute">
    <parent link="R_Shoulder_RollYaw_Link" />
    <child link="R_Upper_Arm_Link" />
    <origin xyz="0.1365 0 0.0315" rpy="0 0 0" />
    <axis xyz="0 0 1" />
    <dynamics damping="0" friction="1" />
    <limit lower="-1.745329" upper="3.316126" effort="120" velocity="10" />
  </joint>
  <joint name="R_Elbow_Joint" type="revolute">
    <parent link="R_Upper_Arm_Link" />
    <child link="R_Elbow_Link" />
    <origin xyz="0.03 0 -0.3255" rpy="0 0 0" />
    <axis xyz="0 1 0" />
    <dynamics damping="0" friction="1" />
    <limit lower="-2.7925268" upper="0.0872665" effort="100" velocity="20" />
  </joint>
  <joint name="R_Wrist_Yaw_Joint" type="revolute">
    <parent link="R_Elbow_Link" />
    <child link="R_Forearm_Link" />
    <origin xyz="-0.045 0 -0.045" rpy="0 0 0" />
    <axis xyz="0 0 1" />
    <dynamics damping="0" friction="1" />
    <limit lower="-0.610865" upper="4.799655" effort="60" velocity="30" />
  </joint>
  <joint name="R_Wrist_Roll_Joint" type="revolute">
    <parent link="R_Forearm_Link" />
    <child link="R_Wrist_Roll_Link" />
    <origin xyz="-0.0085 0 -0.2725" rpy="0 0 0" />
    <axis xyz="1 0 0" />
    <dynamics damping="0" friction="0.3" />
    <limit lower="-0.872665" upper="0.872665" effort="20" velocity="30" />
  </joint>
  <joint name="R_Wrist_Pitch_Joint" type="revolute">
    <parent link="R_Wrist_Roll_Link" />
    <child link="R_Wrist_Pitch_Link" />
    <origin xyz="0.0135 0 -0.025" rpy="0 0 0" />
    <axis xyz="0 1 0" />
    <dynamics damping="0" friction="0.3" />
    <limit lower="-1.396263" upper="1.396263" effort="18" velocity="30" />
  </joint>
  <joint name="R_Thumb_Yaw_Joint" type="revolute">
    <parent link="R_Palm_Link" />
    <child link="R_Thumb_Yaw_Link" />
    <origin xyz="0.0098263 -0.0210097 0.0360889" rpy="-0.0857013198 0.12731092 0.126608008" />
    <axis xyz="0 0 -1" />
    <dynamics damping="0" friction="0.03874" />
    <limit lower="-2.617994" upper="0" effort="1.5" velocity="5" />
  </joint>
  <joint name="R_Thumb_CMC_Joint" type="revolute">
    <parent link="R_Thumb_Yaw_Link" />
    <child link="R_Thumb_Proximal_Link" />
    <origin xyz="0 -0.0139985 -0.0323434" rpy="0.268480431 0 0" />
    <axis xyz="1 0 0" />
    <dynamics damping="0" friction="0.05879" />
    <limit lower="0" upper="1.570796" effort="4.5" velocity="8" />
  </joint>
  <joint name="R_Thumb_MCP_Joint" type="revolute">
    <parent link="R_Thumb_Proximal_Link" />
    <child link="R_Thumb_Middle_Link" />
    <origin xyz="0 -0.0501371 0.0137939" rpy="0 0 0" />
    <axis xyz="1 0 0" />
    <dynamics damping="0" friction="0.0185" />
    <limit lower="0" upper="1.570796" effort="3" velocity="8" />
  </joint>
  <joint name="R_Thumb_IP_Joint" type="revolute">
    <parent link="R_Thumb_Middle_Link" />
    <child link="R_Thumb_Distal_Link" />
    <origin xyz="0 -0.022 0" rpy="0 0 0" />
    <axis xyz="1 0 0" />
    <dynamics damping="0" friction="0" />
    <limit lower="0" upper="1.14964202" effort="0" velocity="8" />
    <mimic joint="R_Thumb_MCP_Joint" multiplier="0.731884995" offset="0" />
  </joint>
  <joint name="R_Index_ABAD_Joint" type="revolute">
    <parent link="R_Palm_Link" />
    <child link="R_Index_Roll_Link" />
    <origin xyz="-0.0186259 -0.0330567 -0.0383928" rpy="-0.111559433 -0.342338035 0.087060514" />
    <axis xyz="1 0 0" />
    <dynamics damping="0" friction="0.0137996" />
    <limit lower="-0.523599" upper="0.523599" effort="3.5" velocity="8" />
  </joint>
  <joint name="R_Index_MCP_Joint" type="revolute">
    <parent link="R_Index_Roll_Link" />
    <child link="R_Index_Proximal_Link" />
    <origin xyz="-0.003817 0 -0.0061246" rpy="0 0.349065878 0" />
    <axis xyz="0 -1 0" />
    <dynamics damping="0" friction="0.0456392" />
    <limit lower="-0.174532" upper="1.570796" effort="5" velocity="8" />
  </joint>
  <joint name="R_Index_PIP_Joint" type="revolute">
    <parent link="R_Index_Proximal_Link" />
    <child link="R_Index_Middle_Link" />
    <origin xyz="0 0 -0.052" rpy="0 0 0" />
    <axis xyz="0 -1 0" />
    <dynamics damping="0" friction="0.0210383" />
    <limit lower="0" upper="1.9198622" effort="3" velocity="10" />
  </joint>
  <joint name="R_Index_DIP_Joint" type="revolute">
    <parent link="R_Index_Middle_Link" />
    <child link="R_Index_Distal_Link" />
    <origin xyz="0.0019932 0 -0.0188952" rpy="0 0 0" />
    <axis xyz="0 -1 0" />
    <dynamics damping="0" friction="0" />
    <limit lower="0" upper="1.25999882" effort="0" velocity="10" />
    <mimic joint="R_Index_PIP_Joint" multiplier="0.656296489" offset="0" />
  </joint>
  <joint name="R_Middle_ABAD_Joint" type="revolute">
    <parent link="R_Palm_Link" />
    <child link="R_Middle_Roll_Link" />
    <origin xyz="-0.0197378 -0.0111686 -0.0403088" rpy="0 -0.349065878 0" />
    <axis xyz="1 0 0" />
    <dynamics damping="0" friction="0.0137996" />
    <limit lower="-0.523599" upper="0.523599" effort="3.5" velocity="8" />
  </joint>
  <joint name="R_Middle_MCP_Joint" type="revolute">
    <parent link="R_Middle_Roll_Link" />
    <child link="R_Middle_Proximal_Link" />
    <origin xyz="-0.003817 0 -0.0061246" rpy="0 0.349065878 0" />
    <axis xyz="0 -1 0" />
    <dynamics damping="0" friction="0.0456392" />
    <limit lower="-0.174532" upper="1.570796" effort="5" velocity="8" />
  </joint>
  <joint name="R_Middle_PIP_Joint" type="revolute">
    <parent link="R_Middle_Proximal_Link" />
    <child link="R_Middle_Middle_Link" />
    <origin xyz="0 0 -0.052" rpy="0 0 0" />
    <axis xyz="0 -1 0" />
    <dynamics damping="0" friction="0.0210383" />
    <limit lower="0" upper="1.9198622" effort="3" velocity="10" />
  </joint>
  <joint name="R_Middle_DIP_Joint" type="revolute">
    <parent link="R_Middle_Middle_Link" />
    <child link="R_Middle_Distal_Link" />
    <origin xyz="0.0019932 0 -0.0188952" rpy="0 0 0" />
    <axis xyz="0 -1 0" />
    <dynamics damping="0" friction="0" />
    <limit lower="0" upper="1.25999882" effort="0" velocity="10" />
    <mimic joint="R_Middle_PIP_Joint" multiplier="0.656296489" offset="0" />
  </joint>
  <joint name="R_Ring_ABAD_Joint" type="revolute">
    <parent link="R_Palm_Link" />
    <child link="R_Ring_Roll_Link" />
    <origin xyz="-0.0197763 0.0108314 -0.040309" rpy="0.111559433 -0.342338035 -0.087060514" />
    <axis xyz="1 0 0" />
    <dynamics damping="0" friction="0.0137996" />
    <limit lower="-0.523599" upper="0.523599" effort="3.5" velocity="8" />
  </joint>
  <joint name="R_Ring_MCP_Joint" type="revolute">
    <parent link="R_Ring_Roll_Link" />
    <child link="R_Ring_Proximal_Link" />
    <origin xyz="-0.003817 0 -0.0061246" rpy="0 0.349065878 0" />
    <axis xyz="0 -1 0" />
    <dynamics damping="0" friction="0.0456392" />
    <limit lower="-0.174532" upper="1.570796" effort="5" velocity="8" />
  </joint>
  <joint name="R_Ring_PIP_Joint" type="revolute">
    <parent link="R_Ring_Proximal_Link" />
    <child link="R_Ring_Middle_Link" />
    <origin xyz="0 0 -0.052" rpy="0 0 0" />
    <axis xyz="0 -1 0" />
    <dynamics damping="0" friction="0.0210383" />
    <limit lower="0" upper="1.9198622" effort="3" velocity="10" />
  </joint>
  <joint name="R_Ring_DIP_Joint" type="revolute">
    <parent link="R_Ring_Middle_Link" />
    <child link="R_Ring_Distal_Link" />
    <origin xyz="0.0019932 0 -0.0188952" rpy="0 0 0" />
    <axis xyz="0 -1 0" />
    <dynamics damping="0" friction="0" />
    <limit lower="0" upper="1.25999882" effort="0" velocity="10" />
    <mimic joint="R_Ring_PIP_Joint" multiplier="0.656296489" offset="0" />
  </joint>
  <joint name="R_Little_ABAD_Joint" type="revolute">
    <parent link="R_Palm_Link" />
    <child link="R_Little_Roll_Link" />
    <origin xyz="-0.0185852 0.0327196 -0.0383938" rpy="0.220991363 -0.322382983 -0.171647217" />
    <axis xyz="1 0 0" />
    <dynamics damping="0" friction="0.0137996" />
    <limit lower="-0.523599" upper="0.523599" effort="3.5" velocity="8" />
  </joint>
  <joint name="R_Little_MCP_Joint" type="revolute">
    <parent link="R_Little_Roll_Link" />
    <child link="R_Little_Proximal_Link" />
    <origin xyz="-0.003817 0 -0.0061246" rpy="0 0.349065878 0" />
    <axis xyz="0 -1 0" />
    <dynamics damping="0" friction="0.0456392" />
    <limit lower="-0.174532" upper="1.570796" effort="5" velocity="8" />
  </joint>
  <joint name="R_Little_PIP_Joint" type="revolute">
    <parent link="R_Little_Proximal_Link" />
    <child link="R_Little_Middle_Link" />
    <origin xyz="0 0 -0.052" rpy="0 0 0" />
    <axis xyz="0 -1 0" />
    <dynamics damping="0" friction="0.0210383" />
    <limit lower="0" upper="1.9198622" effort="3" velocity="10" />
  </joint>
  <joint name="R_Little_DIP_Joint" type="revolute">
    <parent link="R_Little_Middle_Link" />
    <child link="R_Little_Distal_Link" />
    <origin xyz="0.0019932 0 -0.0188952" rpy="0 0 0" />
    <axis xyz="0 -1 0" />
    <dynamics damping="0" friction="0" />
    <limit lower="0" upper="1.25999882" effort="0" velocity="10" />
    <mimic joint="R_Little_PIP_Joint" multiplier="0.656296489" offset="0" />
  </joint>
  <joint name="Chest_Origin_Link_fixed_joint" type="fixed">
    <parent link="Waist_Upper_Pitch_Link" />
    <child link="Chest_Origin_Link" />
    <origin xyz="0.0415 0 0.149" rpy="0 0 0" />
  </joint>
  <joint name="realsense_link_fixed_joint" type="fixed">
    <parent link="Neck_Yaw_Link" />
    <child link="realsense_link" />
    <origin xyz="0.0753 0 0.1029" rpy="0 0 0" />
  </joint>
  <joint name="orbbec_link_fixed_joint" type="fixed">
    <parent link="Neck_Yaw_Link" />
    <child link="orbbec_link" />
    <origin xyz="0.0893 0.002 0.0733" rpy="0 0 0" />
  </joint>
  <joint name="zed_camera_link_fixed_joint" type="fixed">
    <parent link="Neck_Yaw_Link" />
    <child link="zed_camera_link" />
    <origin xyz="0.067225 0 0.0145" rpy="0 0 0" />
  </joint>
  <joint name="L_Palm_Link_fixed_joint" type="fixed">
    <parent link="L_Wrist_Pitch_Link" />
    <child link="L_Palm_Link" />
    <origin xyz="0.0045 0 -0.095" rpy="0 0 0" />
  </joint>
  <joint name="L_Thumb_Fingertip_fixed_joint" type="fixed">
    <parent link="L_Thumb_Distal_Link" />
    <child link="L_Thumb_Fingertip" />
    <origin xyz="0 0.011 -0.006" rpy="0 0 0" />
  </joint>
  <joint name="L_Index_Fingertip_fixed_joint" type="fixed">
    <parent link="L_Index_Distal_Link" />
    <child link="L_Index_Fingertip" />
    <origin xyz="0.0075 0 -0.011" rpy="0 0 0" />
  </joint>
  <joint name="L_Middle_Fingertip_fixed_joint" type="fixed">
    <parent link="L_Middle_Distal_Link" />
    <child link="L_Middle_Fingertip" />
    <origin xyz="0.0075 0 -0.011" rpy="0 0 0" />
  </joint>
  <joint name="L_Ring_Fingertip_fixed_joint" type="fixed">
    <parent link="L_Ring_Distal_Link" />
    <child link="L_Ring_Fingertip" />
    <origin xyz="0.0075 0 -0.011" rpy="0 0 0" />
  </joint>
  <joint name="L_Little_Fingertip_fixed_joint" type="fixed">
    <parent link="L_Little_Distal_Link" />
    <child link="L_Little_Fingertip" />
    <origin xyz="0.0075 0 -0.011" rpy="0 0 0" />
  </joint>
  <joint name="R_Palm_Link_fixed_joint" type="fixed">
    <parent link="R_Wrist_Pitch_Link" />
    <child link="R_Palm_Link" />
    <origin xyz="0.0045 0 -0.095" rpy="0 0 0" />
  </joint>
  <joint name="R_Thumb_Fingertip_fixed_joint" type="fixed">
    <parent link="R_Thumb_Distal_Link" />
    <child link="R_Thumb_Fingertip" />
    <origin xyz="0 -0.011 -0.006" rpy="0 0 0" />
  </joint>
  <joint name="R_Index_Fingertip_fixed_joint" type="fixed">
    <parent link="R_Index_Distal_Link" />
    <child link="R_Index_Fingertip" />
    <origin xyz="0.0075 0 -0.011" rpy="0 0 0" />
  </joint>
  <joint name="R_Middle_Fingertip_fixed_joint" type="fixed">
    <parent link="R_Middle_Distal_Link" />
    <child link="R_Middle_Fingertip" />
    <origin xyz="0.0075 0 -0.011" rpy="0 0 0" />
  </joint>
  <joint name="R_Ring_Fingertip_fixed_joint" type="fixed">
    <parent link="R_Ring_Distal_Link" />
    <child link="R_Ring_Fingertip" />
    <origin xyz="0.0075 0 -0.011" rpy="0 0 0" />
  </joint>
  <joint name="R_Little_Fingertip_fixed_joint" type="fixed">
    <parent link="R_Little_Distal_Link" />
    <child link="R_Little_Fingertip" />
    <origin xyz="0.0075 0 -0.011" rpy="0 0 0" />
  </joint>
  <link name="realsense_color_optical_frame" />
  <joint name="realsense_color_optical_frame_joint" type="fixed">
    <parent link="realsense_link" />
    <child link="realsense_color_optical_frame" />
    <origin xyz="0.011 0.033 0.013" rpy="-0 1.57079633 0" />
  </joint>
  <link name="realsense_depth_optical_frame" />
  <joint name="realsense_depth_optical_frame_joint" type="fixed">
    <parent link="realsense_link" />
    <child link="realsense_depth_optical_frame" />
    <origin xyz="0.011 0.018 0.013" rpy="-0 1.57079633 0" />
  </joint>
  <link name="orbbec_color_optical_frame" />
  <joint name="orbbec_color_optical_frame_joint" type="fixed">
    <parent link="orbbec_link" />
    <child link="orbbec_color_optical_frame" />
    <origin xyz="-0.002 -0.033 -0.001" rpy="-0 1.57079633 0" />
  </joint>
  <link name="orbbec_depth_optical_frame" />
  <joint name="orbbec_depth_optical_frame_joint" type="fixed">
    <parent link="orbbec_link" />
    <child link="orbbec_depth_optical_frame" />
    <origin xyz="0 0 0" rpy="-0 1.57079633 0" />
  </joint>
  <link name="zed_left_camera_optical_frame" />
  <joint name="zed_left_camera_optical_frame_joint" type="fixed">
    <parent link="zed_camera_link" />
    <child link="zed_left_camera_optical_frame" />
    <origin xyz="0 0.032 0.013" rpy="-0 1.57079633 0" />
  </joint>
</robot>
